Workbook

Sheet 1. General 2022_Q2
A1: Count of aggreements by ZIP and CLASS.
A2: WA_TERM_COVID_COUNTS
A3: General 2022
A4: 44652 | D4: 44682 | G4: 44713 | K4: Retail Sales (kWh) | L4: July | M4: August | N4: September | O4: 44652 | P4: 44682 | Q4: 44713 | R4: July | S4: August | T4: September | U4: October | V4: November | W4: December | X4: Totals Q2
A5: Zip | B5: Class | C5: Count | D5: Zip | E5: Class | F5: Count | G5: Zip | H5: Class | I5: Count | K5: Residential | L5: 149454803 | M5: 144341255 | N5: 106642496 | O5: 117639312 | P5: 105770932 | Q5: 92158912 | X5: =SUM(O5:Q5) -> 315569156
A6: 98901 | B6: COM | C6: 2121 | D6: 98901 | E6: COM | F6: 2118 | G6: 98901 | H6: COM | I6: 2132 | K6: Commercial | L6: 140404042 | M6: 148198213 | N6: 131511808 | O6: 110239574 | P6: 106749804 | Q6: 111946253 | X6: =SUM(O6:Q6) -> 328935631
A7: 98902 | B7: COM | C7: 2550 | D7: 98902 | E7: COM | F7: 2533 | G7: 98902 | H7: COM | I7: 2545 | K7: Industrial | L7: 72533895 | M7: 71622459 | N7: 72818621 | O7: 67776438 | P7: 110717833 | Q7: 24110397 | X7: =SUM(O7:Q7) -> 202604668
A8: 98903 | B8: COM | C8: 1615 | D8: 98903 | E8: COM | F8: 1618 | G8: 98903 | H8: COM | I8: 1613 | K8: Irrigation | L8: 36860793 | M8: 39164393 | N8: 25760901 | O8: 6980502 | P8: 12323026 | Q8: 17003255 | X8: =SUM(O8:Q8) -> 36306783
A9: 98904 | B9: COM | C9: 2 | D9: 98904 | E9: COM | F9: 2 | G9: 98904 | H9: COM | I9: 2 | K9: Totals | L9: =SUM(L5:L8) -> 399253533 | M9: =SUM(M5:M8) -> 403326320 | N9: =SUM(N5:N8) -> 336733826 | O9: =SUM(O5:O8) -> 302635826 | P9: =SUM(P5:P8) -> 335561595 | Q9: =SUM(Q5:Q8) -> 245218817 | R9: =SUM(R5:R8) -> 0 | S9: =SUM(S5:S8) -> 0 | ... X9: =SUM(X5:X8) -> 883416238
A10: 98907 | B10: COM | C10: 2 | D10: 98907 | E10: COM | F10: 2 | G10: 98907 | H10: COM | I10: 2
A11: 98908 | B11: COM | C11: 1526 | D11: 98908 | E11: COM | F11: 1527 | G11: 98908 | H11: COM | I11: 1535
A12: 98920 | B12: COM | C12: 4 | D12: 98920 | E12: COM | F12: 4 | G12: 98920 | H12: COM | I12: 4
A13: 98921 | B13: COM | C13: 26 | D13: 98921 | E13: COM | F13: 26 | G13: 98921 | H13: COM | I13: 26
A14: 98923 | B14: COM | C14: 107 | D14: 98923 | E14: COM | F14: 107 | G14: 98923 | H14: COM | I14: 107
A15: 98930 | B15: COM | C15: 619 | D15: 98930 | E15: COM | F15: 620 | G15: 98930 | H15: COM | I15: 624
A16: 98932 | B16: COM | C16: 226 | D16: 98932 | E16: COM | F16: 228 | G16: 98932 | H16: COM | I16: 227
A17: 98933 | B17: COM | C17: 73 | D17: 98933 | E17: COM | F17: 72 | G17: 98933 | H17: COM | I17: 74
A18: 98935 | B18: COM | C18: 135 | D18: 98935 | E18: COM | F18: 136 | G18: 98935 | H18: COM | I18: 138
A19: 98936 | B19: COM | C19: 349 | D19: 98936 | E19: COM | F19: 348 | G19: 98936 | H19: COM | I19: 348
A20: 98937 | B20: COM | C20: 389 | D20: 98937 | E20: COM | F20: 390 | G20: 98937 | H20: COM | I20: 388
A21: 98938 | B21: COM | C21: 154 | D21: 98938 | E21: COM | F21: 157 | G21: 98938 | H21: COM | I21: 157
... A40: 99363 | B40: COM | C40: 72 | D40: 99363 | E40: COM | F40: 74 | G40: 99363 | H40: COM | I40: 73
B41: COM | C41: 1 | E41: COM | F41: 1 | H41: COM | I41: 1
A42: 98901 | B42: IND | C42: 48 | D42: 98901 | E42: IND | F42: 48 | G42: 98901 | H42: IND | I42: 48
A43: 98902 | B43: IND | C43: 85 | D43: 98902 | E43: IND | F43: 85 | G43: 98902 | H43: IND | I43: 85
A44: 98903 | B44: IND | C44: 64 | D44: 98903 | E44: IND | F44: 64 | G44: 98903 | H44: IND | I44: 64
A45: 98908 | B45: IND | C45: 17 | D45: 98908 | E45: IND | F45: 17 | G45: 98908 | H45: IND | I45: 17
A46: 98921 | B46: IND | C46: 1 | D46: 98921 | E46: IND | F46: 1 | G46: 98921 | H46: IND | I46: 1
A47: 98923 | B47: IND | C47: 4 | D47: 98923 | E47: IND | F47: 4 | G47: 98923 | H47: IND | I47: 4
A48: 98930 | B48: IND | C48: 26 | D48: 98930 | E48: IND | F48: 26 | G48: 98930 | H48: IND | I48: 26
A49: 98932 | B49: IND | C49: 12 | D49: 98932 | E49: IND | F49: 12 | G49: 98932 | H49: IND | I49: 12
A50: 98933 | B50: IND | C50: 1 | D50: 98933 | E50: IND | F50: 1 | G50: 98933 | H50: IND | I50: 1
A51: 98935 | B51: IND | C51: 3 | D51: 98935 | E51: IND | F51: 3 | G51: 98935 | H51: IND | I51: 3
A52: 98936 | B52: IND | C52: 18 | D52: 98936 | E52: IND | F52: 18 | G52: 98936 | H52: IND | I52: 18
A53: 98937 | B53: IND | C53: 11 | D53: 98937 | E53: IND | F53: 11 | G53: 98937 | H53: IND | I53: 11
... A143: 99363 | B143: RES | C143: 75 | D143: 99363 | E143: RES | F143: 74 | G143: 99363 | H143: RES | I143: 74

Sheet 2. Disconnections 2022_Q2
A1: General 2022 | D1: Item a) Number of Disconnections by Customer Class per Month | H1: Item b) Avg. Duration of Disconnection by Customer Class (in Hours for recon 10 days or less) | L1: Item c) Number of Customers by Customer Class Receiving Disconnection Notices | P1: Item d) Number of Customers by Customer Class Who Absent the Disconnection Moratorium Would Have Been Disconnected
A2: Zip Code | B2: Customer Class | D2: 44652 | E2: 44682 | F2: 44713 | H2: 44652 | I2: 44682 | J2: 44713 | L2: 44652 | M2: 44682 | N2: 44713 | P2: 44652 | Q2: 44682 | R2: 44713
A3: none

Sheet 3. Fees 2022_Q2
A1: General 2022 | D1: Item a) Number of Customers by Customer Class Assessed Late Payment Fees | H1: Item a) Aggregate amount of Charged Late Payment Fees | L1: Item a) Number of Customers by Customer Class Assessed Disconnection Fees | P1: Item a) Aggregate amount of Charged Disconnection Fees | T1: Item a) Number of Customers by Customer Class Assessed Reconnection Fees | X1: Item a) Aggregate amount of Charged Reconnection Fees
A2: Zip Code | B2: Customer Class | D2: 44652 | E2: 44682 | F2: 44713 | H2: 44652 | I2: 44682 | J2: 44713 | L2: 44652 | M2: 44682 | N2: 44713 | P2: 44652 | Q2: 44682 | R2: 44713 | T2: 44652 | U2: 44682 | V2: 44713 | X2: 44652 | Y2: 44682 | Z2: 44713
A3: None

Sheet 4. Payment Arrangements 2022_Q2
A1: General 2022 | D1: Item a) Number of Customers by Customer Class Taking Service at the Beginning of Each Month with Existing Long Term Payment Agreements | H1: Item b) Number of Customers By Customer Class Completing Long-term Payment Agreements | L1: Item c) Number of Customers by Customer Class Enrolling in New Long-term Payment Agreements | P1: Item d) Number of Customers By Customer Class Renegotiating Long-term Payment Agreements
A2: Zip Code | B2: Customer Class | D2: 44652 | E2: 44682 | F2: 44713 | H2: 44652 | I2: 44682 | J2: 44713 | L2: 44652 | M2: 44682 | N2: 44713 | P2: 44652 | Q2: 44682 | R2: 44713
A3: NA | B3: COM | D3: 100 | E3: 96 | F3: 89 | H3: 5 | I3: 10 | J3: 7 | L3: 26 | M3: 27 | N3: 27 | P3: 0 | Q3: 1 | R3: 1
A4: NA | B4: RES | D4: 3535 | E4: 3340 | F4: 3246 | H4: 100 | I4: 84 | J4: 60 | L4: 882 | M4: 862 | N4: 809 | P4: 24 | Q4: 22 | R4: 45

Sheet 5. Medical Certificates 2022_Q2
A1: General 2022 | D1: Item a) Number of Customers Taking Service at the Beginning of Each Month Under Existing Medical Payment Arrangements | H1: Item b) Number of Customers Completing Medical Payment Arrangements Each Month | L1: Item c) Number of Customers Enrolling in New Medical Payment Arrangements Each Month | P1: Item d) Number of Customers Renegotiating Medical Payment Arrangements Each Month
A2: Zip Code | B2: Customer Class | D2: 44652 | E2: 44682 | F2: 44713 | H2: 44652 | I2: 44682 | J2: 44713 | L2: 44652 | M2: 44682 | N2: 44713 | P2: 44197 | Q2: 44228 | R2: 44256 | S2: 44287 | T2: 44317 | U2: 44348 | V2: 44378 | W2: 44409 | X2: 44440 | Y2: 44652 | Z2: 44682 | AA2: 44713
A3: NA | B3: RES | D3: 6 | E3: 4 | F3: 4 | H3: 0 | I3: 0 | J3: 0 | L3: 0 | M3: 2 | N3: 1 | P3: 0 | Q3: 0 | R3: 0 | S3: 0 | T3: 0 | U3: 0 | V3: 0 | W3: 0 | X3: 0 | Y3: 0 | Z3: 0 | AA3: 0

Sheet 6. Deposits 2022_Q2
A1: General 2022 | D1: Item a) Number of Customers by Customer Class with Required Deposits at the Beginning of Each Month | N1: Item b) Number of Customers by Customer Class Required to Submit New or Increased Deposits Each Month | AH1: Item c) Number of Customers by Customer Class Whose Deposits Were Reduced In Part or Foregone Each Month | AR1: Item d) Number of Customers by Customer Class whose Deposits were Returned in Full Each Month
D2: 44652 | G2: 44682 | J2: 44713 | N2: Zip Code | O2: Customer Class | P2: 44197 | Q2: 44228 | R2: 44256 | S2: Zip Code | T2: Customer Class | U2: 44287 | V2: 44317 | W2: 44348 | X2: 44652 | AA2: 44682 | AD2: 44713 | AH2: 44197 | AI2: 44228 | AJ2: 44256 | AK2: 44287 | AL2: 44317 | AM2: 44348 | AN2: 44652 | AO2: 44682 | AP2: 44713 | AR2: 44652 | AU2: 44682 | AX2: 44713
D3: ZIP | E3: CLASS | F3: Concat Agreement Number | G3: ZIP | H3: CLASS | I3: Concat Agreement Number | J3: ZIP | K3: CLASS | L3: Concat Agreement Number | N3: 98901 | O3: COM | P3: 4 | Q3: 1 | R3: 2 | S3: 98901 | T3: COM | U3: 1 | V3: 6 | X3: ZIP | Y3: CLASS | Z3: Concat Agreement Number | AA3: ZIP | AB3: CLASS | AC3: Concat Agreement Number | AD3: ZIP | AE3: CLASS | AF3: Concat Agreement Number | AR3: ZIP | AS3: CLASS | AT3: Concat Agreement Number | AU3: ZIP | AV3: CLASS | AW3: Concat Agreement Number | AX3: ZIP | AY3: CLASS | AZ3: Concat Agreement Number
D4: 98901 | E4: COM | F4: 16 | G4: 98901 | H4: COM | I4: 18 | J4: 98901 | K4: COM | L4: 18 | N4: 98901 | O4: RES | P4: 71 | Q4: 53 | R4: 58 | S4: 98901 | T4: RES | U4: 19 | V4: 17 | W4: 19 | X4: 98901 | Y4: COM | Z4: 2 | AA4: 98901 | AB4: RES | AC4: 10 | AD4: 98901 | AE4: COM | AF4: 5 | AR4: 98901 | AS4: RES | AT4: 29 | AU4: 98901 | AV4: RES | AW4: 8 | AX4: 98901 | AY4: RES | AZ4: 20
D5: 98901 | E5: RES | F5: 104 | G5: 98901 | H5: RES | I5: 93 | J5: 98901 | K5: RES | L5: 96 | N5: 98902 | O5: COM | Q5: 6 | R5: 3 | S5: 98902 | T5: COM | U5: 4 | V5: 12 | W5: 5 | X5: 98901 | Y5: RES | Z5: 19 | AA5: 98902 | AB5: COM | AC5: 1 | AD5: 98901 | AE5: RES | AF5: 13 | AR5: 98902 | AS5: COM | AT5: 1 | AU5: 98902 | AV5: COM | AW5: 2 | AX5: 98902 | AY5: RES | AZ5: 11
D6: 98902 | E6: COM | F6: 16 | G6: 98902 | H6: COM | I6: 18 | J6: 98902 | K6: COM | L6: 17 | N6: 98902 | O6: RES | P6: 103 | Q6: 75 | R6: 32 | S6: 98902 | T6: RES | U6: 48 | V6: 22 | W6: 19 | X6: 98902 | Y6: COM | Z6: 4 | AA6: 98902 | AB6: RES | AC6: 18 | AD6: 98902 | AE6: COM | AF6: 4 | AR6: 98902 | AS6: RES | AT6: 33 | AU6: 98902 | AV6: RES | AW6: 23 | AX6: 98903 | AY6: RES | AZ6: 8
D7: 98902 | E7: RES | F7: 119 | G7: 98902 | H7: RES | I7: 109 | J7: 98902 | K7: RES | L7: 105 | N7: 98903 | O7: COM | P7: 6 | R7: 1 | S7: 98903 | T7: COM | U7: 2 | V7: 3 | W7: 3 | X7: 98902 | Y7: RES | Z7: 26 | AA7: 98903 | AB7: COM | AC7: 2 | AD7: 98902 | AE7: RES | AF7: 7 | AR7: 98903 | AS7: COM | AT7: 4 | AU7: 98903 | AV7: RES | AW7: 3 | AX7: 98908 | AY7: RES | AZ7: 17
D8: 98903 | E8: COM | F8: 16 | G8: 98903 | H8: COM | I8: 15 | J8: 98903 | K8: COM | L8: 18 | N8: 98903 | O8: RES | P8: 17 | Q8: 16 | R8: 22 | S8: 98903 | T8: RES | U8: 5 | V8: 1 | W8: 6 | X8: 98903 | Y8: COM | Z8: 3 | AA8: 98903 | AB8: RES | AC8: 1 | AD8: 98903 | AE8: COM | AF8: 1 | AR8: 98903 | AS8: RES | AT8: 4 | AU8: 98908 | AV8: RES | AW8: 9 | AX8: 98930 | AY8: COM | AZ8: 1
D9: 98903 | E9: RES | F9: 35 | G9: 98903 | H9: RES | I9: 37 | J9: 98903 | K9: RES | L9: 35 | N9: 98908 | O9: COM | P9: 4 | Q9: 1 | R9: 2 | S9: 98908 | T9: COM | V9: 4 | W9: 2 | X9: 98903 | Y9: RES | Z9: 6 | AA9: 98908 | AB9: COM | AC9: 1 | AD9: 98903 | AE9: RES | AF9: 5 | AR9: 98908 | AS9: COM | AT9: 1 | AU9: 98930 | AV9: COM | AW9: 3 | AX9: 98930 | AY9: RES | AZ9: 3
D10: 98908 | E10: COM | F10: 10 | G10: 98908 | H10: COM | I10: 11 | J10: 98908 | K10: COM | L10: 12 | N10: 98908 | O10: RES | P10: 37 | Q10: 59 | R10: 47 | S10: 98908 | T10: RES | U10: 31 | V10: 18 | W10: 14 | X10: 98908 | Y10: COM | Z10: 2 | AA10: 98908 | AB10: RES | AC10: 14 | AD10: 98908 | AE10: COM | AF10: 2 | AR10: 98908 | AS10: RES | AT10: 17 | AU10: 98932 | AV10: RES | AW10: 1 | AX10: 98932 | AY10: RES | AZ10: 1
D11: 98908 | E11: RES | F11: 79 | G11: 98908 | H11: RES | I11: 72 | J11: 98908 | K11: RES | L11: 77 | N11: 98921 | O11: RES | P11: 2 | Q11: 1 | S11: 98921 | T11: RES | U11: 2 | X11: 98908 | Y11: RES | Z11: 11 | AA11: 98921 | AB11: RES | AC11: 2 | AD11: 98908 | AE11: RES | AF11: 14 | AR11: 98921 | AS11: RES | AT11: 2 | AU11: 98936 | AV11: RES | AW11: 2 | AX11: 98935 | AY11: RES | AZ11: 1
D12: 98921 | E12: RES | F12: 4 | G12: 98921 | H12: RES | I12: 2 | J12: 98921 | K12: RES | L12: 4 | N12: 98923 | O12: RES | P12: 3 | Q12: 1 | S12: 98923 | T12: RES | U12: 1 | X12: 98930 | Y12: RES | Z12: 5 | AA12: 98930 | AB12: COM | AC12: 3 | AD12: 98930 | AE12: RES | AF12: 2 | AR12: 98930 | AS12: RES | AT12: 6 | AU12: 98937 | AV12: COM | AW12: 1 | AX12: 98936 | AY12: RES | AZ12: 1
D13: 98923 | E13: RES | F13: 1 | G13: 98923 | H13: RES | I13: 1 | J13: 98923 | K13: RES | L13: 1 | N13: 98930 | O13: COM | P13: 2 | Q13: 2 | R13: 1 | S13: 98930 | T13: COM | V13: 2 | X13: 98933 | Y13: COM | Z13: 1 | AA13: 98932 | AB13: COM | AC13: 1 | AD13: 98936 | AE13: RES | AF13: 1 | AR13: 98935 | AS13: RES | AT13: 1 | AU13: 98942 | AV13: RES | AW13: 7 | AX13: 98942 | AY13: RES | AZ13: 6
D14: 98930 | E14: COM | F14: 7 | G14: 98930 | H14: COM | I14: 7 | J14: 98930 | K14: COM | L14: 10 | N14: 98930 | O14: RES | P14: 11 | Q14: 23 | R14: 21 | S14: 98930 | T14: RES | U14: 3 | V14: 2 | W14: 1 | X14: 98935 | Y14: RES | Z14: 1 | AA14: 98935 | AB14: RES | AC14: 1 | AD14: 98942 | AE14: COM | AF14: 3 | AR14: 98936 | AS14: RES | AT14: 2 | AU14: 98944 | AV14: COM | AW14: 1 | AX14: 98944 | AY14: COM | AZ14: 2
D15: 98930 | E15: RES | F15: 35 | G15: 98930 | H15: RES | I15: 34 | J15: 98930 | K15: RES | L15: 34 | N15: 98932 | O15: RES | P15: 5 | Q15: 4 | R15: 6 | S15: 98932 | T15: RES | V15: 3 | X15: 98936 | Y15: COM | Z15: 1 | AA15: 98936 | AB15: COM | AC15: 1 | AD15: 98942 | AE15: RES | AF15: 3 | AR15: 98937 | AS15: RES | AT15: 1 | AU15: 98944 | AV15: RES | AW15: 1 | AX15: 98944 | AY15: RES | AZ15: 4
D16: 98932 | E16: COM | F16: 3 | G16: 98932 | H16: COM | I16: 3 | J16: 98932 | K16: COM | L16: 4 | N16: 98933 | O16: RES | Q16: 1 | S16: 98933 | T16: RES | X16: 98936 | Y16: RES | Z16: 4 | AA16: 98942 | AB16: RES | AC16: 8 | AD16: 98944 | AE16: COM | AF16: 4 | AR16: 98938 | AS16: RES | AT16: 1 | AU16: 98948 | AV16: RES | AW16: 1 | AX16: 98947 | AY16: RES | AZ16: 1
D17: 98932 | E17: RES | F17: 8 | G17: 98932 | H17: RES | I17: 8 | J17: 98932 | K17: RES | L17: 7 | N17: 98935 | O17: COM | Q17: 4 | S17: 98935 | T17: COM | X17: 98938 | Y17: RES | Z17: 1 | AA17: 98944 | AB17: RES | AC17: 3 | AD17: 98944 | AE17: RES | AF17: 1 | AR17: 98942 | AS17: RES | AT17: 3 | AU17: 98951 | AV17: RES | AW17: 5 | AX17: 98948 | AY17: RES | AZ17: 4
D18: 98933 | E18: COM | F18: 1 | G18: 98933 | H18: COM | I18: 2 | J18: 98933 | K18: COM | L18: 2 | N18: 98935 | O18: RES | P18: 6 | Q18: 9 | R18: 1 | S18: 98935 | T18: RES | U18: 2 | V18: 1 | X18: 98942 | Y18: COM | Z18: 1 | AA18: 98951 | AB18: RES | AC18: 4 | AD18: 98947 | AE18: RES | AF18: 1 | AR18: 98944 | AS18: COM | AT18: 1 | AU18: 98953 | AV18: RES | AW18: 1 | AX18: 98951 | AY18: COM | AZ18: 2
D19: 98933 | E19: RES | F19: 1 | G19: 98933 | H19: RES | I19: 1 | J19: 98933 | K19: RES | L19: 1 | N19: 98936 | O19: RES | P19: 2 | Q19: 6 | R19: 5 | S19: 98936 | T19: RES | X19: 98942 | Y19: RES | Z19: 3 | AA19: 98953 | AB19: COM | AC19: 1 | AD19: 98948 | AE19: RES | AF19: 2 | AR19: 98944 | AS19: RES | AT19: 4 | AU19: 99328 | AV19: RES | AW19: 1 | AX19: 98951 | AY19: RES | AZ19: 2
D20: 98935 | E20: COM | F20: 1 | G20: 98935 | H20: COM | I20: 1 | J20: 98935 | K20: COM | L20: 1 | N20: 98937 | O20: RES | P20: 5 | Q20: 2 | R20: 2 | S20: 98937 | T20: COM | U20: 1 | W20: 2 | X20: 98944 | Y20: COM | Z20: 3 | AA20: 98953 | AB20: RES | AC20: 1 | AD20: 98951 | AE20: COM | AF20: 1 | AR20: 98948 | AS20: COM | AT20: 2 | AU20: 99360 | AV20: COM | AW20: 1 | AX20: 98953 | AY20: COM | AZ20: 1
D21: 98935 | E21: RES | F21: 7 | G21: 98935 | H21: RES | I21: 6 | J21: 98935 | K21: RES | L21: 7 | N21: 98938 | O21: COM | P21: 1 | S21: 98937 | T21: RES | V21: 2 | X21: 98944 | Y21: RES | Z21: 4 | AA21: 99324 | AB21: RES | AC21: 1 | AD21: 98953 | AE21: COM | AF21: 2 | AR21: 98951 | AS21: RES | AT21: 6 | AU21: 99360 | AV21: RES | AW21: 1 | AX21: 98953 | AY21: RES | AZ21: 2
D22: 98936 | E22: COM | F22: 7 | G22: 98936 | H22: COM | I22: 7 | J22: 98936 | K22: COM | L22: 8 | N22: 98938 | O22: RES | P22: 7 | Q22: 2 | R22: 1 | S22: 98938 | T22: COM | X22: 98948 | Y22: RES | Z22: 2 | AA22: 99328 | AB22: COM | AC22: 1 | AD22: 98953 | AE22: RES | AF22: 2 | AR22: 98953 | AS22: RES | AT22: 2 | AU22: 99361 | AV22: RES | AW22: 2 | AX22: 99324 | AY22: RES | AZ22: 2
D23: 98936 | E23: RES | F23: 9 | G23: 98936 | H23: RES | I23: 12 | J23: 98936 | K23: RES | L23: 11 | N23: 98939 | O23: RES | P23: 1 | S23: 98938 | T23: RES | X23: 98951 | Y23: COM | Z23: 1 | AA23: 99360 | AB23: RES | AC23: 1 | AD23: 99324 | AE23: RES | AF23: 2 | AR23: 99324 | AS23: RES | AT23: 3 | AU23: 99362 | AV23: COM | AW23: 1 | AX23: 99347 | AY23: RES | AZ23: 1
D24: 98937 | E24: COM | F24: 1 | G24: 98937 | H24: COM | I24: 1 | J24: 98937 | K24: RES | L24: 2 | N24: 98942 | O24: COM | P24: 2 | Q24: 2 | S24: 98939 | T24: RES | X24: 98951 | Y24: RES | Z24: 7 | AA24: 99361 | AB24: RES | AC24: 2 | AD24: 99328 | AE24: COM | AF24: 1 | AR24: 99328 | AS24: COM | AT24: 1 | AU24: 99362 | AV24: RES | AW24: 7 | AX24: 99362 | AY24: COM | AZ24: 4
D25: 98937 | E25: RES | F25: 3 | G25: 98937 | H25: RES | I25: 2 | J25: 98938 | K25: RES | L25: 6 | N25: 98942 | O25: RES | P25: 14 | Q25: 25 | R25: 25 | S25: 98942 | T25: COM | W25: 2 | X25: 98953 | Y25: COM | Z25: 1 | AA25: 99362 | AB25: RES | AC25: 13 | AD25: 99347 | AE25: RES | AF25: 2 | AR25: 99328 | AS25: RES | AT25: 1 | AX25: 99362 | AY25: RES | AZ25: 19
D26: 98938 | E26: RES | F26: 6 | G26: 98938 | H26: RES | I26: 6 | J26: 98939 | K26: RES | L26: 2 | N26: 98944 | O26: COM | P26: 4 | Q26: 1 | R26: 9 | S26: 98942 | T26: RES | U26: 7 | V26: 8 | W26: 6 | X26: 98953 | Y26: RES | Z26: 1 | AD26: 99362 | AE26: COM | AF26: 2 | AR26: 99362 | AS26: COM | AT26: 1
D27: 98939 | E27: RES | F27: 2 | G27: 98939 | H27: RES | I27: 2 | J27: 98942 | K27: COM | L27: 14 | N27: 98944 | O27: RES | P27: 36 | Q27: 21 | R27: 7 | S27: 98944 | T27: COM | U27: 2 | V27: 3 | W27: 1 | X27: 99323 | Y27: RES | Z27: 1 | AD27: 99362 | AE27: RES | AF27: 14 | AR27: 99362 | AS27: RES | AT27: 32
D28: 98942 | E28: COM | F28: 13 | G28: 98942 | H28: COM | I28: 14 | J28: 98942 | K28: RES | L28: 29 | N28: 98947 | O28: RES | P28: 3 | Q28: 5 | S28: 98944 | T28: RES | U28: 13 | V28: 7 | W28: 2 | X28: 99324 | Y28: RES | Z28: 4
D29: 98942 | E29: RES | F29: 27 | G29: 98942 | H29: RES | I29: 28 | J29: 98944 | K29: COM | L29: 20 | N29: 98948 | O29: RES | P29: 20 | Q29: 16 | R29: 20 | S29: 98947 | T29: RES | U29: 4 | V29: 2 | X29: 99360 | Y29: COM | Z29: 2
D30: 98944 | E30: COM | F30: 18 | G30: 98944 | H30: COM | I30: 19 | J30: 98944 | K30: RES | L30: 43 | N30: 98951 | O30: COM | R30: 1 | S30: 98948 | T30: COM | U30: 2 | V30: 5 | X30: 99362 | Y30: COM | Z30: 3
D31: 98944 | E31: RES | F31: 40 | G31: 98944 | H31: RES | I31: 40 | J31: 98947 | K31: RES | L31: 6 | N31: 98951 | O31: RES | P31: 18 | Q31: 24 | R31: 13 | S31: 98948 | T31: RES | U31: 4 | V31: 3 | W31: 1 | X31: 99362 | Y31: RES | Z31: 22
D32: 98947 | E32: RES | F32: 6 | G32: 98947 | H32: RES | I32: 6 | J32: 98948 | K32: COM | L32: 7 | N32: 98952 | O32: RES | Q32: 1 | R32: 2 | S32: 98951 | T32: COM | U32: 1 | V32: 8 | W32: 6
D33: 98948 | E33: COM | F33: 9 | G33: 98948 | H33: COM | I33: 7 | J33: 98948 | K33: RES | L33: 25 | N33: 98953 | O33: COM | R33: 1 | S33: 98951 | T33: RES | U33: 9 | V33: 2
D34: 98948 | E34: RES | F34: 23 | G34: 98948 | H34: RES | I34: 25 | J34: 98951 | K34: COM | L34: 18 | N34: 98953 | O34: RES | P34: 7 | Q34: 6 | R34: 9 | S34: 98952 | T34: RES | V34: 2
D35: 98951 | E35: COM | F35: 17 | G35: 98951 | H35: COM | I35: 18 | J35: 98951 | K35: RES | L35: 30 | N35: 99323 | O35: RES | Q35: 2 | R35: 3 | S35: 98953 | T35: COM | U35: 2
D36: 98951 | E36: RES | F36: 29 | G36: 98951 | H36: RES | I36: 30 | J36: 98952 | K36: RES | L36: 3 | N36: 99324 | O36: RES | P36: 14 | Q36: 8 | R36: 10 | S36: 98953 | T36: RES | U36: 5 | V36: 3
D37: 98952 | E37: RES | F37: 3 | G37: 98952 | H37: RES | I37: 3 | J37: 98953 | K37: COM | L37: 5 | N37: 99328 | O37: COM | R37: 1 | S37: 99323 | T37: COM | U37: 1
D38: 98953 | E38: COM | F38: 3 | G38: 98953 | H38: COM | I38: 4 | J38: 98953 | K38: RES | L38: 12 | N38: 99328 | O38: RES | P38: 7 | Q38: 9 | R38: 4 | S38: 99323 | T38: RES | U38: 2
D39: 98953 | E39: RES | F39: 13 | G39: 98953 | H39: RES | I39: 12 | J39: 99323 | K39: COM | L39: 2 | N39: 99347 | O39: RES | P39: 2 | Q39: 4 | R39: 4 | S39: 99324 | T39: RES | U39: 8 | W39: 7
D40: 99323 | E40: COM | F40: 2 | G40: 99323 | H40: COM | I40: 2 | J40: 99323 | K40: RES | L40: 3 | N40: 99360 | O40: COM | R40: 1 | S40: 99328 | T40: COM | U40: 1 | V40: 2
...

Sheet DEP_WKSHT
A1: Zip Code | B1: CLASS | C1: CountOfConcat Agreement Number | D1: MO | G1: Zip Code | H1: CLASS | I1: CountOfConcat Agreement Number | J1: YRMO | K1: Expr1 | Q1: Sum of CountOfConcat Agreement Number | S1: YRMO | X1: Zip Code | Y1: CLASS | Z1: CountOfConcat Agreement Number | AA1: SumOfAmount | AB1: YRMO | AD1: Sum of CountOfConcat Agreement Number | AF1: YRMO
A2: 98901 | B2: NDEP | C2: 78 | D2: 1 | E2: =VLOOKUP(A2,'6. Deposits 2022_Q2'!$A$3:$A$34,1,FALSE) -> #N/A | G2: 98901 | H2: NDEP | I2: 4 | J2: 202010 | K2: 0 | Q2: CLASS | R2: Zip Code | S2: 202010 | T2: 202011 | U2: 202012 | V2: 20209 | X2: 98901 | Y2: NDEP | Z2: 30 | AA2: 0 | AB2: 10 | AD2: CLASS | AE2: Zip Code | AF2: 10 | AG2: 11 | AH2: 12 | AI2: Grand Total
A3: 98902 | B3: NDEP | C3: 97 | D3: 1 | E3: =VLOOKUP(A3,'6. Deposits 2022_Q2'!$A$3:$A$34,1,FALSE) -> #N/A | G3: 98901 | H3: NDEP | I3: 9 | J3: 202011 | K3: 0 | Q3: NDEP | R3: 98901 | S3: 4 | T3: 9 | U3: 2 | V3: 6 | X3: 98901 | Y3: NDEP | Z3: 16 | AA3: 0 | AB3: 11 | AD3: NDEP | AE3: 98901 | AF3: 30 | AG3: 16 | AH3: 20 | AI3: 66
A4: 98903 | B4: NDEP | C4: 47 | D4: 1 | E4: =VLOOKUP(A4,'6. Deposits 2022_Q2'!$A$3:$A$34,1,FALSE) -> #N/A | G4: 98901 | H4: NDEP | I4: 2 | J4: 202012 | K4: 0 | Q4: NDEP | R4: 98902 | S4: 8 | T4: 2 | U4: 2 | V4: 5 | X4: 98901 | Y4: NDEP | Z4: 20 | AA4: 0 | AB4: 12 | AD4: NDEP | AE4: 98902 | AF4: 24 | AG4: 22 | AH4: 32 | AI4: 78
A5: 98908 | B5: NDEP | C5: 35 | D5: 1 | E5: =VLOOKUP(A5,'6. Deposits 2022_Q2'!$A$3:$A$34,1,FALSE) -> #N/A | G5: 98901 | H5: NDEP | I5: 6 | J5: 20209 | K5: 0 | Q5: NDEP | R5: 98903 | S5: 2 | T5: 2 | V5: 4 | X5: 98901 | Y5: RDEP | Z5: 344 | AA5: 0 | AB5: 10 | AD5: NDEP | AE5: 98903 | AF5: 12 | AG5: 6 | AH5: 8 | AI5: 26
A6: 98920 | B6: NDEP | C6: 2 | D6: 1 | E6: =VLOOKUP(A6,'6. Deposits 2022_Q2'!$A$3:$A$34,1,FALSE) -> #N/A | G6: 98901 | H6: RDEP | I6: 99 | J6: 202010 | K6: 0 | Q6: NDEP | R6: 98908 | T6: 5 | X6: 98901 | Y6: RDEP | Z6: 358 | AA6: 0 | AB6: 11 | AD6: NDEP | AE6: 98908 | AF6: 8 | AG6: 18 | AH6: 12 | AI6: 38
A7: 98921 | B7: NDEP | C7: 2 | D7: 1 | E7: =VLOOKUP(A7,'6. Deposits 2022_Q2'!$A$3:$A$34,1,FALSE) -> #N/A | G7: 98901 | H7: RDEP | I7: 70 | J7: 202011 | K7: 0 | Q7: NDEP | R7: 98930 | S7: 3 | X7: 98901 | Y7: RDEP | Z7: 398 | AA7: 0 | AB7: 12 | AD7: NDEP | AE7: 98920 | AH7: 2 | AI7: 2
A8: 98930 | B8: NDEP | C8: 24 | D8: 1 | E8: =VLOOKUP(A8,'6. Deposits 2022_Q2'!$A$3:$A$34,1,FALSE) -> #N/A | G8: 98901 | H8: RDEP | I8: 26 | J8: 202012 | K8: 0 | Q8: NDEP | R8: 98937 | T8: 3 | U8: 2 | X8: 98902 | Y8: NDEP | Z8: 24 | AA8: 0 | AB8: 10 | AD8: NDEP | AE8: 98930 | AF8: 8 | AG8: 8 | AH8: 4 | AI8: 20
A9: 98932 | B9: NDEP | C9: 7 | D9: 1 | E9: =VLOOKUP(A9,'6. Deposits 2022_Q2'!$A$3:$A$34,1,FALSE) -> #N/A | G9: 98901 | H9: RDEP | I9: 109 | J9: 20209 | K9: 0 | Q9: NDEP | R9: 98942 | S9: 2 | V9: 1 | X9: 98902 | Y9: NDEP | Z9: 22 | AA9: 0 | AB9: 11 | AD9: NDEP | AE9: 98932 | AF9: 2 | AI9: 2
A10: 98933 | B10: NDEP | C10: 3 | D10: 1 | E10: =VLOOKUP(A10,'6. Deposits 2022_Q2'!$A$3:$A$34,1,FALSE) -> #N/A | G10: 98902 | H10: NDEP | I10: 8 | J10: 202010 | K10: 0 | Q10: NDEP | R10: 98944 | S10: 17 | U10: 6 | V10: 2 | X10: 98902 | Y10: NDEP | Z10: 32 | AA10: 0 | AB10: 12 | AD10: NDEP | AE10: 98933 | AF10: 2 | AG10: 4 | AH10: 2 | AI10: 8
A11: 98935 | B11: NDEP | C11: 4 | D11: 1 | E11: =VLOOKUP(A11,'6. Deposits 2022_Q2'!$A$3:$A$34,1,FALSE) -> #N/A | G11: 98902 | H11: NDEP | I11: 2 | J11: 202011 | K11: 0 | Q11: NDEP | R11: 98948 | S11: 2 | X11: 98902 | Y11: RDEP | Z11: 502 | AA11: 0 | AB11: 10 | AD11: NDEP | AE11: 98935 | AF11: 4 | AI11: 4
A12: 98936 | B12: NDEP | C12: 21 | D12: 1 | E12: =VLOOKUP(A12,'6. Deposits 2022_Q2'!$A$3:$A$34,1,FALSE) -> #N/A | G12: 98902 | H12: NDEP | I12: 2 | J12: 202012 | K12: 0 | Q12: NDEP | R12: 98951 | S12: 2 | T12: 2 | U12: 2 | X12: 98902 | Y12: RDEP | Z12: 510 | AA12: 0 | AB12: 11 | AD12: NDEP | AE12: 98936 | AF12: 4 | AG12: 2 | AH12: 24 | AI12: 30
A13: 98937 | B13: NDEP | C13: 10 | D13: 1 | E13: =VLOOKUP(A13,'6. Deposits 2022_Q2'!$A$3:$A$34,1,FALSE) -> #N/A | G13: 98902 | H13: NDEP | I13: 5 | J13: 20209 | K13: 0 | Q13: NDEP | R13: 99324 | T13: 2 | X13: 98902 | Y13: RDEP | Z13: 784 | AA13: 0 | AB13: 12 | AD13: NDEP | AE13: 98937 | AG13: 6 | AH13: 2 | AI13: 8
A14: 98938 | B14: NDEP | C14: 1 | D14: 1 | E14: =VLOOKUP(A14,'6. Deposits 2022_Q2'!$A$3:$A$34,1,FALSE) -> #N/A | G14: 98902 | H14: RDEP | I14: 163 | J14: 202010 | K14: 0 | Q14: NDEP | R14: 99328 | V14: 1 | X14: 98903 | Y14: NDEP | Z14: 12 | AA14: 0 | AB14: 10 | AD14: NDEP | AE14: 98942 | AF14: 8 | AG14: 14 | AH14: 4 | AI14: 26
A15: 98942 | B15: NDEP | C15: 18 | D15: 1 | E15: =VLOOKUP(A15,'6. Deposits 2022_Q2'!$A$3:$A$34,1,FALSE) -> #N/A | G15: 98902 | H15: RDEP | I15: 98 | J15: 202011 | K15: 0 | Q15: NDEP | R15: 99347 | S15: 2 | T15: 2 | X15: 98903 | Y15: NDEP | Z15: 6 | AA15: 0 | AB15: 11 | AD15: NDEP | AE15: 98944 | AF15: 12 | AG15: 26 | AH15: 18 | AI15: 56
A16: 98944 | B16: NDEP | C16: 61 | D16: 1 | E16: =VLOOKUP(A16,'6. Deposits 2022_Q2'!$A$3:$A$34,1,FALSE) -> #N/A | G16: 98902 | H16: RDEP | I16: 53 | J16: 202012 | K16: 0 | Q16: NDEP | R16: 99360 | T16: 2 | X16: 98903 | Y16: NDEP | Z16: 8 | AA16: 0 | AB16: 12 | AD16: NDEP | AE16: 98948 | AF16: 6 | AG16: 2 | AH16: 10 | AI16: 18
A17: 98947 | B17: NDEP | C17: 1 | D17: 1 | E17: =VLOOKUP(A17,'6. Deposits 2022_Q2'!$A$3:$A$34,1,FALSE) -> #N/A | G17: 98902 | H17: RDEP | I17: 127 | J17: 20209 | K17: 0 | Q17: NDEP | R17: 99361 | S17: 2 | V17: 1 | X17: 98903 | Y17: RDEP | Z17: 130 | AA17: 0 | AB17: 10 | AD17: NDEP | AE17: 98951 | AF17: 2 | AG17: 4 | AH17: 16 | AI17: 22
A18: 98948 | B18: NDEP | C18: 29 | D18: 1 | E18: =VLOOKUP(A18,'6. Deposits 2022_Q2'!$A$3:$A$34,1,FALSE) -> #N/A | G18: 98903 | H18: NDEP | I18: 2 | J18: 202010 | K18: 0 | Q18: NDEP | R18: 99362 | S18: 4 | T18: 8 | U18: 3 | V18: 8 | X18: 98903 | Y18: RDEP | Z18: 84 | AA18: 0 | AB18: 11 | AD18: NDEP | AE18: 98952 | AH18: 4 | AI18: 4
A19: 98951 | B19: NDEP | C19: 36 | D19: 1 | E19: =VLOOKUP(A19,'6. Deposits 2022_Q2'!$A$3:$A$34,1,FALSE) -> #N/A | G19: 98903 | H19: NDEP | I19: 2 | J19: 202011 | K19: 0 | Q19: NDEP | R19: 99363 | S19: 1 | X19: 98903 | Y19: RDEP | Z19: 130 | AA19: 0 | AB19: 12 | AD19: NDEP | AE19: 98953 | AF19: 2 | AG19: 2 | AH19: 4 | AI19: 8
A20: 98952 | B20: NDEP | C20: 1 | D20: 1 | E20: =VLOOKUP(A20,'6. Deposits 2022_Q2'!$A$3:$A$34,1,FALSE) -> #N/A | G20: 98903 | H20: NDEP | I20: 4 | J20: 20209 | K20: 0 | Q20: RDEP | R20: 98901 | S20: 99 | T20: 70 | U20: 26 | V20: 109 | X20: 98908 | Y20: NDEP | Z20: 8 | AA20: 0 | AB20: 10 | AD20: NDEP | AE20: 99323 | AH20: 2 | AI20: 2
A21: 98953 | B21: NDEP | C21: 10 | D21: 1 | E21: =VLOOKUP(A21,'6. Deposits 2022_Q2'!$A$3:$A$34,1,FALSE) -> #N/A | G21: 98903 | H21: RDEP | I21: 27 | J21: 202010 | K21: 0 | Q21: RDEP | R21: 98902 | S21: 163 | T21: 98 | U21: 53 | V21: 127 | X21: 98908 | Y21: NDEP | Z21: 18 | AA21: 0 | AB21: 11 | AD21: NDEP | AE21: 99324 | AG21: 4 | AH21: 2 | AI21: 6
A22: 99323 | B22: NDEP | C22: 1 | D22: 1 | E22: =VLOOKUP(A22,'6. Deposits 2022_Q2'!$A$3:$A$34,1,FALSE) -> #N/A | G22: 98903 | H22: RDEP | I22: 5 | J22: 202011 | K22: 0 | Q22: RDEP | R22: 98903 | S22: 27 | T22: 5 | U22: 12 | V22: 26 | X22: 98908 | Y22: NDEP | Z22: 12 | AA22: 0 | AB22: 12 | AD22: NDEP | AE22: 99328 | AF22: 2 | AH22: 2 | AI22: 4
A23: 99324 | B23: NDEP | C23: 4 | D23: 1 | E23: =VLOOKUP(A23,'6. Deposits 2022_Q2'!$A$3:$A$34,1,FALSE) -> #N/A | G23: 98903 | H23: RDEP | I23: 12 | J23: 202012 | K23: 0 | Q23: RDEP | R23: 98908 | S23: 136 | T23: 107 | U23: 32 | V23: 123 | X23: 98908 | Y23: RDEP | Z23: 320 | AA23: 0 | AB23: 10 | AD23: NDEP | AE23: 99347 | AG23: 4 | AI23: 4
A24: 99328 | B24: NDEP | C24: 5 | D24: 1 | E24: =VLOOKUP(A24,'6. Deposits 2022_Q2'!$A$3:$A$34,1,FALSE) -> #N/A | G24: 98903 | H24: RDEP | I24: 26 | J24: 20209 | K24: 0 | Q24: RDEP | R24: 98921 | S24: 7 | T24: 4 | V24: 4 | X24: 98908 | Y24: RDEP | Z24: 450 | AA24: 0 | AB24: 11 | AD24: NDEP | AE24: 99360 | AG24: 4 | AH24: 2 | AI24: 6
A25: 99329 | B25: NDEP | C25: 1 | D25: 1 | E25: =VLOOKUP(A25,'6. Deposits 2022_Q2'!$A$3:$A$34,1,FALSE) -> #N/A | G25: 98908 | H25: NDEP | I25: 5 | J25: 202011 | K25: 0 | Q25: RDEP | R25: 98923 | S25: 3 | T25: 2 | U25: 1 | V25: 2 | X25: 98908 | Y25: RDEP | Z25: 350 | AA25: 0 | AB25: 12 | AD25: NDEP | AE25: 99361 | AH25: 6 | AI25: 6
A26: 99347 | B26: NDEP | C26: 3 | D26: 1 | E26: =VLOOKUP(A26,'6. Deposits 2022_Q2'!$A$3:$A$34,1,FALSE) -> #N/A | G26: 98908 | H26: RDEP | I26: 136 | J26: 202010 | K26: 0 | Q26: RDEP | R26: 98930 | S26: 29 | T26: 10 | U26: 18 | V26: 15 | X26: 98920 | Y26: NDEP | Z26: 2 | AA26: 0 | AB26: 12 | AD26: NDEP | AE26: 99362 | AF26: 18 | AG26: 20 | AH26: 16 | AI26: 54
A27: 99360 | B27: NDEP | C27: 3 | D27: 1 | E27: =VLOOKUP(A27,'6. Deposits 2022_Q2'!$A$3:$A$34,1,FALSE) -> #N/A | G27: 98908 | H27: RDEP | I27: 107 | J27: 202011 | K27: 0 | Q27: RDEP | R27: 98932 | S27: 7 | T27: 17 | U27: 8 | V27: 7 | X27: 98921 | Y27: RDEP | Z27: 6 | AA27: 0 | AB27: 10 | AD27: RDEP | AE27: 98901 | AF27: 344 | AG27: 358 | AH27: 398 | AI27: 1100
A28: 99361 | B28: NDEP | C28: 6 | D28: 1 | E28: =VLOOKUP(A28,'6. Deposits 2022_Q2'!$A$3:$A$34,1,FALSE) -> #N/A | G28: 98908 | H28: RDEP | I28: 32 | J28: 202012 | K28: 0 | Q28: RDEP | R28: 98933 | S28: 3 | T28: 3 | U28: 3 | V28: 1 | X28: 98921 | Y28: RDEP | Z28: 18 | AA28: 0 | AB28: 11 | AD28: RDEP | AE28: 98902 | AF28: 502 | AG28: 510 | AH28: 784 | AI28: 1796
A29: 99362 | B29: NDEP | C29: 62 | D29: 1 | E29: =VLOOKUP(A29,'6. Deposits 2022_Q2'!$A$3:$A$34,1,FALSE) -> #N/A | G29: 98908 | H29: RDEP | I29: 123 | J29: 20209 | K29: 0 | Q29: RDEP | R29: 98935 | S29: 5 | T29: 6 | U29: 2 | V29: 4 | X29: 98921 | Y29: RDEP | Z29: 14 | AA29: 0 | AB29: 12 | AD29: RDEP | AE29: 98903 | AF29: 130 | AG29: 84 | AH29: 130 | AI29: 344
A30: 99363 | B30: NDEP | C30: 1 | D30: 1 | E30: =VLOOKUP(A30,'6. Deposits 2022_Q2'!$A$3:$A$34,1,FALSE) -> #N/A | G30: 98921 | H30: RDEP | I30: 7 | J30: 202010 | K30: 0 | Q30: RDEP | R30: 98936 | S30: 6 | T30: 10 | U30: 6 | V30: 5 | X30: 98923 | Y30: RDEP | Z30: 4 | AA30: 0 | AB30: 10 | AD30: RDEP | AE30: 98908 | AF30: 320 | AG30: 450 | AH30: 350 | AI30: 1120
A31: 98901 | B31: RDEP | C31: 1427 | D31: 1 | E31: =VLOOKUP(A31,'6. Deposits 2022_Q2'!$A$35:$A$61,1,FALSE) -> #N/A | G31: 98921 | H31: RDEP | I31: 4 | J31: 202011 | K31: 0 | Q31: RDEP | R31: 98937 | S31: 9 | T31: 2 | U31: 3 | V31: 7 | X31: 98923 | Y31: RDEP | Z31: 4 | AA31: 0 | AB31: 11 | AD31: RDEP | AE31: 98921 | AF31: 6 | AG31: 18 | AH31: 14 | AI31: 38
A32: 98902 | B32: RDEP | C32: 1838 | D32: 1 | E32: =VLOOKUP(A32,'6. Deposits 2022_Q2'!$A$35:$A$61,1,FALSE) -> #N/A | G32: 98921 | H32: RDEP | I32: 4 | J32: 20209 | K32: 0 | Q32: RDEP | R32: 98938 | S32: 1 | U32: 4 | X32: 98923 | Y32: RDEP | Z32: 16 | AA32: 0 | AB32: 12 | AD32: RDEP | AE32: 98923 | AF32: 4 | AG32: 4 | AH32: 16 | AI32: 24
A33: 98903 | B33: RDEP | C33: 403 | D33: 1 | E33: =VLOOKUP(A33,'6. Deposits 2022_Q2'!$A$35:$A$61,1,FALSE) -> #N/A | G33: 98923 | H33: RDEP | I33: 3 | J33: 202010 | K33: 0 | Q33: RDEP | R33: 98939 | U33: 1 | X33: 98930 | Y33: NDEP | Z33: 8 | AA33: 0 | AB33: 10 | AD33: RDEP | AE33: 98930 | AF33: 90 | AG33: 74 | AH33: 120 | AI33: 284
A34: 98908 | B34: RDEP | C34: 1026 | D34: 1 | E34: =VLOOKUP(A34,'6. Deposits 2022_Q2'!$A$35:$A$61,1,FALSE) -> #N/A | G34: 98923 | H34: RDEP | I34: 2 | J34: 202011 | K34: 0 | Q34: RDEP | R34: 98942 | S34: 42 | T34: 27 | U34: 12 | V34: 36 | X34: 98930 | Y34: NDEP | Z34: 8 | AA34: 0 | AB34: 11 | AD34: RDEP | AE34: 98932 | AF34: 30 | AG34: 72 | AH34: 62 | AI34: 164
A35: 98921 | B35: RDEP | C35: 31 | D35: 1 | E35: =VLOOKUP(A35,'6. Deposits 2022_Q2'!$A$35:$A$61,1,FALSE) -> #N/A | G35: 98923 | H35: RDEP | I35: 1 | J35: 202012 | K35: 0 | Q35: RDEP | R35: 98944 | S35: 23 | T35: 30 | U35: 15 | V35: 31 | X35: 98930 | Y35: NDEP | Z35: 4 | AA35: 0 | AB35: 12 | AD35: RDEP | AE35: 98933 | AF35: 4 | AG35: 4 | AH35: 14 | AI35: 22
A36: 98923 | B36: RDEP | C36: 30 | D36: 1 | E36: =VLOOKUP(A36,'6. Deposits 2022_Q2'!$A$35:$A$61,1,FALSE) -> #N/A | G36: 98923 | H36: RDEP | I36: 2 | J36: 20209 | K36: 0 | Q36: RDEP | R36: 98947 | S36: 4 | T36: 2 | U36: 3 | V36: 1 | X36: 98930 | Y36: RDEP | Z36: 90 | AA36: 0 | AB36: 10 | AD36: RDEP | AE36: 98935 | AF36: 30 | AG36: 16 | AH36: 36 | AI36: 82
A37: 98930 | B37: RDEP | C37: 336 | D37: 1 | E37: =VLOOKUP(A37,'6. Deposits 2022_Q2'!$A$35:$A$61,1,FALSE) -> #N/A | G37: 98930 | H37: NDEP | I37: 3 | J37: 202010 | K37: 0 | Q37: RDEP | R37: 98948 | S37: 24 | T37: 4 | U37: 4 | V37: 10 | X37: 98930 | Y37: RDEP | Z37: 74 | AA37: 0 | AB37: 11 | AD37: RDEP | AE37: 98936 | AF37: 38 | AG37: 26 | AH37: 80 | AI37: 144
A38: 98932 | B38: RDEP | C38: 165 | D38: 1 | E38: =VLOOKUP(A38,'6. Deposits 2022_Q2'!$A$35:$A$61,1,FALSE) -> #N/A | G38: 98930 | H38: RDEP | I38: 29 | J38: 202010 | K38: 0 | Q38: RDEP | R38: 98951 | S38: 16 | T38: 12 | U38: 8 | V38: 10 | X38: 98930 | Y38: RDEP | Z38: 120 | AA38: 0 | AB38: 12 | AD38: RDEP | AE38: 98937 | AF38: 20 | AG38: 30 | AH38: 38 | AI38: 88
A39: 98933 | B39: RDEP | C39: 24 | D39: 1 | E39: =VLOOKUP(A39,'6. Deposits 2022_Q2'!$A$35:$A$61,1,FALSE) -> #N/A | G39: 98930 | H39: RDEP | I39: 10 | J39: 202011 | K39: 0 | Q39: RDEP | R39: 98952 | S39: 1 | U39: 1 | X39: 98932 | Y39: NDEP | Z39: 2 | AA39: 0 | AB39: 10 | AD39: RDEP | AE39: 98938 | AF39: 24 | AG39: 14 | AH39: 40 | AI39: 78
A40: 98935 | B40: RDEP | C40: 85 | D40: 1 | E40: =VLOOKUP(A40,'6. Deposits 2022_Q2'!$A$35:$A$61,1,FALSE) -> #N/A | G40: 98930 | H40: RDEP | I40: 18 | J40: 202012 | K40: 0 | Q40: RDEP | R40: 98953 | S40: 7 | T40: 9 | V40: 10 | X40: 98932 | Y40: RDEP | Z40: 30 | AA40: 0 | AB40: 10 | AD40: RDEP | AE40: 98939 | AF40: 4 | AG40: 4 | AH40: 2 | AI40: 10
...

Sheet 7. Bill Assistance 2022_Q2
A1: Item a) Number of Premises Receiving Bill Assistance or Enrolled in Any Other Assistance Program
A2: 44197 | B2: 44228 | C2: 44256 | D2: ZIP ** | E2: 44287 | F2: 44317 | G2: 44348 | H2: 44378 | I2: 44409 | J2: 44440 | K2: 44470 | L2: 44501 | M2: 44531 | N2: Zip Code | O2: 44652 | P2: Zip Code | Q2: 44682 | R2: Zip Code | S2: 44713
A3: 44 | B3: 89 | C3: 87 | D3: 98901 | E3: 349 | F3: 108 | G3: 51 | N3: 98901 | O3: 1041 | P3: 98901 | Q3: 1032 | R3: 98901 | S3: 1010
A4: 70 | B4: 149 | C4: 107 | D4: 98902 | E4: 411 | F4: 123 | G4: 72 | N4: 98902 | O4: 1331 | P4: 98902 | Q4: 1316 | R4: 98902 | S4: 1305
A5: 24 | B5: 48 | C5: 38 | D5: 98903 | E5: 138 | F5: 31 | G5: 17 | N5: 98903 | O5: 436 | P5: 98903 | Q5: 430 | R5: 98903 | S5: 421
A6: 19 | B6: 33 | C6: 35 | D6: 98908 | E6: 111 | F6: 51 | G6: 23 | N6: 98908 | O6: 432 | P6: 98908 | Q6: 418 | R6: 98908 | S6: 406
A7: 6 | B7: 7 | C7: 7 | D7: 98921 | E7: 22 | F7: 7 | G7: 2 | N7: 98921 | O7: 38 | P7: 98921 | Q7: 39 | R7: 98921 | S7: 38
A8: 1 | B8: 1 | C8: 3 | D8: 98923 | E8: 6 | F8: 3 | G8: 4 | N8: 98923 | O8: 22 | P8: 98923 | Q8: 22 | R8: 98923 | S8: 22
A9: 43 | B9: 35 | C9: 40 | D9: 98930 | E9: 83 | F9: 29 | G9: 31 | N9: 98930 | O9: 343 | P9: 98930 | Q9: 340 | R9: 98930 | S9: 333
A10: 17 | B10: 10 | C10: 12 | D10: 98932 | E10: 38 | F10: 17 | G10: 13 | N10: 98932 | O10: 162 | P10: 98932 | Q10: 162 | R10: 98932 | S10: 158
A11: 2 | B11: 2 | D11: 98933 | E11: 6 | F11: 2 | G11: 1 | N11: 98933 | O11: 13 | P11: 98933 | Q11: 13 | R11: 98933 | S11: 13
A12: 13 | B12: 6 | C12: 5 | D12: 98935 | E12: 30 | F12: 16 | G12: 14 | N12: 98935 | O12: 120 | P12: 98935 | Q12: 121 | R12: 98935 | S12: 120
A13: 6 | B13: 1 | C13: 5 | D13: 98936 | E13: 20 | F13: 3 | G13: 2 | N13: 98936 | O13: 80 | P13: 98936 | Q13: 75 | R13: 98936 | S13: 74
A14: 3 | B14: 3 | C14: 2 | D14: 98937 | E14: 8 | F14: 3 | G14: 2 | N14: 98937 | O14: 42 | P14: 98937 | Q14: 43 | R14: 98937 | S14: 45
A15: 6 | B15: 3 | C15: 5 | D15: 98938 | E15: 12 | F15: 1 | G15: 8 | N15: 98938 | O15: 33 | P15: 98938 | Q15: 33 | R15: 98938 | S15: 33
B16: 1 | C16: 1 | D16: 98939 | E16: 1 | F16: 4 | G16: 1 | N16: 98939 | O16: 10 | P16: 98939 | Q16: 13 | R16: 98939 | S16: 10
A17: 10 | B17: 14 | C17: 8 | D17: 98942 | E17: 49 | F17: 7 | G17: 12 | N17: 98942 | O17: 164 | P17: 98942 | Q17: 161 | R17: 98942 | S17: 157
A18: 79 | B18: 51 | C18: 52 | D18: 98944 | E18: 169 | F18: 45 | G18: 55 | N18: 98944 | O18: 656 | P18: 98944 | Q18: 658 | R18: 98944 | S18: 652
A19: 6 | B19: 7 | C19: 6 | D19: 98947 | E19: 17 | F19: 5 | G19: 8 | N19: 98947 | O19: 75 | P19: 98947 | Q19: 72 | R19: 98947 | S19: 75
A20: 40 | B20: 42 | C20: 31 | D20: 98948 | E20: 178 | F20: 27 | G20: 41 | N20: 98948 | O20: 375 | P20: 98948 | Q20: 372 | R20: 98948 | S20: 353
A21: 34 | B21: 39 | C21: 40 | D21: 98951 | E21: 194 | F21: 27 | G21: 26 | N21: 98951 | O21: 298 | P21: 98951 | Q21: 286 | R21: 98951 | S21: 266
A22: 1 | B22: 3 | C22: 2 | D22: 98952 | E22: 20 | F22: 1 | G22: 2 | N22: 98952 | O22: 9 | P22: 98952 | Q22: 6 | R22: 98952 | S22: 2
A23: 11 | B23: 7 | C23: 6 | D23: 98953 | E23: 23 | F23: 6 | G23: 5 | N23: 98953 | O23: 83 | P23: 98953 | Q23: 83 | R23: 98953 | S23: 81
A24: 3 | B24: 2 | C24: 1 | D24: 99323 | E24: 4 | F24: 2 | G24: 3 | N24: 99323 | O24: 18 | P24: 99323 | Q24: 19 | R24: 99323 | S24: 18
A25: 13 | B25: 20 | C25: 23 | D25: 99324 | E25: 57 | F25: 4 | G25: 11 | N25: 99324 | O25: 126 | P25: 99324 | Q25: 129 | R25: 99324 | S25: 126
A26: 3 | C26: 2 | D26: 99328 | E26: 36 | F26: 2 | G26: 3 | N26: 99328 | O26: 87 | P26: 99328 | Q26: 87 | R26: 99328 | S26: 87
B27: 1 | C27: 1 | D27: 99347 | E27: 15 | F27: 0 | G27: 4 | N27: 99329 | O27: 3 | P27: 99329 | Q27: 3 | R27: 99329 | S27: 3
A28: 4 | B28: 3 | C28: 2 | D28: 99348 | E28: 4 | F28: 0 | G28: 2 | N28: 99347 | O28: 35 | P28: 99347 | Q28: 35 | R28: 99347 | S28: 35
A29: 1 | D29: 99360 | E29: 3 | F29: 0 | G29: 1 | N29: 99348 | O29: 12 | P29: 99348 | Q29: 10 | R29: 99348 | S29: 11
A30: 1 | B30: 1 | D30: 99361 | E30: 8 | F30: 2 | G30: 2 | N30: 99350 | O30: 2 | P30: 99350 | Q30: 2 | R30: 99350 | S30: 2
A31: 6 | B31: 6 | C31: 1 | D31: 99362 | E31: 311 | F31: 46 | G31: 96 | N31: 99360 | O31: 5 | P31: 99360 | Q31: 6 | R31: 99360 | S31: 5
A32: 69 | B32: 81 | C32: 92 | D32: 99363 | E32: 2 | F32: 1 | G32: 0 | N32: 99361 | O32: 20 | P32: 99361 | Q32: 19 | R32: 99361 | S32: 19
D33: 98907 | E33: 0 | F33: 1 | G33: 0 | N33: 99362 | O33: 737 | P33: 99362 | Q33: 725 | R33: 99362 | S33: 716
D34: 98909 | E34: 0 | F34: 1 | G34: 0 | N34: 99363 | O34: 3 | P34: 99363 | Q34: 3 | R34: 99363 | S34: 3
N35: TOTAL | O35: =SUM(O3:O34) -> 6811 | Q35: =SUM(Q3:Q34) -> 6733 | S35: =SUM(S3:S34) -> 6599

Sheet BA_WRKSHT
A1: FLAG | B1: SumOfJAN20 | C1: SumOfFEB20 | D1: SumOfMAR20 | E1: SumOfAPR20 | F1: SumOfMAY20 | G1: SumOfJUN20 | H1: SumOfJUL20 | I1: SumOfAUG20 | J1: SumOfSEP20 | K1: SumOfOCT20 | L1: SumOfNOV20 | M1: SumOfDEC20 | N1: SumOfJAN19 | O1: SumOfFEB19 | P1: SumOfMAR19 | Q1: SumOfAPR19 | R1: SumOfMAY19 | S1: SumOfJUN19 | T1: SumOfJUL19 | U1: SumOfAUG19 | V1: SumOfSEP19 | W1: SumOfOCT19 | X1: SumOfNOV19 | Y1: SumOfDEC19
A2: 98901RES | B2: 37 | C2: 35 | D2: 33 | E2: 31 | F2: 31 | G2: 31 | H2: 30 | I2: 27 | J2: 27 | K2: 27 | L2: 24 | M2: 24 | N2: 23 | O2: 28 | P2: 28 | Q2: 30 | R2: 32 | S2: 33 | T2: 33 | U2: 35 | V2: 36 | W2: 37 | X2: 38 | Y2: 39
A3: 98902RES | B3: 54 | C3: 51 | D3: 48 | E3: 46 | F3: 43 | G3: 41 | H3: 38 | I3: 34 | J3: 33 | K3: 29 | L3: 27 | M3: 24 | N3: 24 | O3: 31 | P3: 34 | Q3: 38 | R3: 39 | S3: 43 | T3: 45 | U3: 47 | V3: 48 | W3: 50 | X3: 51 | Y3: 53
A4: 98903RES | B4: 26 | C4: 26 | D4: 24 | E4: 24 | F4: 23 | G4: 21 | H4: 22 | I4: 23 | J4: 23 | K4: 22 | L4: 22 | M4: 21 | N4: 22 | O4: 23 | P4: 24 | Q4: 26 | R4: 26 | S4: 27 | T4: 26 | U4: 26 | V4: 25 | W4: 26 | X4: 26 | Y4: 26
A5: 98908RES | B5: 29 | C5: 29 | D5: 27 | E5: 27 | F5: 27 | G5: 26 | H5: 26 | I5: 25 | J5: 26 | K5: 26 | L5: 26 | M5: 23 | N5: 23 | O5: 26 | P5: 26 | Q5: 26 | R5: 25 | S5: 25 | T5: 25 | U5: 26 | V5: 27 | W5: 27 | X5: 26 | Y5: 28
A6: 98921RES | B6: 10 | C6: 10 | D6: 9 | E6: 9 | F6: 9 | G6: 10 | H6: 9 | I6: 9 | J6: 7 | K6: 7 | L6: 7 | M6: 7 | N6: 12 | O6: 13 | P6: 12 | Q6: 12 | R6: 12 | S6: 11 | T6: 11 | U6: 10 | V6: 10 | W6: 10 | X6: 10 | Y6: 10
A7: 98923RES | B7: 3 | C7: 4 | D7: 3 | E7: 4 | F7: 3 | G7: 3 | H7: 4 | I7: 3 | J7: 4 | K7: 3 | L7: 4 | M7: 4 | N7: 4 | O7: 4 | P7: 5 | Q7: 4 | R7: 4 | S7: 5 | T7: 4 | U7: 4 | V7: 5 | W7: 5 | X7: 4 | Y7: 4
A8: 98930RES | B8: 33 | C8: 32 | D8: 32 | E8: 32 | F8: 30 | G8: 29 | H8: 28 | I8: 28 | J8: 28 | K8: 24 | L8: 21 | M8: 20 | N8: 21 | O8: 22 | P8: 25 | Q8: 25 | R8: 26 | S8: 27 | T8: 28 | U8: 28 | V8: 32 | W8: 31 | X8: 32 | Y8: 32
A9: 98932RES | B9: 21 | C9: 20 | D9: 21 | E9: 22 | F9: 21 | G9: 18 | H9: 18 | I9: 18 | J9: 17 | K9: 16 | L9: 15 | M9: 14 | N9: 16 | O9: 17 | P9: 17 | Q9: 17 | R9: 17 | S9: 19 | T9: 19 | U9: 20 | V9: 19 | W9: 20 | X9: 21 | Y9: 21
A10: 98933RES | B10: 4 | C10: 4 | D10: 4 | E10: 4 | F10: 4 | G10: 4 | H10: 4 | I10: 3 | J10: 2 | K10: 2 | L10: 2 | M10: 3 | N10: 2 | O10: 3 | P10: 3 | Q10: 3 | R10: 2 | S10: 3 | T10: 1 | U10: 1 | V10: 1 | W10: 2 | X10: 3 | Y10: 3
A11: 98935RES | B11: 12 | C11: 12 | D11: 12 | E11: 12 | F11: 12 | G11: 11 | H11: 10 | I11: 10 | J11: 10 | K11: 10 | L11: 10 | M11: 8 | N11: 9 | O11: 10 | P11: 10 | Q11: 9 | R11: 10 | S11: 11 | T11: 11 | U11: 10 | V11: 10 | W11: 12 | X11: 12 | Y11: 12
A12: 98936RES | B12: 8 | C12: 8 | D12: 7 | E12: 8 | F12: 7 | G12: 8 | H12: 8 | I12: 8 | J12: 8 | K12: 10 | L12: 10 | M12: 9 | N12: 7 | O12: 7 | P12: 7 | Q12: 7 | R12: 6 | S12: 6 | T12: 6 | U12: 5 | V12: 5 | W12: 7 | X12: 6 | Y12: 8
A13: 98937RES | B13: 9 | C13: 10 | D13: 9 | E13: 9 | F13: 8 | G13: 10 | H13: 10 | I13: 9 | J13: 10 | K13: 9 | L13: 9 | M13: 9 | N13: 7 | O13: 7 | P13: 7 | Q13: 7 | R13: 8 | S13: 8 | T13: 7 | U13: 7 | V13: 7 | W13: 9 | X13: 8 | Y13: 9
... A33: 99363RES | B33: 3 | C33: 2 | D33: 2 | E33: 2 | F33: 2 | G33: 2 | H33: 2 | I33: 1 | J33: 2 | K33: 1 | L33: 1 | M33: 1 | N33: 2 | O33: 2 | P33: 2 | Q33: 3 | R33: 2 | S33: 2 | T33: 2 | U33: 2 | V33: 2 | W33: 2 | X33: 2 | Y33: 3

Sheet 8.ARREARS NEW 2022_Q2
A1: Item a) Number of Customers by Customer Class With Past-due balances (arrearages) | V1: Item c) Amount of Past-due Balances for Known Low-income Households and Number of Days Past-due | CH1: Section D. Bad Debt | CQ1: Item e) The Amount of Past-due Balances Written-off and Classified as Bad Debt, if different than item d | DD1: Item f) Number of Customer Accounts Referred to Collection Agencies | DM1: Item f) Total Amount of Bad Debt Referred for Collection | DS1: Item f) Total Revenue to the Company from the Collection Process
V2: EAP | CJ2: 0.32
A3: 202204 | H3: 202205 | O3: 202206 | X3: 202101 | AC3: 202102 | AH3: 202103 | AO3: 202104 | AT3: 202105 | AY3: 202106 | BD3: 202204 | BK3: 202205 | BR3: 202206 | CH3: 202204 | CK3: 202205 | CN3: 202206 | CQ3: Class | CR3: 202101 | CS3: 202102 | CT3: 202103 | CU3: 202104 | CV3: 202105 | CW3: 202106 | CX3: 202107 | CY3: 202108 | CZ3: 202109 | DA3: 202204 | DB3: 202205 | DC3: 202206 | DD3: 202204 | DG3: 202205 | DJ3: 202206 | DM3: 202204 | DO3: 202205 | DQ3: 202206 | DS3: 202204 | DU3: 202205 | DW3: 202206
A4: CLASS | B4: ZIP | C4: COUNT | D4: DAYS 31 60 | E4: DAYS 61 90 | F4: DAYS 91+ | G4: ARREARS | H4: CLASS | I4: ZIP | J4: COUNT | K4: DAYS 31 60 | L4: DAYS 61 90 | M4: DAYS 91+ | N4: ARREARS | O4: ZIP | P4: COUNT | Q4: COUNT | R4: DAYS 31 60 | S4: DAYS 61 90 | T4: DAYS 91+ | U4: ARREARS | V4: CLASS | W4: ZIP | X4: Count | Y4: Days 31 60 | Z4: Days 61 90 | AA4: Days 91+ | AB4: Arrears | AC4: Count | AD4: Days 31 60 | AE4: Days 61 90 | AF4: Days 91+ | AG4: Arrears | AH4: Count | AI4: Days 31 60 | AJ4: Days 61 90 | AK4: Days 91+ | AL4: Arrears | AM4: Agrmt Revenue Class Cd | AN4: Zip Code | AO4: Count | AP4: Days 31 60 | AQ4: Days 61 90 | AR4: Days 91+ | AS4: Arrears | AT4: Count | AU4: Days 31 60 | AV4: Days 61 90 | AW4: Days 91+ | AX4: Arrears | AY4: Count | AZ4: Days 31 60 | BA4: Days 61 90 | BB4: Days 91+ | BC4: Arrears | BD4: CLASS | BE4: ZIP | BF4: COUNT | BG4: DAYS 31 60 | BH4: DAYS 61 90 | BI4: DAYS 91+ | BJ4: ARREARS | BK4: CLASS | BL4: ZIP | BM4: COUNT | BN4: DAYS 31 60 | BO4: DAYS 61 90 | BP4: DAYS 91+ | BQ4: ARREARS | BR4: CLASS | BS4: ZIP | BT4: COUNT | BU4: DAYS 31 60 | BV4: DAYS 61 90 | BW4: DAYS 91+ | BX4: ARREARS | CH4: CLASS | CI4: ZIP | CJ4: BAD DEBT | CK4: CLASS | CL4: ZIP | CM4: BAD DEBT | CN4: CLASS | CO4: ZIP | CP4: BAD DEBT | CQ4: RES | CR4: 78547.88 | CS4: 83507.78 | CT4: 74673.15 | CU4: 63441.04 | CV4: 64476.9 | CW4: 57542.34 | CX4: 83815.89 | CY4: 81559.71 | CZ4: 121882.53 | DA4: 161527.14 | DB4: 197790.97 | DC4: 165796.26 | DD4: ZIP | DE4: CLASS | DF4: 202204 | DG4: ZIP | DH4: CLASS | DI4: 202205 | DJ4: Zip Code | DK4: Revenue Class Cd | DL4: 202206 | DM4: ZIP/CLASS | DN4: 202204 | DO4: ZIP/CLASS | DP4: 202205 | DQ4: ZIP/CLASS | DR4: 202206 | DS4: ZIP/CLASS | DT4: 202204 | DU4: ZIP/CLASS | DV4: 202205 | DW4: ZIP/CLASS | DX4: 202206
A5: COM | B5: 98901 | C5: 144 | D5: 61058.34 | E5: 26917.46 | F5: 149187.34 | G5: 237163.14 | H5: COM | I5: 98901 | J5: 150 | K5: 36240.65 | L5: 25142.84 | M5: 157378.33 | N5: 218761.82 | O5: COM | P5: 98901 | Q5: 137 | R5: 55526.69 | S5: 25500.16 | T5: 168042.41 | U5: 249069.26 | V5: COM | W5: 98901 | X5: 1 | Y5: 82.45 | Z5: 53.83 | AA5: 302.58 | AB5: 438.86 | AC5: 1 | AD5: 84.64 | AE5: 82.45 | AF5: 356.41 | AG5: 523.5 | AH5: 1 | AI5: 85.48 | AJ5: 84.64 | AK5: 438.86 | AL5: 608.98 | AM5: COM | AN5: 98901 | AO5: 2 | AP5: 281.67 | AQ5: 312.97 | AR5: 971.94 | AS5: 1566.58 | AT5: 1 | AU5: 59.27 | AV5: 84.24 | AW5: 608.98 | AX5: 752.49 | AY5: 1 | AZ5: 39.33 | BA5: 59.27 | BB5: 693.22 | BC5: 791.82 | BD5: COM | BE5: 98901 | BF5: 2 | BG5: 175.1 | BH5: 218.66 | BI5: 483.39 | BJ5: 877.15 | BK5: COM | BL5: 98901 | BM5: 4 | BN5: 208.5 | BO5: 175.1 | BP5: 702.05 | BQ5: 1085.65 | BR5: COM | BS5: 98901 | BT5: 3 | BU5: 57.09 | BV5: 58.25 | BW5: 68.07 | BX5: 183.41 | CH5: =A5 -> COM | CI5: =B5 -> 98901 | CJ5: =D5*1.6%+E5*6.3%+F5*28.9% -> 45787.875 | CK5: =H5 -> COM | CL5: =I5 -> 98901 | CM5: =K5*1.6%+L5*6.3%+M5*28.9% -> 47646.187 | CN5: =O5 -> COM | CO5: =P5 -> 98901 | CP5: =R5*1.6%+S5*6.3%+T5*28.9% -> 51059.194 | CQ5: COM | CR5: 35411.49 | CS5: 19861.99 | CT5: 1614.2 | CU5: 209.93 | CV5: 2347.21 | CW5: 3702.39 | CX5: 16587.84 | CY5: 21717.76 | CZ5: 41593.57 | DA5: 26622.79 | DB5: 22917.54 | DC5: 16743.23 | DD5: 98901 | DE5: COM | DF5: 7 | DG5: 98901 | DH5: COM | DI5: 3 | DJ5: 98901 | DK5: COM | DL5: 1 | DM5: 98901COM | DN5: 3846.37 | DO5: 98901COM | DP5: 520.66 | DQ5: 98901COM | DR5: 1526.8 | DS5: 98901RES | DT5: 1498.41 | DU5: 98901COM | DV5: 483.7 | DW5: 98901RES | DX5: 813.78
A6: COM | B6: 98902 | C6: 211 | D6: 77087.2 | E6: 28345.49 | F6: 125741.79 | G6: 231174.48 | H6: COM | I6: 98902 | J6: 217 | K6: 92293.42 | L6: 21740.24 | M6: 138675.7 | N6: 252709.36 | O6: COM | P6: 98902 | Q6: 182 | R6: 35377.08 | S6: 18130.43 | T6: 147129.49 | U6: 200637 | V6: COM | W6: 98902 | X6: 1 | Y6: 201.67 | Z6: 184.35 | AA6: 790.64 | AB6: 1176.66 | AC6: 1 | AD6: 199.22 | AE6: 201.67 | AF6: 974.99 | AG6: 1375.88 | AH6: 1 | AI6: 141.61 | AJ6: 199.22 | AK6: 1176.66 | AL6: 1517.49 | AM6: COM | AN6: 98902 | AO6: 3 | AP6: 220.21 | AQ6: 220.32 | AR6: 1375.88 | AS6: 1816.41 | AT6: 2 | AU6: 95.4 | AV6: 149.07 | AW6: 1017.49 | AX6: 1261.96 | AY6: 3 | AZ6: 96.28 | BA6: 87.4 | BB6: 1166.56 | BC6: 1350.24 | BD6: COM | BE6: 98902 | BF6: 3 | BG6: 253.64 | BH6: 125.48 | BI6: 307.49 | BJ6: 686.61 | BK6: COM | BL6: 98902 | BM6: 2 | BN6: 114.2 | BO6: 108.06 | BP6: 432.97 | BQ6: 655.23 | BR6: COM | BS6: 98902 | BT6: 2 | BU6: 88.44 | BV6: 106.2 | BW6: 541.03 | BX6: 735.67 | CH6: =A6 -> COM | CI6: =B6 -> 98902 | CJ6: =D6*1.6%+E6*6.3%+F6*28.9% -> 39358.538 | CK6: =H6 -> COM | CL6: =I6 -> 98902 | CM6: =K6*1.6%+L6*6.3%+M6*28.9% -> 42923.607 | CN6: =O6 -> COM | CO6: =P6 -> 98902 | CP6: =R6*1.6%+S6*6.3%+T6*28.9% -> 44228.673 | DD6: 98902 | DE6: COM | DF6: 2 | DG6: 98902 | DH6: COM | DI6: 5 | DJ6: 98902 | DK6: COM | DL6: 7 | DM6: 98901RES | DN6: 137166.95 | DO6: 98901RES | DP6: 22809.38 | DQ6: 98901RES | DR6: 26742.52 | DS6: 98902RES | DT6: 2372.83 | DU6: 98901RES | DV6: 298.23 | DW6: 98902RES | DX6: 251.74
A7: COM | B7: 98903 | C7: 130 | D7: 34608.06 | E7: 11749.03 | F7: 70588.16 | G7: 116945.25 | H7: COM | I7: 98903 | J7: 111 | K7: 16723.79 | L7: 17935.02 | M7: 79059.27 | N7: 113718.08 | O7: COM | P7: 98903 | Q7: 99 | R7: 20368.42 | S7: 10085.67 | T7: 76672.52 | U7: 107126.61 | V7: COM | W7: 98908 | X7: 2 | Y7: 158.37 | Z7: 111.77 | AA7: 460.42 | AB7: 730.56 | AC7: 2 | AD7: 150.01 | AE7: 158.37 | AF7: 572.19 | AG7: 880.57 | AH7: 2 | AI7: 110.55 | AJ7: 150.01 | AK7: 730.56 | AL7: 991.12 | AM7: COM | AN7: 98903 | AO7: 1 | AP7: 11.54 | AQ7: 0 | AR7: 0 | AS7: 11.54 | BD7: COM | BE7: 98903 | BF7: 3 | BG7: 138.84 | BH7: 40.46 | BI7: 68.31 | BJ7: 247.61 | BK7: COM | BL7: 98903 | BM7: 2 | BN7: 183.01 | BO7: 28.26 | BP7: 81.82 | BQ7: 293.09 | BR7: COM | BS7: 98903 | BT7: 2 | BU7: 183.23 | BV7: 104.83 | BW7: 106.26 | BX7: 394.32 | CH7: =A7 -> COM | CI7: =B7 -> 98903 | CJ7: =D7*1.6%+E7*6.3%+F7*28.9% -> 21693.896 | CK7: =H7 -> COM | CL7: =I7 -> 98903 | CM7: =K7*1.6%+L7*6.3%+M7*28.9% -> 24245.616 | CN7: =O7 -> COM | CO7: =P7 -> 98903 | CP7: =R7*1.6%+S7*6.3%+T7*28.9% -> 23119.65 | DD7: 98930 | DE7: COM | DF7: 1 | DG7: 98903 | DH7: COM | DI7: 1 | DJ7: 98908 | DK7: COM | DL7: 4 | DM7: 98902COM | DN7: 36862.79 | DO7: 98902COM | DP7: 3875.33 | DQ7: 98902COM | DR7: 5619.56 | DS7: 98908RES | DT7: 1146.97 | DU7: 98902COM | DV7: 25.41 | DW7: 98903RES | DX7: 324.35
A8: COM | B8: 98904 | D8: 0 | E8: 0 | F8: 0 | G8: 0 | H8: COM | I8: 98904 | K8: 0 | L8: 0 | M8: 0 | N8: 0 | O8: COM | P8: 98904 | R8: 0 | S8: 0 | T8: 0 | U8: 0 | V8: COM | W8: 98939 | AH8: 1 | AI8: 18.28 | AJ8: 0 | AK8: 0 | AL8: 18.28 | AM8: COM | AN8: 98908 | AO8: 2 | AP8: 110.6 | AQ8: 110.55 | AR8: 880.57 | AS8: 1101.72 | AT8: 2 | AU8: 83.91 | AV8: 110.6 | AW8: 888.12 | AX8: 1082.63 | AY8: 2 | AZ8: 63.03 | BA8: 83.91 | BB8: 996.87 | BC8: 1143.81 | BD8: COM | BE8: 98908 | BF8: 4 | BG8: 524.79 | BH8: 486.04 | BI8: 2728.77 | BJ8: 3739.6 | BK8: COM | BL8: 98908 | BM8: 4 | BN8: 508.28 | BO8: 524.79 | BP8: 2922.87 | BQ8: 3955.94 | BR8: COM | BS8: 98908 | BT8: 3 | BU8: 488.96 | BV8: 470.95 | BW8: 3373.23 | BX8: 4333.14 | CH8: =A8 -> COM | CI8: =B8 -> 98904 | CJ8: =D8*1.6%+E8*6.3%+F8*28.9% -> 0 | CK8: =H8 -> COM | CL8: =I8 -> 98904 | CM8: =K8*1.6%+L8*6.3%+M8*28.9% -> 0 | CN8: =O8 -> COM | CO8: =P8 -> 98904 | CP8: =R8*1.6%+S8*6.3%+T8*28.9% -> 0 | DD8: 98932 | DE8: COM | DF8: 1 | DG8: 98930 | DH8: COM | DI8: 2 | DJ8: 98932 | DK8: COM | DL8: 2 | DM8: 98902RES | DN8: 43475.35 | DO8: 98902RES | DP8: 77490.83 | DQ8: 98902RES | DR8: 56967.37 | DS8: 98921RES | DT8: 244.25 | DU8: 98902RES | DV8: 1566.43 | DW8: 98908COM | DX8: 634.85
A9: COM | B9: 98907 | D9: 0 | E9: 0 | F9: 0 | G9: 0 | H9: COM | I9: 98907 | K9: 0 | L9: 0 | M9: 0 | N9: 0 | O9: COM | P9: 98907 | R9: 0 | S9: 0 | T9: 0 | U9: 0 | V9: COM | W9: 98944 | X9: 1 | Y9: 693.32 | Z9: 625.8 | AA9: 8208.19 | AB9: 9527.31 | AC9: 1 | AD9: 651.21 | AE9: 693.32 | AF9: 8491.43 | AG9: 9835.96 | AH9: 1 | AI9: 746.89 | AJ9: 651.21 | AK9: 9184.75 | AL9: 10582.85 | AM9: COM | AN9: 98939 | AO9: 2 | AP9: 275.97 | AQ9: 333.69 | AR9: 0 | AS9: 609.66 | AT9: 2 | AU9: 275.97 | AV9: 0 | AW9: 0 | AX9: 275.97 | AY9: 2 | AZ9: 275.97 | BA9: 0 | BB9: 0 | BC9: 275.97 | BD9: COM | BE9: 98932 | BF9: 1 | BG9: 14.03 | BH9: 15.24 | BI9: 129.47 | BJ9: 158.74 | BK9: COM | BL9: 98932 | BM9: 1 | BN9: 13.91 | BO9: 14.03 | BP9: 49.92 | BQ9: 77.86 | BR9: COM | BS9: 98932 | BT9: 1 | BU9: 14.05 | BV9: 0 | BW9: 0 | BX9: 14.05 | CH9: =A9 -> COM | CI9: =B9 -> 98907 | CJ9: =D9*1.6%+E9*6.3%+F9*28.9% -> 0 | CK9: =H9 -> COM | CL9: =I9 -> 98907 | CM9: =K9*1.6%+L9*6.3%+M9*28.9% -> 0 | CN9: =O9 -> COM | CO9: =P9 -> 98907 | CP9: =R9*1.6%+S9*6.3%+T9*28.9% -> 0 | DD9: 98936 | DE9: COM | DF9: 2 | DG9: 98944 | DH9: COM | DI9: 1 | DJ9: 99362 | DK9: COM | DL9: 1 | DM9: 98903RES | DN9: 29938.64 | DO9: 98903COM | DP9: 312.62 | DQ9: 98903RES | DR9: 16394.39 | DS9: 98930RES | DT9: 376.46 | DU9: 98903RES | DV9: 280.29 | DW9: 98908RES | DX9: 186.02
A10: COM | B10: 98908 | C10: 119 | D10: 39004.73 | E10: 10177.83 | F10: 33853.78 | G10: 83036.34 | H10: COM | I10: 98908 | J10: 117 | K10: 27323.46 | L10: 9326.87 | M10: 35083.31 | N10: 71733.64 | O10: COM | P10: 98908 | Q10: 114 | R10: 22063.93 | S10: 7836.95 | T10: 33871.31 | U10: 63772.19 | V10: COM | W10: 98947 | X10: 1 | Y10: 133.37 | Z10: 100.97 | AA10: 523.95 | AB10: 758.29 | AH10: 1 | AI10: 28.62 | AJ10: 0 | AK10: 0 | AL10: 28.62 | AM10: COM | AN10: 98944 | AO10: 1 | AP10: 661.59 | AQ10: 746.89 | AR10: 9835.96 | AS10: 11244.44 | AT10: 1 | AU10: 524.18 | AV10: 661.59 | AW10: 9982.85 | AX10: 11168.62 | AY10: 1 | AZ10: 426.92 | BA10: 524.18 | BB10: 10244.44 | BC10: 11195.54 | BD10: COM | BE10: 98933 | BG10: 0 | BH10: 0 | BI10: 0 | BJ10: 0 | BK10: COM | BL10: 98933 | BN10: 0 | BO10: 0 | BP10: 0 | BQ10: 0 | BR10: COM | BS10: 98933 | BU10: 0 | BV10: 0 | BW10: 0 | BX10: 0 | CH10: =A10 -> COM | CI10: =B10 -> 98908 | CJ10: =D10*1.6%+E10*6.3%+F10*28.9% -> 11049.021 | CK10: =H10 -> COM | CL10: =I10 -> 98908 | CM10: =K10*1.6%+L10*6.3%+M10*28.9% -> 11163.845 | CN10: =O10 -> COM | CO10: =P10 -> 98908 | CP10: =R10*1.6%+S10*6.3%+T10*28.9% -> 10635.559 | DD10: 98951 | DE10: COM | DF10: 1 | DG10: 98948 | DH10: COM | DI10: 3 | DJ10: 98901 | DK10: RES | DL10: 43 | DM10: 98908RES | DN10: 13886.69 | DO10: 98903RES | DP10: 21393.79 | DQ10: 98908COM | DR10: 673.7 | DS10: 98938RES | DT10: 92.76 | DU10: 98908RES | DV10: 1131.82 | DW10: 98923RES | DX10: 44.32
A11: COM | B11: 98920 | D11: 0 | E11: 0 | F11: 0 | G11: 0 | H11: COM | I11: 98920 | K11: 0 | L11: 0 | M11: 0 | N11: 0 | O11: COM | P11: 98920 | R11: 0 | S11: 0 | T11: 0 | U11: 0 | V11: COM | W11: 98948 | X11: 13 | Y11: 2679.32 | Z11: 4508.48 | AA11: 8955.01 | AB11: 16142.81 | AC11: 13 | AD11: 4720.25 | AE11: 2679.3 | AF11: 12509.89 | AG11: 19909.44 | AH11: 7 | AI11: 2581.95 | AJ11: 1965.03 | AK11: 3186.9 | AL11: 7733.88 | AM11: COM | AN11: 98947 | AO11: 1 | AP11: 153.22 | AQ11: 28.62 | AR11: 0 | AS11: 181.84 | AT11: 1 | AU11: 53.68 | AV11: 153.22 | AW11: 28.62 | AX11: 235.52 | AY11: 1 | AZ11: 99.66 | BA11: 53.68 | BB11: 179.99 | BC11: 333.33 | BD11: COM | BE11: 98936 | BK11: COM | BL11: 98936 | BR11: COM | BS11: 98936 | BU11: 0 | BV11: 0 | BW11: 0 | BX11: 0 | CH11: =A11 -> COM | CI11: =B11 -> 98920 | CJ11: =D11*1.6%+E11*6.3%+F11*28.9% -> 0 | CK11: =H11 -> COM | CL11: =I11 -> 98920 | CM11: =K11*1.6%+L11*6.3%+M11*28.9% -> 0 | CN11: =O11 -> COM | CO11: =P11 -> 98920 | CP11: =R11*1.6%+S11*6.3%+T11*28.9% -> 0 | DD11: 99328 | DE11: COM | DF11: 3 | DG11: 98901 | DH11: RES | DI11: 52 | DJ11: 98902 | DK11: RES | DL11: 78 | DM11: 98921RES | DN11: 246 | DO11: 98908RES | DP11: 13682.06 | DQ11: 98908RES | DR11: 19280.31 | DS11: 98942RES | DT11: 2192.36 | DU11: 98923RES | DV11: 185.65 | DW11: 98936RES | DX11: 82.68
A12: COM | B12: 98921 | C12: 2 | D12: 124.99 | E12: 144.72 | F12: 148.98 | G12: 418.69 | H12: COM | I12: 98921 | J12: 4 | K12: 278.48 | L12: 121.77 | M12: 147.34 | N12: 547.59 | O12: COM | P12: 98921 | Q12: 3 | R12: 124.59 | S12: 125.29 | T12: 269.11 | U12: 518.99 | V12: COM | W12: 98951 | X12: 4 | Y12: 378.67 | Z12: 249.13 | AA12: 728.58 | AB12: 1356.38 | AC12: 4 | AD12: 357.8 | AE12: 209.84 | AF12: 977.71 | AG12: 1545.35 | AH12: 3 | AI12: 297.18 | AJ12: 174.7 | AK12: 1176.78 | AL12: 1648.66 | AM12: COM | AN12: 98948 | AO12: 6 | AP12: 6418.74 | AQ12: 11.34 | AR12: 650.48 | AS12: 7080.56 | AT12: 6 | AU12: 4152.47 | AV12: 1531.26 | AW12: 88.2 | AX12: 5771.93 | AY12: 4 | AZ12: 2645.64 | BA12: 79.99 | BB12: 22.92 | BC12: 2748.55 | BD12: COM | BE12: 98938 | BG12: 0 | BH12: 0 | BI12: 0 | BJ12: 0 | BK12: COM | BL12: 98938 | BN12: 0 | BO12: 0 | BP12: 0 | BQ12: 0 | BR12: COM | BS12: 98938 | BT12: 1 | BU12: 0.02 | BV12: 0 | BW12: 0 | BX12: 0.02 | CH12: =A12 -> COM | CI12: =B12 -> 98921 | CJ12: =D12*1.6%+E12*6.3%+F12*28.9% -> 54.17242 | CK12: =H12 -> COM | CL12: =I12 -> 98921 | CM12: =K12*1.6%+L12*6.3%+M12*28.9% -> 54.70845 | CN12: =O12 -> COM | CO12: =P12 -> 98921 | CP12: =R12*1.6%+S12*6.3%+T12*28.9% -> 87.6595 | DD12: 99347 | DE12: COM | DF12: 1 | DG12: 98902 | DH12: RES | DI12: 83 | DJ12: 98903 | DK12: RES | DL12: 20 | DM12: 98930COM | DN12: 884.12 | DO12: 98921RES | DP12: 1865.61 | DQ12: 98921RES | DR12: 1301.81 | DS12: 98944RES | DT12: 407.03 | DU12: 98930RES | DV12: 59.2 | DW12: 98942RES | DX12: 208.89
A13: COM | B13: 98923 | C13: 8 | D13: 12752.59 | E13: 88.99 | F13: 592.68 | G13: 13434.26 | H13: COM | I13: 98923 | J13: 10 | K13: 12113.39 | L13: 11846.26 | M13: 621.6 | N13: 24581.25 | O13: COM | P13: 98923 | Q13: 8 | R13: 12831.93 | S13: 5103.86 | T13: 6531.14 | U13: 24466.93 | V13: COM | W13: 98952 | X13: 1 | Y13: 191.52 | Z13: 111.91 | AA13: 298.69 | AB13: 602.12 | AC13: 1 | AD13: 139.04 | AE13: 191.52 | AF13: 110.6 | AG13: 441.16 | AH13: 1 | AI13: 86.41 | AJ13: 139.04 | AK13: 302.12 | AL13: 527.57 | AM13: COM | AN13: 98951 | AO13: 3 | AP13: 374.25 | AQ13: 107.31 | AR13: 1098.31 | AS13: 1579.87 | AT13: 3 | AU13: 385.42 | AV13: 374.25 | AW13: 1205.62 | AX13: 1965.29 | AY13: 2 | AZ13: 193.02 | BA13: 273.23 | BB13: 252.38 | BC13: 718.63 | BD13: COM | BE13: 98939 | BF13: 1 | BG13: 255.72 | BH13: 20.25 | BI13: 0 | BJ13: 275.97 | BK13: COM | BL13: 98939 | BM13: 1 | BN13: 275.97 | BO13: 0 | BP13: 0 | BQ13: 275.97 | BR13: COM | BS13: 98939 | BT13: 1 | BU13: 284.66 | BV13: 275.97 | BW13: 0 | BX13: 560.63 | CH13: =A13 -> COM | CI13: =B13 -> 98923 | CJ13: =D13*1.6%+E13*6.3%+F13*28.9% -> 380.93233 | CK13: =H13 -> COM | CL13: =I13 -> 98923 | CM13: =K13*1.6%+L13*6.3%+M13*28.9% -> 1119.771 | CN13: =O13 -> COM | CO13: =P13 -> 98923 | CP13: =R13*1.6%+S13*6.3%+T13*28.9% -> 2414.3535 | DD13: 98901 | DE13: RES | DF13: 42 | DG13: 98903 | DH13: RES | DI13: 17 | DJ13: 98908 | DK13: RES | DL13: 33 | DM13: 98930RES | DN13: 5556.71 | DO13: 98923RES | DP13: 322.29 | DQ13: 98923RES | DR13: 4010.65 | DS13: 98947RES | DT13: 288 | DU13: 98932RES | DV13: 743.66 | DW13: 98944RES | DX13: 96.21
A14: COM | B14: 98930 | C14: 35 | D14: 5841.59 | E14: 5030.47 | F14: 16375.5 | G14: 27247.56 | H14: COM | I14: 98930 | J14: 26 | K14: 3401.06 | L14: 4372.5 | M14: 20459.97 | N14: 28233.53 | O14: COM | P14: 98930 | Q14: 33 | R14: 4337.27 | S14: 3182.68 | T14: 22246.7 | U14: 29766.65 | V14: COM | W14: 99347 | X14: 2 | Y14: 522.01 | Z14: 305.81 | AA14: 46.45 | AB14: 874.27 | AC14: 2 | AD14: 338.57 | AE14: 522.01 | AF14: 352.26 | AG14: 1212.84 | AH14: 1 | AI14: 126.21 | AJ14: 188.49 | AK14: 716.19 | AL14: 1030.89 | AM14: COM | AN14: 98952 | AO14: 1 | AP14: 86.45 | AQ14: 86.41 | AR14: 441.16 | AS14: 614.02 | AT14: 1 | AU14: 74.27 | AV14: 86.45 | AW14: 527.57 | AX14: 688.29 | AY14: 1 | AZ14: 54.78 | BA14: 74.27 | BB14: 614.02 | BC14: 743.07 | BD14: COM | BE14: 98942 | BG14: 0 | BH14: 0 | BI14: 0 | BJ14: 0 | BK14: COM | BL14: 98942 | BN14: 0 | BO14: 0 | BP14: 0 | BQ14: 0 | BR14: COM | BS14: 98942 | BU14: 0 | BV14: 0 | BW14: 0 | BX14: 0 | CH14: =A14 -> COM | CI14: =B14 -> 98930 | CJ14: =D14*1.6%+E14*6.3%+F14*28.9% -> 5142.9045 | CK14: =H14 -> COM | CL14: =I14 -> 98930 | CM14: =K14*1.6%+L14*6.3%+M14*28.9% -> 6242.8158 | CN14: =O14 -> COM | CO14: =P14 -> 98930 | CP14: =R14*1.6%+S14*6.3%+T14*28.9% -> 6699.2015 | DD14: 98902 | DE14: RES | DF14: 70 | DG14: 98908 | DH14: RES | DI14: 24 | DJ14: 98921 | DK14: RES | DL14: 1 | DM14: 98932COM | DN14: 6460.72 | DO14: 98930COM | DP14: 2241.76 | DQ14: 98930RES | DR14: 13479.57 | DS14: 98948RES | DT14: 185.77 | DU14: 98935RES | DV14: 875.23 | DW14: 98948RES | DX14: 26.82
