Workbook

Sheet 1. General 2023_Q3
A1: Count of aggreements by ZIP and CLASS.
A2: WA_TERM_COVID_COUNTS
A3: General 2023
A4: 45108 | D4: 45139 | G4: 45170 | K4: Retail Sales (kWh) | L4: July | M4: August | N4: September | O4: 45108 | P4: 45139 | Q4: 45170 | R4: July | S4: August | T4: September | U4: October | V4: November | W4: December | X4: Totals Q3
A5: Zip | B5: Class | C5: Count | D5: Zip | E5: Class | F5: Count | G5: Zip | H5: Class | I5: Count | K5: Residential | L5: 149454803 | M5: 144341255 | N5: 106642496 | O5: 127826646 | P5: 133081832 | Q5: 111734624 | X5: =SUM(O5:Q5) -> 372643102
A6: 98901 | B6: COM | C6: 2140 | D6: 98901 | E6: COM | F6: 2151 | G6: 98901 | H6: COM | I6: 2156 | K6: Commercial | L6: 140404042 | M6: 148198213 | N6: 131511808 | O6: 128676067 | P6: 138229616 | Q6: 135834307 | X6: =SUM(O6:Q6) -> 402739990
A7: 98902 | B7: COM | C7: 2571 | D7: 98902 | E7: COM | F7: 2574 | G7: 98902 | H7: COM | I7: 2570 | K7: Industrial | L7: 72533895 | M7: 71622459 | N7: 72818621 | O7: 33667523 | P7: 23039927 | Q7: 30185750 | X7: =SUM(O7:Q7) -> 86893200
A8: 98903 | B8: COM | C8: 1649 | D8: 98903 | E8: COM | F8: 1646 | G8: 98903 | H8: COM | I8: 1645 | K8: Irrigation | L8: 36860793 | M8: 39164393 | N8: 25760901 | O8: 32157540 | P8: 35430267 | Q8: 29459076 | X8: =SUM(O8:Q8) -> 97046883
A9: 98904 | B9: COM | C9: 2 | D9: 98904 | E9: COM | F9: 2 | G9: 98904 | H9: COM | I9: 2 | K9: Totals | L9: =SUM(L5:L8) -> 399253533 | M9: =SUM(M5:M8) -> 403326320 | N9: =SUM(N5:N8) -> 336733826 | O9: =SUM(O5:O8) -> 322327776 | P9: =SUM(P5:P8) -> 329781642 | Q9: =SUM(Q5:Q8) -> 307213757 | R9: =SUM(R5:R8) -> 0 | S9: =SUM(S5:S8) -> 0 | ... X9: =SUM(X5:X8) -> 959323175
A10: 98907 | B10: COM | C10: 2 | D10: 98907 | E10: COM | F10: 2 | G10: 98907 | H10: COM | I10: 2
A11: 98908 | B11: COM | C11: 1571 | D11: 98908 | E11: COM | F11: 1581 | G11: 98908 | H11: COM | I11: 1583
A12: 98920 | B12: COM | C12: 3 | D12: 98920 | E12: COM | F12: 3 | G12: 98920 | H12: COM | I12: 3
A13: 98921 | B13: COM | C13: 26 | D13: 98921 | E13: COM | F13: 26 | G13: 98921 | H13: COM | I13: 26
A14: 98923 | B14: COM | C14: 107 | D14: 98923 | E14: COM | F14: 107 | G14: 98923 | H14: COM | I14: 108
A15: 98930 | B15: COM | C15: 637 | D15: 98930 | E15: COM | F15: 640 | G15: 98930 | H15: COM | I15: 649
A16: 98932 | B16: COM | C16: 231 | D16: 98932 | E16: COM | F16: 231 | G16: 98932 | H16: COM | I16: 230
A17: 98933 | B17: COM | C17: 73 | D17: 98933 | E17: COM | F17: 71 | G17: 98933 | H17: COM | I17: 71
A18: 98935 | B18: COM | C18: 137 | D18: 98935 | E18: COM | F18: 137 | G18: 98935 | H18: COM | I18: 137
A19: 98936 | B19: COM | C19: 346 | D19: 98936 | E19: COM | F19: 345 | G19: 98936 | H19: COM | I19: 344
A20: 98937 | B20: COM | C20: 398 | D20: 98937 | E20: COM | F20: 399 | G20: 98937 | H20: COM | I20: 395
A21: 98938 | B21: COM | C21: 153 | D21: 98938 | E21: COM | F21: 154 | G21: 98938 | H21: COM | I21: 153
... A40: 99363 | B40: COM | C40: 73 | D40: 99363 | E40: COM | F40: 73 | G40: 99363 | H40: COM | I40: 73
B41: COM | C41: 4 | E41: COM | F41: 4 | H41: COM | I41: 4
A42: 98901 | B42: IND | C42: 48 | D42: 98901 | E42: IND | F42: 48 | G42: 98901 | H42: IND | I42: 48
A43: 98902 | B43: IND | C43: 85 | D43: 98902 | E43: IND | F43: 85 | G43: 98902 | H43: IND | I43: 85
A44: 98903 | B44: IND | C44: 64 | D44: 98903 | E44: IND | F44: 64 | G44: 98903 | H44: IND | I44: 64
A45: 98908 | B45: IND | C45: 17 | D45: 98908 | E45: IND | F45: 17 | G45: 98908 | H45: IND | I45: 17
A46: 98921 | B46: IND | C46: 1 | D46: 98921 | E46: IND | F46: 1 | G46: 98921 | H46: IND | I46: 1
A47: 98923 | B47: IND | C47: 4 | D47: 98923 | E47: IND | F47: 4 | G47: 98923 | H47: IND | I47: 4
A48: 98930 | B48: IND | C48: 26 | D48: 98930 | E48: IND | F48: 26 | G48: 98930 | H48: IND | I48: 26
A49: 98932 | B49: IND | C49: 12 | D49: 98932 | E49: IND | F49: 12 | G49: 98932 | H49: IND | I49: 12
A50: 98933 | B50: IND | C50: 1 | D50: 98933 | E50: IND | F50: 1 | G50: 98933 | H50: IND | I50: 1
A51: 98935 | B51: IND | C51: 3 | D51: 98935 | E51: IND | F51: 3 | G51: 98935 | H51: IND | I51: 3
A52: 98936 | B52: IND | C52: 18 | D52: 98936 | E52: IND | F52: 18 | G52: 98936 | H52: IND | I52: 18
A53: 98937 | B53: IND | C53: 11 | D53: 98937 | E53: IND | F53: 11 | G53: 98937 | H53: IND | I53: 11
... A143: 99363 | B143: RES | C143: 72 | D143: 99363 | E143: RES | F143: 74 | G143: 99363 | H143: RES | I143: 74

Sheet 2. Disconnections 2023_Q3
A1: General 2023 | D1: Item a) Number of Disconnections by Customer Class per Month | H1: Item b) Avg. Duration of Disconnection by Customer Class (in Hours for recon 10 days or less) | R1: Item c) Number of Customers by Customer Class Receiving Disconnection Notices | W1: Item d) Number of Customers by Customer Class Who Absent the Disconnection Moratorium Would Have Been Disconnected
A2: Zip Code | B2: Customer Class | D2: 45108 | E2: 45139 | F2: 45170 | H2: ZIP | I2: REV | J2: 45108 | K2: ZIP | L2: REV | M2: 45139 | N2: ZIP | O2: REV | P2: 45170 | R2: Category | S2: 45108 | T2: 45139 | U2: 45170 | W2: Category | X2: 45108 | Y2: 45139 | Z2: 45170
A3: 98901 | B3: COM | E3: 2 | F3: 3 | H3: 99324 | I3: RES | J3: 0.60019841 | K3: 98901 | L3: RES | M3: 0.70300926 | N3: 98901 | O3: RES | P3: 2.85625 | R3: FFN | S3: 6363 | T3: 6695 | U3: 6599
A4: 98901 | B4: RES | E4: 20 | F4: 26 | H4: 99328 | I4: RES | J4: 1.0013889 | K4: 98902 | L4: COM | M4: 4.9416667 | N4: 98902 | O4: RES | P4: 0.031944444 | R4: FNL | S4: 9767 | T4: 10303 | U4: 10076
A5: 98902 | B5: COM | E5: 1 | H5: 99362 | I5: RES | J5: 0.57282197 | K5: 98936 | L5: RES | M5: 1.0166667 | N5: 98903 | O5: COM | P5: 1.0409722 | R5: PDN | S5: 11304 | T5: 13006 | U5: 12145
A6: 98902 | B6: RES | D6: 2 | E6: 3 | F6: 6 | K6: 98942 | L6: COM | M6: 0.85972222 | N6: 98932 | O6: RES | P6: 0.1375
A7: 98903 | B7: COM | D7: 1 | F7: 1 | K7: 98951 | L7: RES | M7: 1.2358796 | N7: 98933 | O7: RES | P7: 0.98541667
A8: 98903 | B8: RES | D8: 1 | E8: 1 | F8: 1 | K8: 99324 | L8: RES | M8: 0.80185185 | N8: 98937 | O8: COM | P8: 0.26527778
A9: 98908 | B9: RES | D9: 1 | F9: 13 | K9: 99347 | L9: RES | M9: 1.9104167 | N9: 98937 | O9: RES | P9: 0.67847222
A10: 98932 | B10: RES | F10: 1 | K10: 99362 | L10: RES | M10: 0.84229167 | N10: 98938 | O10: IRG | P10: 0.98194444
A11: 98933 | B11: RES | F11: 1 | N11: 98938 | O11: RES | P11: 0.10138889
A12: 98936 | B12: RES | E12: 4 | N12: 98942 | O12: RES | P12: 1.0229167
A13: 98937 | B13: COM | F13: 2 | N13: 99323 | O13: RES | P13: 0.066319444
A14: 98937 | B14: RES | F14: 5 | N14: 99324 | O14: RES | P14: 0.14305556
A15: 98938 | B15: IRG | F15: 1 | N15: 99328 | O15: RES | P15: 0.05
A16: 98938 | B16: RES | F16: 2 | N16: 99361 | O16: RES | P16: 0.31388889
A17: 98942 | B17: COM | E17: 1 | N17: 99362 | O17: RES | P17: 1.1102705
A18: 98942 | B18: IRG | E18: 4
A19: 98942 | B19: RES | E19: 5 | F19: 1
A20: 98944 | B20: RES | F20: 10
A21: 98948 | B21: RES | E21: 1
A22: 98951 | B22: COM | E22: 1
A23: 98951 | B23: IRG | E23: 1
A24: 98951 | B24: RES | E24: 14 | F24: 1
A25: 98952 | B25: RES | F25: 1
A26: 98953 | B26: RES | E26: 1 | F26: 1
A27: 99301 | B27: RES | F27: 1
A28: 99323 | B28: RES | D28: 2 | E28: 1 | F28: 2
A29: 99324 | B29: RES | D29: 15 | E29: 5 | F29: 3
A30: 99328 | B30: RES | D30: 5 | F30: 2
A31: 99329 | B31: RES | D31: 1
A32: 99347 | B32: RES | E32: 12
A33: 99348 | B33: RES | D33: 2
A34: 99360 | B34: RES | D34: 2 | F34: 1
A35: 99361 | B35: RES | D35: 6 | F35: 2
A36: 99362 | B36: COM | F36: 1
A37: 99362 | B37: RES | D37: 60 | E37: 42 | F37: 34
A38: 99363 | B38: RES | F38: 1
A39: TOTAL | D39: =SUMIF($B$3:$B$38,$B$4,D3:D38) -> 97 | E39: =SUMIF($B$3:$B$38,$B$4,E3:E38) -> 109 | F39: =SUMIF($B$3:$B$38,$B$4,F3:F38) -> 115

Sheet 3. Fees 2023_Q3
A1: General 2023 | D1: Item a) Number of Customers by Customer Class Assessed Late Payment Fees | H1: Item a) Aggregate amount of Charged Late Payment Fees | L1: Item a) Number of Customers by Customer Class Assessed Disconnection Fees | P1: Item a) Aggregate amount of Charged Disconnection Fees | T1: Item a) Number of Customers by Customer Class Assessed Reconnection Fees | X1: Item a) Aggregate amount of Charged Reconnection Fees
A2: Zip Code | B2: Customer Class | D2: 45017 | E2: 45047 | F2: 45078 | H2: 45017 | I2: 45047 | J2: 45078 | L2: 45017 | M2: 45047 | N2: 45078 | P2: 45017 | Q2: 45047 | R2: 45078 | T2: 45017 | U2: 45047 | V2: 45078 | X2: 45017 | Y2: 45047 | Z2: 45078
A3: None

Sheet 4. Payment Arrangements 2023_Q3
A1: General 2023 | D1: Item a) Number of Customers by Customer Class Taking Service at the Beginning of Each Month with Existing Long Term Payment Agreements | H1: Item b) Number of Customers By Customer Class Completing Long-term Payment Agreements | L1: Item c) Number of Customers by Customer Class Enrolling in New Long-term Payment Agreements | P1: Item d) Number of Customers By Customer Class Renegotiating Long-term Payment Agreements
A2: Zip Code | B2: Customer Class | D2: 45108 | E2: 45139 | F2: 45170 | H2: 45108 | I2: 45139 | J2: 45170 | L2: 45108 | M2: 45139 | N2: 45170 | P2: 45108 | Q2: 45139 | R2: 45170
A3: NA | B3: COM | D3: 164 | E3: 157 | F3: 150 | H3: 17 | I3: 20 | J3: 14 | L3: 40 | M3: 46 | N3: 36 | P3: 1 | Q3: 0 | R3: 0
A4: NA | B4: RES | D4: 5473 | E4: 5298 | F4: 5044 | H4: 175 | I4: 256 | J4: 147 | L4: 866 | M4: 1027 | N4: 778 | P4: 144 | Q4: 147 | R4: 67

Sheet 5. Medical Certificates 2023_Q3
A1: General 2023 | D1: Item a) Number of Customers Taking Service at the Beginning of Each Month Under Existing Medical Payment Arrangements | H1: Item b) Number of Customers Completing Medical Payment Arrangements Each Month | L1: Item c) Number of Customers Enrolling in New Medical Payment Arrangements Each Month | P1: Item d) Number of Customers Renegotiating Medical Payment Arrangements Each Month
A2: Zip Code | B2: Customer Class | D2: 45108 | E2: 45139 | F2: 45170 | H2: 45108 | I2: 45139 | J2: 45170 | L2: 45108 | M2: 45139 | N2: 45170 | P2: 44197 | Q2: 44228 | R2: 44256 | S2: 44287 | T2: 44317 | U2: 44348 | V2: 44378 | W2: 44409 | X2: 44440 | Y2: 45108 | Z2: 45139 | AA2: 45170
A3: NA | B3: RES | D3: 14 | E3: 13 | F3: 17 | H3: 0 | I3: 0 | J3: 0 | L3: 2 | M3: 9 | N3: 5 | P3: 0 | Q3: 0 | R3: 0 | S3: 0 | T3: 0 | U3: 0 | V3: 0 | W3: 0 | X3: 0 | Y3: 0 | Z3: 0 | AA3: 0

Sheet 6. Deposits 2023_Q3
A1: General 2023 | D1: Item a) Number of Customers by Customer Class with Required Deposits at the Beginning of Each Month | N1: Item b) Number of Customers by Customer Class Required to Submit New or Increased Deposits Each Month | AH1: Item c) Number of Customers by Customer Class Whose Deposits Were Reduced In Part or Foregone Each Month | AR1: Item d) Number of Customers by Customer Class whose Deposits were Returned in Full Each Month
D2: 45108 | G2: 45139 | J2: 45170 | N2: Zip Code | O2: Customer Class | P2: 44197 | Q2: 44228 | R2: 44256 | S2: Zip Code | T2: Customer Class | U2: 44287 | V2: 44317 | W2: 44348 | X2: 45108 | AA2: 45139 | AD2: 45170 | AH2: 44197 | AI2: 44228 | AJ2: 44256 | AK2: 44287 | AL2: 44317 | AM2: 44348 | AN2: 45108 | AO2: 45139 | AP2: 45170 | AR2: 45108 | AU2: 45139 | AX2: 45170
D3: ZIP | E3: CLASS | F3: Concat Agreement Number | G3: ZIP | H3: CLASS | I3: Concat Agreement Number | J3: ZIP | K3: CLASS | L3: Concat Agreement Number | N3: 98901 | O3: COM | P3: 4 | Q3: 1 | R3: 2 | S3: 98901 | T3: COM | U3: 1 | V3: 6 | X3: ZIP | Y3: CLASS | Z3: Concat Agreement Number | AA3: ZIP | AB3: CLASS | AC3: Concat Agreement Number | AD3: ZIP | AE3: CLASS | AF3: Concat Agreement Number | AR3: ZIP | AS3: CLASS | AT3: Concat Agreement Number | AU3: ZIP | AV3: CLASS | AW3: Concat Agreement Number | AX3: ZIP | AY3: CLASS | AZ3: Concat Agreement Number
D4: 98901 | E4: COM | F4: 8 | G4: 98901 | H4: COM | I4: 71 | J4: 98901 | K4: COM | L4: 64 | N4: 98901 | O4: RES | P4: 71 | Q4: 53 | R4: 58 | S4: 98901 | T4: RES | U4: 19 | V4: 17 | W4: 19 | X4: 98901 | Y4: COM | Z4: 5 | AA4: 98901 | AB4: COM | AC4: 1 | AD4: 98901 | AE4: COM | AF4: 4 | AR4: 98901 | AS4: COM | AT4: 2 | AU4: 98901 | AV4: COM | AW4: 8 | AX4: ZIP | AY4: CLASS | AZ4: Concat Agreement Number
D5: 98901 | E5: RES | F5: 44 | G5: 98901 | H5: RES | I5: 11 | J5: 98901 | K5: RES | L5: 4 | N5: 98902 | O5: COM | Q5: 6 | R5: 3 | S5: 98902 | T5: COM | U5: 4 | V5: 12 | W5: 5 | X5: 98901 | Y5: RES | Z5: 19 | AA5: 98902 | AB5: COM | AC5: 10 | AD5: 98902 | AE5: COM | AF5: 4 | AR5: 98901 | AS5: RES | AT5: 56 | AU5: 98902 | AV5: COM | AW5: 6 | AX5: 98901 | AY5: COM | AZ5: 3
D6: 98902 | E6: COM | F6: 8 | G6: 98902 | H6: COM | I6: 71 | J6: 98902 | K6: COM | L6: 73 | N6: 98902 | O6: RES | P6: 103 | Q6: 75 | R6: 32 | S6: 98902 | T6: RES | U6: 48 | V6: 22 | W6: 19 | X6: 98902 | Y6: COM | Z6: 4 | AA6: 98903 | AB6: COM | AC6: 2 | AD6: 98903 | AE6: COM | AF6: 8 | AR6: 98902 | AS6: COM | AT6: 5 | AU6: 98902 | AV6: RES | AW6: 13 | AX6: 98902 | AY6: COM | AZ6: 3
D7: 98902 | E7: RES | F7: 48 | G7: 98902 | H7: RES | I7: 15 | J7: 98902 | K7: RES | L7: 2 | N7: 98903 | O7: COM | P7: 6 | R7: 1 | S7: 98903 | T7: COM | U7: 2 | V7: 3 | W7: 3 | X7: 98902 | Y7: RES | Z7: 18 | AA7: 98908 | AB7: COM | AC7: 2 | AD7: 98908 | AE7: COM | AF7: 3 | AR7: 98902 | AS7: RES | AT7: 66 | AU7: 98903 | AV7: COM | AW7: 4 | AX7: 98903 | AY7: COM | AZ7: 4
D8: 98903 | E8: COM | F8: 3 | G8: 98903 | H8: COM | I8: 34 | J8: 98903 | K8: COM | L8: 32 | N8: 98903 | O8: RES | P8: 17 | Q8: 16 | R8: 22 | S8: 98903 | T8: RES | U8: 5 | V8: 1 | W8: 6 | X8: 98903 | Y8: COM | Z8: 1 | AA8: 98930 | AB8: COM | AC8: 1 | AD8: 98937 | AE8: COM | AF8: 1 | AR8: 98903 | AS8: RES | AT8: 20 | AU8: 98903 | AV8: RES | AW8: 5 | AX8: 98908 | AY8: RES | AZ8: 1
D9: 98903 | E9: RES | F9: 24 | G9: 98903 | H9: RES | I9: 9 | J9: 98903 | K9: RES | L9: 4 | N9: 98908 | O9: COM | P9: 4 | Q9: 1 | R9: 2 | S9: 98908 | T9: COM | V9: 4 | W9: 2 | X9: 98903 | Y9: RES | Z9: 4 | AA9: 98937 | AB9: COM | AC9: 1 | AD9: 98944 | AE9: COM | AF9: 11 | AR9: 98908 | AS9: COM | AT9: 2 | AU9: 98908 | AV9: COM | AW9: 2 | AX9: 98930 | AY9: COM | AZ9: 1
D10: 98908 | E10: COM | F10: 6 | G10: 98908 | H10: COM | I10: 30 | J10: 98908 | K10: COM | L10: 30 | N10: 98908 | O10: RES | P10: 37 | Q10: 59 | R10: 47 | S10: 98908 | T10: RES | U10: 31 | V10: 18 | W10: 14 | X10: 98908 | Y10: COM | Z10: 3 | AA10: 98944 | AB10: COM | AC10: 1 | AD10: 98948 | AE10: COM | AF10: 1 | AR10: 98908 | AS10: RES | AT10: 60 | AU10: 98908 | AV10: RES | AW10: 14 | AX10: 98936 | AY10: COM | AZ10: 1
D11: 98908 | E11: RES | F11: 50 | G11: 98908 | H11: RES | I11: 29 | J11: 98908 | K11: RES | L11: 15 | N11: 98921 | O11: RES | P11: 2 | Q11: 1 | S11: 98921 | T11: RES | U11: 2 | X11: 98908 | Y11: RES | Z11: 10 | AA11: 98948 | AB11: COM | AC11: 1 | AD11: 98951 | AE11: COM | AF11: 1 | AR11: 98923 | AS11: RES | AT11: 1 | AU11: 98921 | AV11: RES | AW11: 1 | AX11: 98937 | AY11: COM | AZ11: 2
D12: 98921 | E12: RES | F12: 2 | G12: 98921 | H12: RES | I12: 2 | J12: 98921 | K12: RES | L12: 1 | N12: 98923 | O12: RES | P12: 3 | Q12: 1 | S12: 98923 | T12: RES | U12: 1 | X12: 98932 | Y12: RES | Z12: 1 | AA12: 98951 | AB12: COM | AC12: 2 | AD12: 98953 | AE12: COM | AF12: 2 | AR12: 98930 | AS12: COM | AT12: 1 | AU12: 98923 | AV12: RES | AW12: 1 | AX12: 98938 | AY12: COM | AZ12: 1
D13: 98923 | E13: RES | F13: 1 | G13: 98923 | H13: COM | I13: 1 | J13: 98923 | K13: COM | L13: 1 | N13: 98930 | O13: COM | P13: 2 | Q13: 2 | R13: 1 | S13: 98930 | T13: COM | V13: 2 | X13: 98935 | Y13: COM | Z13: 1 | AA13: 98953 | AB13: COM | AC13: 1 | AD13: 99324 | AE13: COM | AF13: 1 | AR13: 98930 | AS13: RES | AT13: 23 | AU13: 98930 | AV13: RES | AW13: 5 | AX13: 98938 | AY13: RES | AZ13: 1
D14: 98930 | E14: COM | F14: 5 | G14: 98923 | H14: RES | I14: 1 | J14: 98930 | K14: COM | L14: 10 | N14: 98930 | O14: RES | P14: 11 | Q14: 23 | R14: 21 | S14: 98930 | T14: RES | U14: 3 | V14: 2 | W14: 1 | X14: 98937 | Y14: COM | Z14: 1 | AA14: 99328 | AB14: COM | AC14: 1 | AD14: 99328 | AE14: COM | AF14: 1 | AR14: 98932 | AS14: COM | AT14: 1 | AU14: 98932 | AV14: RES | AW14: 1 | AX14: 98944 | AY14: COM | AZ14: 3
D15: 98930 | E15: RES | F15: 25 | G15: 98930 | H15: COM | I15: 9 | J15: 98930 | K15: RES | L15: 2 | N15: 98932 | O15: RES | P15: 5 | Q15: 4 | R15: 6 | S15: 98932 | T15: RES | V15: 3 | X15: 98937 | Y15: RES | Z15: 2 | AA15: 99362 | AB15: COM | AC15: 6 | AD15: 99329 | AE15: COM | AF15: 1 | AR15: 98932 | AS15: RES | AT15: 4 | AU15: 98935 | AV15: COM | AW15: 1 | AX15: 98951 | AY15: COM | AZ15: 1
D16: 98932 | E16: COM | F16: 3 | G16: 98930 | H16: RES | I16: 7 | J16: 98932 | K16: COM | L16: 2 | N16: 98933 | O16: RES | Q16: 1 | S16: 98933 | T16: RES | X16: 98938 | Y16: COM | Z16: 2 | AD16: 99347 | AE16: COM | AF16: 1 | AR16: 98933 | AS16: RES | AT16: 2 | AU16: 98936 | AV16: RES | AW16: 2 | AX16: 98953 | AY16: COM | AZ16: 1
D17: 98932 | E17: RES | F17: 5 | G17: 98932 | H17: COM | I17: 2 | J17: 98933 | K17: COM | L17: 1 | N17: 98935 | O17: COM | Q17: 4 | S17: 98935 | T17: COM | X17: 98942 | Y17: COM | Z17: 1 | AD17: 99362 | AE17: COM | AF17: 2 | AR17: 98935 | AS17: RES | AT17: 4 | AU17: 98937 | AV17: COM | AW17: 1 | AX17: 99329 | AY17: COM | AZ17: 1
D18: 98933 | E18: COM | F18: 1 | G18: 98932 | H18: RES | I18: 1 | J18: 98933 | K18: RES | L18: 1 | N18: 98935 | O18: RES | P18: 6 | Q18: 9 | R18: 1 | S18: 98935 | T18: RES | U18: 2 | V18: 1 | X18: 98942 | Y18: RES | Z18: 3 | AR18: 98936 | AS18: COM | AT18: 3 | AU18: 98942 | AV18: COM | AW18: 5 | AX18: 99362 | AY18: COM | AZ18: 8
D19: 98933 | E19: RES | F19: 1 | G19: 98933 | H19: COM | I19: 1 | J19: 98935 | K19: COM | L19: 7 | N19: 98936 | O19: RES | P19: 2 | Q19: 6 | R19: 5 | S19: 98936 | T19: RES | X19: 98944 | Y19: COM | Z19: 2 | AR19: 98936 | AS19: RES | AT19: 8 | AU19: 98942 | AV19: RES | AW19: 6
D20: 98935 | E20: RES | F20: 4 | G20: 98933 | H20: RES | I20: 1 | J20: 98936 | K20: COM | L20: 13 | N20: 98937 | O20: RES | P20: 5 | Q20: 2 | R20: 2 | S20: 98937 | T20: COM | U20: 1 | W20: 2 | X20: 98944 | Y20: RES | Z20: 1 | AR20: 98937 | AS20: RES | AT20: 1 | AU20: 98944 | AV20: COM | AW20: 3
D21: 98936 | E21: COM | F21: 7 | G21: 98935 | H21: COM | I21: 8 | J21: 98937 | K21: COM | L21: 10 | N21: 98938 | O21: COM | P21: 1 | S21: 98937 | T21: RES | V21: 2 | X21: 98947 | Y21: RES | Z21: 1 | AR21: 98938 | AS21: COM | AT21: 1 | AU21: 98944 | AV21: RES | AW21: 7
D22: 98936 | E22: RES | F22: 9 | G22: 98936 | H22: COM | I22: 13 | J22: 98938 | K22: COM | L22: 1 | N22: 98938 | O22: RES | P22: 7 | Q22: 2 | R22: 1 | S22: 98938 | T22: COM | X22: 98948 | Y22: RES | Z22: 1 | AR22: 98938 | AS22: RES | AT22: 5 | AU22: 98947 | AV22: RES | AW22: 1
D23: 98937 | E23: RES | F23: 1 | G23: 98936 | H23: RES | I23: 2 | J23: 98938 | K23: RES | L23: 1 | N23: 98939 | O23: RES | P23: 1 | S23: 98938 | T23: RES | X23: 98951 | Y23: RES | Z23: 3 | AR23: 98939 | AS23: RES | AT23: 1 | AU23: 98948 | AV23: COM | AW23: 2
D24: 98938 | E24: RES | F24: 6 | G24: 98937 | H24: COM | I24: 10 | J24: 98942 | K24: COM | L24: 11 | N24: 98942 | O24: COM | P24: 2 | Q24: 2 | S24: 98939 | T24: RES | X24: 99324 | Y24: RES | Z24: 2 | AR24: 98942 | AS24: COM | AT24: 1 | AU24: 98948 | AV24: RES | AW24: 3
D25: 98939 | E25: RES | F25: 1 | G25: 98938 | H25: COM | I25: 1 | J25: 98942 | K25: RES | L25: 1 | N25: 98942 | O25: RES | P25: 14 | Q25: 25 | R25: 25 | S25: 98942 | T25: COM | W25: 2 | X25: 99328 | Y25: COM | Z25: 2 | AR25: 98942 | AS25: RES | AT25: 24 | AU25: 98951 | AV25: RES | AW25: 2
D26: 98942 | E26: COM | F26: 12 | G26: 98938 | H26: RES | I26: 1 | J26: 98944 | K26: COM | L26: 19 | N26: 98944 | O26: COM | P26: 4 | Q26: 1 | R26: 9 | S26: 98942 | T26: RES | U26: 7 | V26: 8 | W26: 6 | X26: 99328 | Y26: RES | Z26: 1 | AR26: 98944 | AS26: COM | AT26: 3 | AU26: 99324 | AV26: RES | AW26: 4
D27: 98942 | E27: RES | F27: 23 | G27: 98942 | H27: COM | I27: 15 | J27: 98944 | K27: RES | L27: 4 | N27: 98944 | O27: RES | P27: 36 | Q27: 21 | R27: 7 | S27: 98944 | T27: COM | U27: 2 | V27: 3 | W27: 1 | X27: 99347 | Y27: COM | Z27: 3 | AR27: 98947 | AS27: RES | AT27: 5 | AU27: 99347 | AV27: COM | AW27: 3
D28: 98944 | E28: COM | F28: 7 | G28: 98942 | H28: RES | I28: 7 | J28: 98947 | K28: COM | L28: 4 | N28: 98947 | O28: RES | P28: 3 | Q28: 5 | S28: 98944 | T28: RES | U28: 13 | V28: 7 | W28: 2 | X28: 99361 | Y28: RES | Z28: 2 | AR28: 98948 | AS28: COM | AT28: 1 | AU28: 99361 | AV28: RES | AW28: 1
D29: 98944 | E29: RES | F29: 30 | G29: 98944 | H29: COM | I29: 21 | J29: 98947 | K29: RES | L29: 1 | N29: 98948 | O29: RES | P29: 20 | Q29: 16 | R29: 20 | S29: 98947 | T29: RES | U29: 4 | V29: 2 | X29: 99362 | Y29: COM | Z29: 3 | AR29: 98948 | AS29: RES | AT29: 11 | AU29: 99362 | AV29: COM | AW29: 8
D30: 98947 | E30: RES | F30: 4 | G30: 98944 | H30: RES | I30: 11 | J30: 98948 | K30: COM | L30: 13 | N30: 98951 | O30: COM | R30: 1 | S30: 98948 | T30: COM | U30: 2 | V30: 5 | X30: 99362 | Y30: RES | Z30: 14 | AR30: 98951 | AS30: RES | AT30: 19 | AU30: 99362 | AV30: RES | AW30: 16
D31: 98948 | E31: COM | F31: 5 | G31: 98947 | H31: COM | I31: 4 | J31: 98948 | K31: RES | L31: 3 | N31: 98951 | O31: RES | P31: 18 | Q31: 24 | R31: 13 | S31: 98948 | T31: RES | U31: 4 | V31: 3 | W31: 1 | AR31: 98952 | AS31: RES | AT31: 3
D32: 98948 | E32: RES | F32: 16 | G32: 98947 | H32: RES | I32: 2 | J32: 98951 | K32: COM | L32: 36 | N32: 98952 | O32: RES | Q32: 1 | R32: 2 | S32: 98951 | T32: COM | U32: 1 | V32: 8 | W32: 6 | AR32: 98953 | AS32: COM | AT32: 1
D33: 98951 | E33: COM | F33: 11 | G33: 98948 | H33: COM | I33: 14 | J33: 98951 | K33: RES | L33: 2 | N33: 98953 | O33: COM | R33: 1 | S33: 98951 | T33: RES | U33: 9 | V33: 2 | AR33: 98953 | AS33: RES | AT33: 10
D34: 98951 | E34: RES | F34: 20 | G34: 98948 | H34: RES | I34: 6 | J34: 98952 | K34: COM | L34: 1 | N34: 98953 | O34: RES | P34: 7 | Q34: 6 | R34: 9 | S34: 98952 | T34: RES | V34: 2 | AR34: 99323 | AS34: RES | AT34: 3
D35: 98952 | E35: RES | F35: 2 | G35: 98951 | H35: COM | I35: 34 | J35: 98953 | K35: COM | L35: 13 | N35: 99323 | O35: RES | Q35: 2 | R35: 3 | S35: 98953 | T35: COM | U35: 2 | AR35: 99324 | AS35: RES | AT35: 5
D36: 98953 | E36: COM | F36: 1 | G36: 98951 | H36: RES | I36: 4 | J36: 98953 | K36: RES | L36: 3 | N36: 99324 | O36: RES | P36: 14 | Q36: 8 | R36: 10 | S36: 98953 | T36: RES | U36: 5 | V36: 3 | AR36: 99328 | AS36: COM | AT36: 3
D37: 98953 | E37: RES | F37: 9 | G37: 98952 | H37: COM | I37: 1 | J37: 99323 | K37: COM | L37: 2 | N37: 99328 | O37: COM | R37: 1 | S37: 99323 | T37: COM | U37: 1 | AR37: 99328 | AS37: RES | AT37: 10
D38: 99323 | E38: COM | F38: 2 | G38: 98953 | H38: COM | I38: 12 | J38: 99324 | K38: COM | L38: 1 | N38: 99328 | O38: RES | P38: 7 | Q38: 9 | R38: 4 | S38: 99323 | T38: RES | U38: 2 | AR38: 99347 | AS38: RES | AT38: 2
D39: 99323 | E39: RES | F39: 2 | G39: 98953 | H39: RES | I39: 3 | J39: 99328 | K39: COM | L39: 6 | N39: 99347 | O39: RES | P39: 2 | Q39: 4 | R39: 4 | S39: 99324 | T39: RES | U39: 8 | W39: 7 | AR39: 99361 | AS39: RES | AT39: 1
D40: 99324 | E40: RES | F40: 5 | G40: 99323 | H40: COM | I40: 2 | J40: 99347 | K40: COM | L40: 2 | N40: 99360 | O40: COM | R40: 1 | S40: 99328 | T40: COM | U40: 1 | V40: 2 | AR40: 99362 | AS40: COM | AT40: 4
...

Sheet DEP_WKSHT
A1: Zip Code | B1: CLASS | C1: CountOfConcat Agreement Number | D1: MO | G1: Zip Code | H1: CLASS | I1: CountOfConcat Agreement Number | J1: YRMO | K1: Expr1 | Q1: Sum of CountOfConcat Agreement Number | S1: YRMO | X1: Zip Code | Y1: CLASS | Z1: CountOfConcat Agreement Number | AA1: SumOfAmount | AB1: YRMO | AD1: Sum of CountOfConcat Agreement Number | AF1: YRMO
A2: 98901 | B2: NDEP | C2: 78 | D2: 1 | E2: =VLOOKUP(A2,'6. Deposits 2023_Q3'!$A$3:$A$34,1,FALSE) -> #N/A | G2: 98901 | H2: NDEP | I2: 4 | J2: 202010 | K2: 0 | Q2: CLASS | R2: Zip Code | S2: 202010 | T2: 202011 | U2: 202012 | V2: 20209 | X2: 98901 | Y2: NDEP | Z2: 30 | AA2: 0 | AB2: 10 | AD2: CLASS | AE2: Zip Code | AF2: 10 | AG2: 11 | AH2: 12 | AI2: Grand Total
A3: 98902 | B3: NDEP | C3: 97 | D3: 1 | E3: =VLOOKUP(A3,'6. Deposits 2023_Q3'!$A$3:$A$34,1,FALSE) -> #N/A | G3: 98901 | H3: NDEP | I3: 9 | J3: 202011 | K3: 0 | Q3: NDEP | R3: 98901 | S3: 4 | T3: 9 | U3: 2 | V3: 6 | X3: 98901 | Y3: NDEP | Z3: 16 | AA3: 0 | AB3: 11 | AD3: NDEP | AE3: 98901 | AF3: 30 | AG3: 16 | AH3: 20 | AI3: 66
A4: 98903 | B4: NDEP | C4: 47 | D4: 1 | E4: =VLOOKUP(A4,'6. Deposits 2023_Q3'!$A$3:$A$34,1,FALSE) -> #N/A | G4: 98901 | H4: NDEP | I4: 2 | J4: 202012 | K4: 0 | Q4: NDEP | R4: 98902 | S4: 8 | T4: 2 | U4: 2 | V4: 5 | X4: 98901 | Y4: NDEP | Z4: 20 | AA4: 0 | AB4: 12 | AD4: NDEP | AE4: 98902 | AF4: 24 | AG4: 22 | AH4: 32 | AI4: 78
A5: 98908 | B5: NDEP | C5: 35 | D5: 1 | E5: =VLOOKUP(A5,'6. Deposits 2023_Q3'!$A$3:$A$34,1,FALSE) -> #N/A | G5: 98901 | H5: NDEP | I5: 6 | J5: 20209 | K5: 0 | Q5: NDEP | R5: 98903 | S5: 2 | T5: 2 | V5: 4 | X5: 98901 | Y5: RDEP | Z5: 344 | AA5: 0 | AB5: 10 | AD5: NDEP | AE5: 98903 | AF5: 12 | AG5: 6 | AH5: 8 | AI5: 26
A6: 98920 | B6: NDEP | C6: 2 | D6: 1 | E6: =VLOOKUP(A6,'6. Deposits 2023_Q3'!$A$3:$A$34,1,FALSE) -> #N/A | G6: 98901 | H6: RDEP | I6: 99 | J6: 202010 | K6: 0 | Q6: NDEP | R6: 98908 | T6: 5 | X6: 98901 | Y6: RDEP | Z6: 358 | AA6: 0 | AB6: 11 | AD6: NDEP | AE6: 98908 | AF6: 8 | AG6: 18 | AH6: 12 | AI6: 38
A7: 98921 | B7: NDEP | C7: 2 | D7: 1 | E7: =VLOOKUP(A7,'6. Deposits 2023_Q3'!$A$3:$A$34,1,FALSE) -> #N/A | G7: 98901 | H7: RDEP | I7: 70 | J7: 202011 | K7: 0 | Q7: NDEP | R7: 98930 | S7: 3 | X7: 98901 | Y7: RDEP | Z7: 398 | AA7: 0 | AB7: 12 | AD7: NDEP | AE7: 98920 | AH7: 2 | AI7: 2
A8: 98930 | B8: NDEP | C8: 24 | D8: 1 | E8: =VLOOKUP(A8,'6. Deposits 2023_Q3'!$A$3:$A$34,1,FALSE) -> #N/A | G8: 98901 | H8: RDEP | I8: 26 | J8: 202012 | K8: 0 | Q8: NDEP | R8: 98937 | T8: 3 | U8: 2 | X8: 98902 | Y8: NDEP | Z8: 24 | AA8: 0 | AB8: 10 | AD8: NDEP | AE8: 98930 | AF8: 8 | AG8: 8 | AH8: 4 | AI8: 20
A9: 98932 | B9: NDEP | C9: 7 | D9: 1 | E9: =VLOOKUP(A9,'6. Deposits 2023_Q3'!$A$3:$A$34,1,FALSE) -> #N/A | G9: 98901 | H9: RDEP | I9: 109 | J9: 20209 | K9: 0 | Q9: NDEP | R9: 98942 | S9: 2 | V9: 1 | X9: 98902 | Y9: NDEP | Z9: 22 | AA9: 0 | AB9: 11 | AD9: NDEP | AE9: 98932 | AF9: 2 | AI9: 2
A10: 98933 | B10: NDEP | C10: 3 | D10: 1 | E10: =VLOOKUP(A10,'6. Deposits 2023_Q3'!$A$3:$A$34,1,FALSE) -> #N/A | G10: 98902 | H10: NDEP | I10: 8 | J10: 202010 | K10: 0 | Q10: NDEP | R10: 98944 | S10: 17 | U10: 6 | V10: 2 | X10: 98902 | Y10: NDEP | Z10: 32 | AA10: 0 | AB10: 12 | AD10: NDEP | AE10: 98933 | AF10: 2 | AG10: 4 | AH10: 2 | AI10: 8
A11: 98935 | B11: NDEP | C11: 4 | D11: 1 | E11: =VLOOKUP(A11,'6. Deposits 2023_Q3'!$A$3:$A$34,1,FALSE) -> #N/A | G11: 98902 | H11: NDEP | I11: 2 | J11: 202011 | K11: 0 | Q11: NDEP | R11: 98948 | S11: 2 | X11: 98902 | Y11: RDEP | Z11: 502 | AA11: 0 | AB11: 10 | AD11: NDEP | AE11: 98935 | AF11: 4 | AI11: 4
A12: 98936 | B12: NDEP | C12: 21 | D12: 1 | E12: =VLOOKUP(A12,'6. Deposits 2023_Q3'!$A$3:$A$34,1,FALSE) -> #N/A | G12: 98902 | H12: NDEP | I12: 2 | J12: 202012 | K12: 0 | Q12: NDEP | R12: 98951 | S12: 2 | T12: 2 | U12: 2 | X12: 98902 | Y12: RDEP | Z12: 510 | AA12: 0 | AB12: 11 | AD12: NDEP | AE12: 98936 | AF12: 4 | AG12: 2 | AH12: 24 | AI12: 30
A13: 98937 | B13: NDEP | C13: 10 | D13: 1 | E13: =VLOOKUP(A13,'6. Deposits 2023_Q3'!$A$3:$A$34,1,FALSE) -> #N/A | G13: 98902 | H13: NDEP | I13: 5 | J13: 20209 | K13: 0 | Q13: NDEP | R13: 99324 | T13: 2 | X13: 98902 | Y13: RDEP | Z13: 784 | AA13: 0 | AB13: 12 | AD13: NDEP | AE13: 98937 | AG13: 6 | AH13: 2 | AI13: 8
A14: 98938 | B14: NDEP | C14: 1 | D14: 1 | E14: =VLOOKUP(A14,'6. Deposits 2023_Q3'!$A$3:$A$34,1,FALSE) -> #N/A | G14: 98902 | H14: RDEP | I14: 163 | J14: 202010 | K14: 0 | Q14: NDEP | R14: 99328 | V14: 1 | X14: 98903 | Y14: NDEP | Z14: 12 | AA14: 0 | AB14: 10 | AD14: NDEP | AE14: 98942 | AF14: 8 | AG14: 14 | AH14: 4 | AI14: 26
A15: 98942 | B15: NDEP | C15: 18 | D15: 1 | E15: =VLOOKUP(A15,'6. Deposits 2023_Q3'!$A$3:$A$34,1,FALSE) -> #N/A | G15: 98902 | H15: RDEP | I15: 98 | J15: 202011 | K15: 0 | Q15: NDEP | R15: 99347 | S15: 2 | T15: 2 | X15: 98903 | Y15: NDEP | Z15: 6 | AA15: 0 | AB15: 11 | AD15: NDEP | AE15: 98944 | AF15: 12 | AG15: 26 | AH15: 18 | AI15: 56
A16: 98944 | B16: NDEP | C16: 61 | D16: 1 | E16: =VLOOKUP(A16,'6. Deposits 2023_Q3'!$A$3:$A$34,1,FALSE) -> #N/A | G16: 98902 | H16: RDEP | I16: 53 | J16: 202012 | K16: 0 | Q16: NDEP | R16: 99360 | T16: 2 | X16: 98903 | Y16: NDEP | Z16: 8 | AA16: 0 | AB16: 12 | AD16: NDEP | AE16: 98948 | AF16: 6 | AG16: 2 | AH16: 10 | AI16: 18
A17: 98947 | B17: NDEP | C17: 1 | D17: 1 | E17: =VLOOKUP(A17,'6. Deposits 2023_Q3'!$A$3:$A$34,1,FALSE) -> #N/A | G17: 98902 | H17: RDEP | I17: 127 | J17: 20209 | K17: 0 | Q17: NDEP | R17: 99361 | S17: 2 | V17: 1 | X17: 98903 | Y17: RDEP | Z17: 130 | AA17: 0 | AB17: 10 | AD17: NDEP | AE17: 98951 | AF17: 2 | AG17: 4 | AH17: 16 | AI17: 22
A18: 98948 | B18: NDEP | C18: 29 | D18: 1 | E18: =VLOOKUP(A18,'6. Deposits 2023_Q3'!$A$3:$A$34,1,FALSE) -> #N/A | G18: 98903 | H18: NDEP | I18: 2 | J18: 202010 | K18: 0 | Q18: NDEP | R18: 99362 | S18: 4 | T18: 8 | U18: 3 | V18: 8 | X18: 98903 | Y18: RDEP | Z18: 84 | AA18: 0 | AB18: 11 | AD18: NDEP | AE18: 98952 | AH18: 4 | AI18: 4
A19: 98951 | B19: NDEP | C19: 36 | D19: 1 | E19: =VLOOKUP(A19,'6. Deposits 2023_Q3'!$A$3:$A$34,1,FALSE) -> #N/A | G19: 98903 | H19: NDEP | I19: 2 | J19: 202011 | K19: 0 | Q19: NDEP | R19: 99363 | S19: 1 | X19: 98903 | Y19: RDEP | Z19: 130 | AA19: 0 | AB19: 12 | AD19: NDEP | AE19: 98953 | AF19: 2 | AG19: 2 | AH19: 4 | AI19: 8
A20: 98952 | B20: NDEP | C20: 1 | D20: 1 | E20: =VLOOKUP(A20,'6. Deposits 2023_Q3'!$A$3:$A$34,1,FALSE) -> #N/A | G20: 98903 | H20: NDEP | I20: 4 | J20: 20209 | K20: 0 | Q20: RDEP | R20: 98901 | S20: 99 | T20: 70 | U20: 26 | V20: 109 | X20: 98908 | Y20: NDEP | Z20: 8 | AA20: 0 | AB20: 10 | AD20: NDEP | AE20: 99323 | AH20: 2 | AI20: 2
A21: 98953 | B21: NDEP | C21: 10 | D21: 1 | E21: =VLOOKUP(A21,'6. Deposits 2023_Q3'!$A$3:$A$34,1,FALSE) -> #N/A | G21: 98903 | H21: RDEP | I21: 27 | J21: 202010 | K21: 0 | Q21: RDEP | R21: 98902 | S21: 163 | T21: 98 | U21: 53 | V21: 127 | X21: 98908 | Y21: NDEP | Z21: 18 | AA21: 0 | AB21: 11 | AD21: NDEP | AE21: 99324 | AG21: 4 | AH21: 2 | AI21: 6
A22: 99323 | B22: NDEP | C22: 1 | D22: 1 | E22: =VLOOKUP(A22,'6. Deposits 2023_Q3'!$A$3:$A$34,1,FALSE) -> #N/A | G22: 98903 | H22: RDEP | I22: 5 | J22: 202011 | K22: 0 | Q22: RDEP | R22: 98903 | S22: 27 | T22: 5 | U22: 12 | V22: 26 | X22: 98908 | Y22: NDEP | Z22: 12 | AA22: 0 | AB22: 12 | AD22: NDEP | AE22: 99328 | AF22: 2 | AH22: 2 | AI22: 4
A23: 99324 | B23: NDEP | C23: 4 | D23: 1 | E23: =VLOOKUP(A23,'6. Deposits 2023_Q3'!$A$3:$A$34,1,FALSE) -> #N/A | G23: 98903 | H23: RDEP | I23: 12 | J23: 202012 | K23: 0 | Q23: RDEP | R23: 98908 | S23: 136 | T23: 107 | U23: 32 | V23: 123 | X23: 98908 | Y23: RDEP | Z23: 320 | AA23: 0 | AB23: 10 | AD23: NDEP | AE23: 99347 | AG23: 4 | AI23: 4
A24: 99328 | B24: NDEP | C24: 5 | D24: 1 | E24: =VLOOKUP(A24,'6. Deposits 2023_Q3'!$A$3:$A$34,1,FALSE) -> #N/A | G24: 98903 | H24: RDEP | I24: 26 | J24: 20209 | K24: 0 | Q24: RDEP | R24: 98921 | S24: 7 | T24: 4 | V24: 4 | X24: 98908 | Y24: RDEP | Z24: 450 | AA24: 0 | AB24: 11 | AD24: NDEP | AE24: 99360 | AG24: 4 | AH24: 2 | AI24: 6
A25: 99329 | B25: NDEP | C25: 1 | D25: 1 | E25: =VLOOKUP(A25,'6. Deposits 2023_Q3'!$A$3:$A$34,1,FALSE) -> #N/A | G25: 98908 | H25: NDEP | I25: 5 | J25: 202011 | K25: 0 | Q25: RDEP | R25: 98923 | S25: 3 | T25: 2 | U25: 1 | V25: 2 | X25: 98908 | Y25: RDEP | Z25: 350 | AA25: 0 | AB25: 12 | AD25: NDEP | AE25: 99361 | AH25: 6 | AI25: 6
A26: 99347 | B26: NDEP | C26: 3 | D26: 1 | E26: =VLOOKUP(A26,'6. Deposits 2023_Q3'!$A$3:$A$34,1,FALSE) -> #N/A | G26: 98908 | H26: RDEP | I26: 136 | J26: 202010 | K26: 0 | Q26: RDEP | R26: 98930 | S26: 29 | T26: 10 | U26: 18 | V26: 15 | X26: 98920 | Y26: NDEP | Z26: 2 | AA26: 0 | AB26: 12 | AD26: NDEP | AE26: 99362 | AF26: 18 | AG26: 20 | AH26: 16 | AI26: 54
A27: 99360 | B27: NDEP | C27: 3 | D27: 1 | E27: =VLOOKUP(A27,'6. Deposits 2023_Q3'!$A$3:$A$34,1,FALSE) -> #N/A | G27: 98908 | H27: RDEP | I27: 107 | J27: 202011 | K27: 0 | Q27: RDEP | R27: 98932 | S27: 7 | T27: 17 | U27: 8 | V27: 7 | X27: 98921 | Y27: RDEP | Z27: 6 | AA27: 0 | AB27: 10 | AD27: RDEP | AE27: 98901 | AF27: 344 | AG27: 358 | AH27: 398 | AI27: 1100
A28: 99361 | B28: NDEP | C28: 6 | D28: 1 | E28: =VLOOKUP(A28,'6. Deposits 2023_Q3'!$A$3:$A$34,1,FALSE) -> #N/A | G28: 98908 | H28: RDEP | I28: 32 | J28: 202012 | K28: 0 | Q28: RDEP | R28: 98933 | S28: 3 | T28: 3 | U28: 3 | V28: 1 | X28: 98921 | Y28: RDEP | Z28: 18 | AA28: 0 | AB28: 11 | AD28: RDEP | AE28: 98902 | AF28: 502 | AG28: 510 | AH28: 784 | AI28: 1796
A29: 99362 | B29: NDEP | C29: 62 | D29: 1 | E29: =VLOOKUP(A29,'6. Deposits 2023_Q3'!$A$3:$A$34,1,FALSE) -> #N/A | G29: 98908 | H29: RDEP | I29: 123 | J29: 20209 | K29: 0 | Q29: RDEP | R29: 98935 | S29: 5 | T29: 6 | U29: 2 | V29: 4 | X29: 98921 | Y29: RDEP | Z29: 14 | AA29: 0 | AB29: 12 | AD29: RDEP | AE29: 98903 | AF29: 130 | AG29: 84 | AH29: 130 | AI29: 344
A30: 99363 | B30: NDEP | C30: 1 | D30: 1 | E30: =VLOOKUP(A30,'6. Deposits 2023_Q3'!$A$3:$A$34,1,FALSE) -> #N/A | G30: 98921 | H30: RDEP | I30: 7 | J30: 202010 | K30: 0 | Q30: RDEP | R30: 98936 | S30: 6 | T30: 10 | U30: 6 | V30: 5 | X30: 98923 | Y30: RDEP | Z30: 4 | AA30: 0 | AB30: 10 | AD30: RDEP | AE30: 98908 | AF30: 320 | AG30: 450 | AH30: 350 | AI30: 1120
A31: 98901 | B31: RDEP | C31: 1427 | D31: 1 | E31: =VLOOKUP(A31,'6. Deposits 2023_Q3'!$A$35:$A$61,1,FALSE) -> #N/A | G31: 98921 | H31: RDEP | I31: 4 | J31: 202011 | K31: 0 | Q31: RDEP | R31: 98937 | S31: 9 | T31: 2 | U31: 3 | V31: 7 | X31: 98923 | Y31: RDEP | Z31: 4 | AA31: 0 | AB31: 11 | AD31: RDEP | AE31: 98921 | AF31: 6 | AG31: 18 | AH31: 14 | AI31: 38
A32: 98902 | B32: RDEP | C32: 1838 | D32: 1 | E32: =VLOOKUP(A32,'6. Deposits 2023_Q3'!$A$35:$A$61,1,FALSE) -> #N/A | G32: 98921 | H32: RDEP | I32: 4 | J32: 20209 | K32: 0 | Q32: RDEP | R32: 98938 | S32: 1 | U32: 4 | X32: 98923 | Y32: RDEP | Z32: 16 | AA32: 0 | AB32: 12 | AD32: RDEP | AE32: 98923 | AF32: 4 | AG32: 4 | AH32: 16 | AI32: 24
A33: 98903 | B33: RDEP | C33: 403 | D33: 1 | E33: =VLOOKUP(A33,'6. Deposits 2023_Q3'!$A$35:$A$61,1,FALSE) -> #N/A | G33: 98923 | H33: RDEP | I33: 3 | J33: 202010 | K33: 0 | Q33: RDEP | R33: 98939 | U33: 1 | X33: 98930 | Y33: NDEP | Z33: 8 | AA33: 0 | AB33: 10 | AD33: RDEP | AE33: 98930 | AF33: 90 | AG33: 74 | AH33: 120 | AI33: 284
A34: 98908 | B34: RDEP | C34: 1026 | D34: 1 | E34: =VLOOKUP(A34,'6. Deposits 2023_Q3'!$A$35:$A$61,1,FALSE) -> #N/A | G34: 98923 | H34: RDEP | I34: 2 | J34: 202011 | K34: 0 | Q34: RDEP | R34: 98942 | S34: 42 | T34: 27 | U34: 12 | V34: 36 | X34: 98930 | Y34: NDEP | Z34: 8 | AA34: 0 | AB34: 11 | AD34: RDEP | AE34: 98932 | AF34: 30 | AG34: 72 | AH34: 62 | AI34: 164
A35: 98921 | B35: RDEP | C35: 31 | D35: 1 | E35: =VLOOKUP(A35,'6. Deposits 2023_Q3'!$A$35:$A$61,1,FALSE) -> #N/A | G35: 98923 | H35: RDEP | I35: 1 | J35: 202012 | K35: 0 | Q35: RDEP | R35: 98944 | S35: 23 | T35: 30 | U35: 15 | V35: 31 | X35: 98930 | Y35: NDEP | Z35: 4 | AA35: 0 | AB35: 12 | AD35: RDEP | AE35: 98933 | AF35: 4 | AG35: 4 | AH35: 14 | AI35: 22
A36: 98923 | B36: RDEP | C36: 30 | D36: 1 | E36: =VLOOKUP(A36,'6. Deposits 2023_Q3'!$A$35:$A$61,1,FALSE) -> #N/A | G36: 98923 | H36: RDEP | I36: 2 | J36: 20209 | K36: 0 | Q36: RDEP | R36: 98947 | S36: 4 | T36: 2 | U36: 3 | V36: 1 | X36: 98930 | Y36: RDEP | Z36: 90 | AA36: 0 | AB36: 10 | AD36: RDEP | AE36: 98935 | AF36: 30 | AG36: 16 | AH36: 36 | AI36: 82
A37: 98930 | B37: RDEP | C37: 336 | D37: 1 | E37: =VLOOKUP(A37,'6. Deposits 2023_Q3'!$A$35:$A$61,1,FALSE) -> #N/A | G37: 98930 | H37: NDEP | I37: 3 | J37: 202010 | K37: 0 | Q37: RDEP | R37: 98948 | S37: 24 | T37: 4 | U37: 4 | V37: 10 | X37: 98930 | Y37: RDEP | Z37: 74 | AA37: 0 | AB37: 11 | AD37: RDEP | AE37: 98936 | AF37: 38 | AG37: 26 | AH37: 80 | AI37: 144
A38: 98932 | B38: RDEP | C38: 165 | D38: 1 | E38: =VLOOKUP(A38,'6. Deposits 2023_Q3'!$A$35:$A$61,1,FALSE) -> #N/A | G38: 98930 | H38: RDEP | I38: 29 | J38: 202010 | K38: 0 | Q38: RDEP | R38: 98951 | S38: 16 | T38: 12 | U38: 8 | V38: 10 | X38: 98930 | Y38: RDEP | Z38: 120 | AA38: 0 | AB38: 12 | AD38: RDEP | AE38: 98937 | AF38: 20 | AG38: 30 | AH38: 38 | AI38: 88
A39: 98933 | B39: RDEP | C39: 24 | D39: 1 | E39: =VLOOKUP(A39,'6. Deposits 2023_Q3'!$A$35:$A$61,1,FALSE) -> #N/A | G39: 98930 | H39: RDEP | I39: 10 | J39: 202011 | K39: 0 | Q39: RDEP | R39: 98952 | S39: 1 | U39: 1 | X39: 98932 | Y39: NDEP | Z39: 2 | AA39: 0 | AB39: 10 | AD39: RDEP | AE39: 98938 | AF39: 24 | AG39: 14 | AH39: 40 | AI39: 78
A40: 98935 | B40: RDEP | C40: 85 | D40: 1 | E40: =VLOOKUP(A40,'6. Deposits 2023_Q3'!$A$35:$A$61,1,FALSE) -> #N/A | G40: 98930 | H40: RDEP | I40: 18 | J40: 202012 | K40: 0 | Q40: RDEP | R40: 98953 | S40: 7 | T40: 9 | V40: 10 | X40: 98932 | Y40: RDEP | Z40: 30 | AA40: 0 | AB40: 10 | AD40: RDEP | AE40: 98939 | AF40: 4 | AG40: 4 | AH40: 2 | AI40: 10
...

Sheet 7. Bill Assistance 2023_Q3
A1: Item a) Number of Premises Receiving Bill Assistance or Enrolled in Any Other Assistance Program
A2: 44197 | B2: 44228 | C2: 44256 | D2: ZIP ** | E2: 44287 | F2: 44317 | G2: 44348 | H2: 44378 | I2: 44409 | J2: 44440 | K2: 44470 | L2: 44501 | M2: 44531 | N2: Zip Code | O2: 45108 | P2: Zip Code | Q2: 45139 | R2: Zip Code | S2: 45170
N3: 98901 | O3: 1212 | P3: 98901 | Q3: 1208 | R3: 98901 | S3: 1178
N4: 98902 | O4: 1708 | P4: 98902 | Q4: 1696 | R4: 98902 | S4: 1669
N5: 98903 | O5: 563 | P5: 98903 | Q5: 563 | R5: 98903 | S5: 557
N6: 98908 | O6: 562 | P6: 98908 | Q6: 562 | R6: 98908 | S6: 548
N7: 98921 | O7: 53 | P7: 98921 | Q7: 54 | R7: 98921 | S7: 53
N8: 98923 | O8: 29 | P8: 98923 | Q8: 28 | R8: 98923 | S8: 28
N9: 98930 | O9: 452 | P9: 98930 | Q9: 452 | R9: 98930 | S9: 446
N10: 98932 | O10: 214 | P10: 98932 | Q10: 212 | R10: 98932 | S10: 210
N11: 98933 | O11: 19 | P11: 98933 | Q11: 19 | R11: 98933 | S11: 19
N12: 98935 | O12: 138 | P12: 98935 | Q12: 137 | R12: 98935 | S12: 137
N13: 98936 | O13: 100 | P13: 98936 | Q13: 98 | R13: 98936 | S13: 97
N14: 98937 | O14: 47 | P14: 98937 | Q14: 48 | R14: 98937 | S14: 45
... N34: 99363 | O34: 4 | P34: 99363 | Q34: 4 | R34: 99363 | S34: 5
N35: TOTAL | O35: =SUM(O3:O34) -> 8355 | Q35: =SUM(Q3:Q34) -> 8328 | S35: =SUM(S3:S34) -> 8181

Sheet BA_WRKSHT
A1: FLAG | B1: SumOfJAN20 | C1: SumOfFEB20 | D1: SumOfMAR20 | E1: SumOfAPR20 | F1: SumOfMAY20 | G1: SumOfJUN20 | H1: SumOfJUL20 | I1: SumOfAUG20 | J1: SumOfSEP20 | K1: SumOfOCT20 | L1: SumOfNOV20 | M1: SumOfDEC20 | N1: SumOfJAN19 | O1: SumOfFEB19 | P1: SumOfMAR19 | Q1: SumOfAPR19 | R1: SumOfMAY19 | S1: SumOfJUN19 | T1: SumOfJUL19 | U1: SumOfAUG19 | V1: SumOfSEP19 | W1: SumOfOCT19 | X1: SumOfNOV19 | Y1: SumOfDEC19
A2: 98901RES | B2: 37 | C2: 35 | D2: 33 | E2: 31 | F2: 31 | G2: 31 | H2: 30 | I2: 27 | J2: 27 | K2: 27 | L2: 24 | M2: 24 | N2: 23 | O2: 28 | P2: 28 | Q2: 30 | R2: 32 | S2: 33 | T2: 33 | U2: 35 | V2: 36 | W2: 37 | X2: 38 | Y2: 39
A3: 98902RES | B3: 54 | C3: 51 | D3: 48 | E3: 46 | F3: 43 | G3: 41 | H3: 38 | I3: 34 | J3: 33 | K3: 29 | L3: 27 | M3: 24 | N3: 24 | O3: 31 | P3: 34 | Q3: 38 | R3: 39 | S3: 43 | T3: 45 | U3: 47 | V3: 48 | W3: 50 | X3: 51 | Y3: 53
A4: 98903RES | B4: 26 | C4: 26 | D4: 24 | E4: 24 | F4: 23 | G4: 21 | H4: 22 | I4: 23 | J4: 23 | K4: 22 | L4: 22 | M4: 21 | N4: 22 | O4: 23 | P4: 24 | Q4: 26 | R4: 26 | S4: 27 | T4: 26 | U4: 26 | V4: 25 | W4: 26 | X4: 26 | Y4: 26
A5: 98908RES | B5: 29 | C5: 29 | D5: 27 | E5: 27 | F5: 27 | G5: 26 | H5: 26 | I5: 25 | J5: 26 | K5: 26 | L5: 26 | M5: 23 | N5: 23 | O5: 26 | P5: 26 | Q5: 26 | R5: 25 | S5: 25 | T5: 25 | U5: 26 | V5: 27 | W5: 27 | X5: 26 | Y5: 28
A6: 98921RES | B6: 10 | C6: 10 | D6: 9 | E6: 9 | F6: 9 | G6: 10 | H6: 9 | I6: 9 | J6: 7 | K6: 7 | L6: 7 | M6: 7 | N6: 12 | O6: 13 | P6: 12 | Q6: 12 | R6: 12 | S6: 11 | T6: 11 | U6: 10 | V6: 10 | W6: 10 | X6: 10 | Y6: 10
A7: 98923RES | B7: 3 | C7: 4 | D7: 3 | E7: 4 | F7: 3 | G7: 3 | H7: 4 | I7: 3 | J7: 4 | K7: 3 | L7: 4 | M7: 4 | N7: 4 | O7: 4 | P7: 5 | Q7: 4 | R7: 4 | S7: 5 | T7: 4 | U7: 4 | V7: 5 | W7: 5 | X7: 4 | Y7: 4
A8: 98930RES | B8: 33 | C8: 32 | D8: 32 | E8: 32 | F8: 30 | G8: 29 | H8: 28 | I8: 28 | J8: 28 | K8: 24 | L8: 21 | M8: 20 | N8: 21 | O8: 22 | P8: 25 | Q8: 25 | R8: 26 | S8: 27 | T8: 28 | U8: 28 | V8: 32 | W8: 31 | X8: 32 | Y8: 32
A9: 98932RES | B9: 21 | C9: 20 | D9: 21 | E9: 22 | F9: 21 | G9: 18 | H9: 18 | I9: 18 | J9: 17 | K9: 16 | L9: 15 | M9: 14 | N9: 16 | O9: 17 | P9: 17 | Q9: 17 | R9: 17 | S9: 19 | T9: 19 | U9: 20 | V9: 19 | W9: 20 | X9: 21 | Y9: 21
A10: 98933RES | B10: 4 | C10: 4 | D10: 4 | E10: 4 | F10: 4 | G10: 4 | H10: 4 | I10: 3 | J10: 2 | K10: 2 | L10: 2 | M10: 3 | N10: 2 | O10: 3 | P10: 3 | Q10: 3 | R10: 2 | S10: 3 | T10: 1 | U10: 1 | V10: 1 | W10: 2 | X10: 3 | Y10: 3
A11: 98935RES | B11: 12 | C11: 12 | D11: 12 | E11: 12 | F11: 12 | G11: 11 | H11: 10 | I11: 10 | J11: 10 | K11: 10 | L11: 10 | M11: 8 | N11: 9 | O11: 10 | P11: 10 | Q11: 9 | R11: 10 | S11: 11 | T11: 11 | U11: 10 | V11: 10 | W11: 12 | X11: 12 | Y11: 12
A12: 98936RES | B12: 8 | C12: 8 | D12: 7 | E12: 8 | F12: 7 | G12: 8 | H12: 8 | I12: 8 | J12: 8 | K12: 10 | L12: 10 | M12: 9 | N12: 7 | O12: 7 | P12: 7 | Q12: 7 | R12: 6 | S12: 6 | T12: 6 | U12: 5 | V12: 5 | W12: 7 | X12: 6 | Y12: 8
A13: 98937RES | B13: 9 | C13: 10 | D13: 9 | E13: 9 | F13: 8 | G13: 10 | H13: 10 | I13: 9 | J13: 10 | K13: 9 | L13: 9 | M13: 9 | N13: 7 | O13: 7 | P13: 7 | Q13: 7 | R13: 8 | S13: 8 | T13: 7 | U13: 7 | V13: 7 | W13: 9 | X13: 8 | Y13: 9
... A33: 99363RES | B33: 3 | C33: 2 | D33: 2 | E33: 2 | F33: 2 | G33: 2 | H33: 2 | I33: 1 | J33: 2 | K33: 1 | L33: 1 | M33: 1 | N33: 2 | O33: 2 | P33: 2 | Q33: 3 | R33: 2 | S33: 2 | T33: 2 | U33: 2 | V33: 2 | W33: 2 | X33: 2 | Y33: 3

Sheet 8.ARREARS NEW 2023_Q3
A1: Item a) Number of Customers by Customer Class With Past-due balances (arrearages) | R1: Item c) Amount of Past-due Balances for Known Low-income Households and Number of Days Past-due | AR1: Section D. Bad Debt | AW1: Item e) The Amount of Past-due Balances Written-off and Classified as Bad Debt, if different than item d | BJ1: Item f) Number of Customer Accounts Referred to Collection Agencies | BS1: Item f) Total Amount of Bad Debt Referred for Collection | BY1: Item f) Total Revenue to the Company from the Collection Process
A3: 202307 | H3: 202308 | O3: 202309 | R3: 202307 | Y3: 202308 | AD3: 202309 | AR3: 202307 | AU3: 202308 | AV3: 202309 | AW3: Class | AX3: 202101 | AY3: 202102 | AZ3: 202103 | BA3: 202104 | BB3: 202105 | BC3: 202106 | BD3: 202107 | BE3: 202108 | BF3: 202109 | BG3: 202307 | BH3: 202308 | BI3: 202309 | BJ3: 202307 | BM3: 202308 | BP3: 202309 | BS3: 202307 | BU3: 202308 | BW3: 202309 | BY3: 202307 | CA3: 202308 | CC3: 202309
A4: CLASS | B4: ZIP | C4: COUNT | D4: DAYS 31 60 | E4: DAYS 61 90 | F4: DAYS 91+ | G4: ARREARS | H4: COUNT | I4: DAYS 31 60 | J4: DAYS 61 90 | K4: DAYS 91+ | L4: ARREARS | M4: COUNT | N4: DAYS 31 60 | O4: DAYS 61 90 | P4: DAYS 91+ | Q4: ARREARS | R4: CLASS | S4: ZIP | T4: COUNT | U4: DAYS 31 60 | V4: DAYS 61 90 | W4: DAYS 91+ | X4: ARREARS | Y4: COUNT | Z4: DAYS 31 60 | AA4: DAYS 61 90 | AB4: DAYS 91+ | AC4: ARREARS | AD4: COUNT | AE4: DAYS 31 60 | AF4: DAYS 61 90 | AG4: DAYS 91+ | AH4: ARREARS | AR4: CLASS | AS4: ZIP | AT4: BAD DEBT | AU4: BAD DEBT | AV4: BAD DEBT | AW4: RES | AX4: 78547.88 | AY4: 83507.78 | AZ4: 74673.15 | BA4: 63441.04 | BB4: 64476.9 | BC4: 57542.34 | BD4: 83815.89 | BE4: 81559.71 | BF4: 121882.53 | BG4: 235999.64 | BH4: 280875.02 | BI4: 334506.88 | BJ4: ZIP | BK4: CLASS | BL4: Count | BM4: ZIP | BN4: CLASS | BO4: Count | BP4: Zip Code | BQ4: CLASS | BR4: Count | BS4: ZIP/CLASS | BT4: Amount | BU4: ZIP/CLASS | BV4: Amount | BW4: ZIP/CLASS | BX4: Amount | BY4: ZIP/CLASS | BZ4: Amount | CA4: ZIP/CLASS | CB4: Amount | CC4: ZIP/CLASS | CD4: Amount
A5: COM | B5: 98901 | C5: 121 | D5: 45844.45 | E5: 22882.89 | F5: 183422.03 | G5: 252149.37 | H5: 130 | I5: 47977.92 | J5: 20050.96 | K5: 166925.16 | L5: 234954.04 | M5: 155 | N5: 65368.24 | O5: 22713.44 | P5: 120555.73 | Q5: 208637.41 | R5: COM | S5: 98901 | T5: 6 | U5: 225.34 | V5: 297.41 | W5: 1136.97 | X5: 1659.72 | Y5: 5 | Z5: 262.55 | AA5: 231.46 | AB5: 1412.06 | AC5: 1906.07 | AD5: 5 | AE5: 233.48 | AF5: 244.55 | AG5: 836.2 | AH5: 1314.23 | AR5: COM | AS5: 98901 | AT5: =D5*1.6%+E5*6.3%+F5*28.9% -> 55184.1 | AU5: =I5*1.6%+J5*6.3%+K5*28.9% -> 50272.228 | AV5: =N5*1.6%+O5*6.3%+P5*28.9% -> 37317.445 | AW5: COM | AX5: 35411.49 | AY5: 19861.99 | AZ5: 1614.2 | BA5: 209.93 | BB5: 2347.21 | BC5: 3702.39 | BD5: 16587.84 | BE5: 21717.76 | BF5: 41593.57 | BG5: 57754.15 | BH5: 41500.39 | BI5: 23065.75 | BJ5: 98901 | BK5: COM | BL5: 2 | BM5: 98901 | BN5: COM | BO5: 5 | BP5: 98901 | BQ5: COM | BR5: 3 | BS5: 98901COM | BT5: 1021.93 | BU5: 98901COM | BV5: 55987.33 | BW5: 98901COM | BX5: 26605.29 | BY5: 98901COM | BZ5: 87.97 | CA5: 98901COM | CB5: 230.16 | CC5: 98901RES | CD5: 819.1
A6: COM | B6: 98902 | C6: 209 | D6: 70788.9 | E6: 27409.63 | F6: 107286.42 | G6: 205484.95 | H6: 197 | I6: 60951.68 | J6: 26441.63 | K6: 108496.66 | L6: 195889.97 | M6: 231 | N6: 87758.69 | O6: 32081.85 | P6: 117775.9 | Q6: 237616.44 | R6: COM | S6: 98902 | T6: 4 | U6: 273.34 | V6: 239.01 | W6: 948.15 | X6: 1460.5 | Y6: 4 | Z6: 1497.65 | AA6: 86.13 | AB6: 222.72 | AC6: 1806.5 | AD6: 4 | AE6: 306.53 | AF6: 88.46 | AG6: 308.85 | AH6: 703.84 | AR6: COM | AS6: 98902 | AT6: =D6*1.6%+E6*6.3%+F6*28.9% -> 33865.204 | AU6: =I6*1.6%+J6*6.3%+K6*28.9% -> 33996.584 | AV6: =N6*1.6%+O6*6.3%+P6*28.9% -> 37462.531 | BJ6: 98902 | BK6: COM | BL6: 1 | BM6: 98902 | BN6: COM | BO6: 4 | BP6: 98902 | BQ6: COM | BR6: 1 | BS6: 98901RES | BT6: 40734.43 | BU6: 98901RES | BV6: 81570.47 | BW6: 98901RES | BX6: 41667.14 | BY6: 98901RES | BZ6: 1301.41 | CA6: 98901RES | CB6: 1645.55 | CC6: 98902RES | CD6: 1936.48
A7: COM | B7: 98903 | C7: 139 | D7: 14933.74 | E7: 22284.73 | F7: 155348.95 | G7: 192567.42 | H7: 100 | I7: 30267.37 | J7: 11192.05 | K7: 150206.92 | L7: 191666.34 | M7: 193 | N7: 117396.53 | O7: 9537.04 | P7: 126497.38 | Q7: 253430.95 | R7: COM | S7: 98903 | T7: 5 | U7: 308.48 | V7: 252.27 | W7: 1715.53 | X7: 2276.28 | Y7: 5 | Z7: 323.21 | AA7: 279.04 | AB7: 884.84 | AC7: 1487.09 | AD7: 5 | AE7: 316.25 | AF7: 215.73 | AG7: 1170.82 | AH7: 1702.8 | AR7: COM | AS7: 98903 | AT7: =D7*1.6%+E7*6.3%+F7*28.9% -> 46538.724 | AU7: =I7*1.6%+J7*6.3%+K7*28.9% -> 44599.177 | AV7: =N7*1.6%+O7*6.3%+P7*28.9% -> 39036.921 | BJ7: 98903 | BK7: COM | BL7: 2 | BM7: 98903 | BN7: COM | BO7: 1 | BP7: 98951 | BQ7: COM | BR7: 1 | BS7: 98902COM | BT7: 16571.43 | BU7: 98902COM | BV7: 43337.6 | BW7: 98902COM | BX7: 109.28 | BY7: 98902RES | BZ7: 4070.94 | CA7: 98902RES | CB7: 747.66 | CC7: 98903RES | CD7: 104.49
A8: COM | B8: 98904 | D8: 0 | E8: 0 | F8: 0 | G8: 0 | I8: 0 | J8: 0 | K8: 0 | L8: 0 | N8: 0 | O8: 0 | P8: 0 | Q8: 0 | R8: COM | S8: 98908 | T8: 6 | U8: 356.95 | V8: 309.87 | W8: 1737.83 | X8: 2404.65 | Y8: 7 | Z8: 460.79 | AA8: 409.61 | AB8: 1838.73 | AC8: 2709.13 | AD8: 7 | AE8: 509.45 | AF8: 308.3 | AG8: 2225.35 | AH8: 3043.1 | AR8: COM | AS8: 98904 | AT8: =D8*1.6%+E8*6.3%+F8*28.9% -> 0 | AU8: =I8*1.6%+J8*6.3%+K8*28.9% -> 0 | AV8: =N8*1.6%+O8*6.3%+P8*28.9% -> 0 | BJ8: 98936 | BK8: COM | BL8: 1 | BM8: 98908 | BN8: COM | BO8: 1 | BP8: 99328 | BQ8: COM | BR8: 1 | BS8: 98902RES | BT8: 97412.08 | BU8: 98902RES | BV8: 102992.75 | BW8: 98902RES | BX8: 71143.46 | BY8: 98903RES | BZ8: 1284.52 | CA8: 98903RES | CB8: 519.1 | CC8: 98908RES | CD8: 123.99
A9: COM | B9: 98907 | D9: 0 | E9: 0 | F9: 0 | G9: 0 | I9: 0 | J9: 0 | K9: 0 | L9: 0 | N9: 0 | O9: 0 | P9: 0 | Q9: 0 | R9: COM | S9: 98930 | U9: 0 | V9: 0 | W9: 0 | X9: 0 | Y9: 1 | Z9: 11.71 | AA9: 0 | AB9: 0 | AC9: 11.71 | AR9: COM | AS9: 98907 | AT9: =D9*1.6%+E9*6.3%+F9*28.9% -> 0 | AU9: =I9*1.6%+J9*6.3%+K9*28.9% -> 0 | AV9: =N9*1.6%+O9*6.3%+P9*28.9% -> 0 | BJ9: 98937 | BK9: COM | BL9: 1 | BM9: 98942 | BN9: COM | BO9: 1 | BP9: 99347 | BQ9: COM | BR9: 1 | BS9: 98903COM | BT9: 5802.3 | BU9: 98903COM | BV9: 3495.99 | BW9: 98903RES | BX9: 23058.6 | BY9: 98908RES | BZ9: 2014.83 | CA9: 98908RES | CB9: 1010.08 | CC9: 98930RES | CD9: 150.9
A10: COM | B10: 98908 | C10: 116 | D10: 37953.29 | E10: 9065.54 | F10: 27735.11 | G10: 74753.94 | H10: 137 | I10: 89937.53 | J10: 8484.55 | K10: 25456.59 | L10: 123878.67 | M10: 133 | N10: 50929.41 | O10: 13003.59 | P10: 24520.22 | Q10: 88453.22 | R10: COM | S10: 98932 | T10: 1 | U10: 14.74 | V10: 15.13 | W10: 143.46 | X10: 173.33 | Y10: 1 | Z10: 16.94 | AA10: 14.74 | AB10: 132.46 | AC10: 164.14 | AD10: 1 | AE10: 15.13 | AF10: 16.94 | AG10: 18.73 | AH10: 50.8 | AR10: COM | AS10: 98908 | AT10: =D10*1.6%+E10*6.3%+F10*28.9% -> 9193.8285 | AU10: =I10*1.6%+J10*6.3%+K10*28.9% -> 9330.4816 | AV10: =N10*1.6%+O10*6.3%+P10*28.9% -> 8720.4403 | BJ10: 98942 | BK10: COM | BL10: 1 | BM10: 98944 | BN10: COM | BO10: 1 | BP10: 99362 | BQ10: COM | BR10: 3 | BS10: 98903RES | BT10: 31989.74 | BU10: 98903RES | BV10: 120967.55 | BW10: 98908RES | BX10: 50024.74 | BY10: 98930RES | BZ10: 797.03 | CA10: 98930RES | CB10: 56.14 | CC10: 98935RES | CD10: 62.69
A11: COM | B11: 98920 | D11: 0 | E11: 0 | F11: 0 | G11: 0 | I11: 0 | J11: 0 | K11: 0 | L11: 0 | N11: 0 | O11: 0 | P11: 0 | Q11: 0 | R11: COM | S11: 98933 | U11: 0 | V11: 0 | W11: 0 | X11: 0 | Z11: 0 | AA11: 0 | AB11: 0 | AC11: 0 | AE11: 0 | AF11: 0 | AG11: 0 | AH11: 0 | AR11: COM | AS11: 98920 | AT11: =D11*1.6%+E11*6.3%+F11*28.9% -> 0 | AU11: =I11*1.6%+J11*6.3%+K11*28.9% -> 0 | AV11: =N11*1.6%+O11*6.3%+P11*28.9% -> 0 | BJ11: 98944 | BK11: COM | BL11: 1 | BM11: 98947 | BN11: COM | BO11: 1 | BP11: 98901 | BQ11: RES | BR11: 65 | BS11: 98908RES | BT11: 66317.97 | BU11: 98908COM | BV11: 1058.53 | BW11: 98930RES | BX11: 8543.94 | BY11: 98932RES | BZ11: 483.86 | CA11: 98932RES | CB11: 221.53 | CC11: 98942RES | CD11: 36.72
A12: COM | B12: 98921 | C12: 1 | D12: 13.7 | E12: 13.7 | F12: 95.9 | G12: 123.3 | H12: 2 | I12: 15417.72 | J12: 13.7 | K12: 109.6 | L12: 15541.02 | M12: 1 | N12: 13.7 | O12: 13.7 | P12: 123.3 | Q12: 150.7 | R12: COM | S12: 98936 | T12: 1 | U12: 37.76 | V12: 107.8 | W12: 0 | X12: 145.56 | Y12: 1 | Z12: 35.03 | AA12: 37.76 | AB12: 107.8 | AC12: 180.59 | AD12: 1 | AE12: 35.98 | AF12: 35.03 | AG12: 145.56 | AH12: 216.57 | AR12: COM | AS12: 98921 | AT12: =D12*1.6%+E12*6.3%+F12*28.9% -> 28.7974 | AU12: =I12*1.6%+J12*6.3%+K12*28.9% -> 279.22102 | AV12: =N12*1.6%+O12*6.3%+P12*28.9% -> 36.716 | BJ12: 98948 | BK12: COM | BL12: 2 | BM12: 98948 | BN12: COM | BO12: 3 | BP12: 98902 | BQ12: RES | BR12: 84 | BS12: 98921RES | BT12: 686.37 | BU12: 98908RES | BV12: 32146.85 | BW12: 98932RES | BX12: 2372.6 | BY12: 98933RES | BZ12: 165.2 | CA12: 98936RES | CB12: 439.98 | CC12: 98944RES | CD12: 551.43
A13: COM | B13: 98923 | C13: 8 | D13: 15294.03 | E13: 2332.86 | F13: 13466.93 | G13: 31093.82 | H13: 9 | I13: 14841.39 | J13: 2664.88 | K13: 12522.31 | L13: 30028.58 | M13: 7 | N13: 12941.62 | O13: 1596.24 | P13: 13632.73 | Q13: 28170.59 | R13: COM | S13: 98937 | T13: 1 | U13: 28.85 | V13: 24.87 | W13: 268.81 | X13: 322.53 | Y13: 1 | Z13: 36.4 | AA13: 28.85 | AB13: 293.68 | AC13: 358.93 | AD13: 1 | AE13: 43.14 | AF13: 36.4 | AG13: 322.53 | AH13: 402.07 | AR13: COM | AS13: 98923 | AT13: =D13*1.6%+E13*6.3%+F13*28.9% -> 4283.6174 | AU13: =I13*1.6%+J13*6.3%+K13*28.9% -> 4024.2973 | AV13: =N13*1.6%+O13*6.3%+P13*28.9% -> 4247.488 | BJ13: 98951 | BK13: COM | BL13: 3 | BM13: 99328 | BN13: COM | BO13: 1 | BP13: 98903 | BQ13: RES | BR13: 17 | BS13: 98923RES | BT13: 3597.58 | BU13: 98923RES | BV13: 1402.38 | BW13: 98933RES | BX13: 7983.59 | BY13: 98935RES | BZ13: 889.86 | CA13: 98937RES | CB13: 335.33 | CC13: 98948RES | CD13: 237.99
A14: COM | B14: 98930 | C14: 33 | D14: 6078.2 | E14: 4826.14 | F14: 30904.02 | G14: 41808.36 | H14: 33 | I14: 7600.99 | J14: 5123.68 | K14: 30835.44 | L14: 43560.11 | M14: 41 | N14: 19763.75 | O14: 2728.02 | P14: 29183.44 | Q14: 51675.21 | R14: COM | S14: 98938 | T14: 1 | U14: 85.86 | V14: 87.29 | W14: 971 | X14: 1144.15 | Y14: 2 | Z14: 156.5 | AA14: 85.86 | AB14: 1058.29 | AC14: 1300.65 | AD14: 1 | AE14: 87.04 | AF14: 66.17 | AG14: 1144.15 | AH14: 1297.36 | AR14: COM | AS14: 98930 | AT14: =D14*1.6%+E14*6.3%+F14*28.9% -> 9332.5598 | AU14: =I14*1.6%+J14*6.3%+K14*28.9% -> 9355.8498 | AV14: =N14*1.6%+O14*6.3%+P14*28.9% -> 8922.0994 | BJ14: 99328 | BK14: COM | BL14: 5 | BM14: 99362 | BN14: COM | BO14: 1 | BP14: 98908 | BQ14: RES | BR14: 37 | BS14: 98930RES | BT14: 10757.62 | BU14: 98930RES | BV14: 11499.35 | BW14: 98935RES | BX14: 752.65 | BY14: 98942RES | BZ14: 1394.99 | CA14: 98942RES | CB14: 1056.17 | CC14: 98951RES | CD14: 33.13
A15: COM | B15: 98932 | C15: 24 | D15: 8434.25 | E15: 2545.33 | F15: 16552.01 | G15: 27531.59 | H15: 26 | I15: 12078.76 | J15: 2582.38 | K15: 15803.65 | L15: 30464.79 | M15: 21 | N15: 34101.08 | O15: 14590.73 | P15: 15777.9 | Q15: 64469.71 | R15: COM | S15: 98939 | T15: 1 | U15: 509.46 | V15: 21.85 | W15: 119.35 | X15: 650.66 | Y15: 1 | Z15: 22 | AA15: 8.9 | AB15: 0 | AC15: 30.9 | AD15: 1 | AE15: 76.72 | AF15: 22 | AG15: 8.9 | AH15: 107.62 | AR15: COM | AS15: 98932 | AT15: =D15*1.6%+E15*6.3%+F15*28.9% -> 5078.8347 | AU15: =I15*1.6%+J15*6.3%+K15*28.9% -> 4923.2049 | AV15: =N15*1.6%+O15*6.3%+P15*28.9% -> 6024.6464 | BJ15: 99362 | BK15: COM | BL15: 1 | BM15: 98901 | BN15: RES | BO15: 54 | BP15: 98930 | BQ15: RES | BR15: 19 | BS15: 98932RES | BT15: 4828.32 | BU15: 98932RES | BV15: 1730.38 | BW15: 98936RES | BX15: 2995.38 | BY15: 98944RES | BZ15: 250.22 | CA15: 98944RES | CB15: 667.56 | CC15: 99324RES | CD15: 97.61
A16: COM | B16: 98933 | C16: 10 | D16: 2494.33 | E16: 1012.59 | F16: 2136.02 | G16: 5642.94 | H16: 11 | I16: 2946.1 | J16: 850.36 | K16: 1154.1 | L16: 4950.56 | M16: 12 | N16: 2797.21 | O16: 983.08 | P16: 1153.78 | Q16: 4934.07 | R16: COM | S16: 98942 | U16: 0 | V16: 0 | W16: 0 | X16: 0 | Z16: 0 | AA16: 0 | AB16: 0 | AC16: 0 | AE16: 0 | AF16: 0 | AG16: 0 | AH16: 0 | AR16: COM | AS16: 98933 | AT16: =D16*1.6%+E16*6.3%+F16*28.9% -> 721.01223 | AU16: =I16*1.6%+J16*6.3%+K16*28.9% -> 434.24518 | AV16: =N16*1.6%+O16*6.3%+P16*28.9% -> 440.13182 | BJ16: 98901 | BK16: RES | BL16: 43 | BM16: 98902 | BN16: RES | BO16: 63 | BP16: 98932 | BQ16: RES | BR16: 3 | BS16: 98933RES | BT16: 650.34 | BU16: 98933RES | BV16: 3128.92 | BW16: 98937RES | BX16: 1656.58 | BY16: 98948RES | BZ16: 152.65 | CA16: 98948RES | CB16: 405.27 | CC16: 99347RES | CD16: 326.42
A17: COM | B17: 98935 | C17: 7 | D17: 0 | E17: 480.9 | F17: 587.44 | G17: 1068.34 | H17: 8 | I17: 3904.55 | J17: 278.07 | K17: 71.9 | L17: 4254.52 | M17: 13 | N17: 7221.07 | O17: 0 | P17: 676.63 | Q17: 7897.7 | R17: COM | S17: 98944 | T17: 3 | U17: 650.6 | V17: 547.67 | W17: 22219.64 | X17: 23417.91 | Y17: 3 | Z17: 619.47 | AA17: 609.73 | AB17: 22767.31 | AC17: 23996.51 | AD17: 3 | AE17: 859.76 | AF17: 619.47 | AG17: 22875.54 | AH17: 24354.77 | AR17: COM | AS17: 98935 | AT17: =D17*1.6%+E17*6.3%+F17*28.9% -> 200.06686 | AU17: =I17*1.6%+J17*6.3%+K17*28.9% -> 100.77031 | AV17: =N17*1.6%+O17*6.3%+P17*28.9% -> 311.08319 | BJ17: 98902 | BK17: RES | BL17: 85 | BM17: 98903 | BN17: RES | BO17: 24 | BP17: 98933 | BQ17: RES | BR17: 3 | BS17: 98935RES | BT17: 1756.35 | BU17: 98936RES | BV17: 2847.11 | BW17: 98942RES | BX17: 36069.66 | BY17: 98951RES | BZ17: 153.5 | CA17: 98951RES | CB17: 131.65 | CC17: 99362COM | CD17: 3178.49
A18: COM | B18: 98936 | C18: 22 | D18: 4994.39 | E18: 1760.09 | F18: 17304.8 | G18: 24059.28 | H18: 21 | I18: 3447.19 | J18: 4084.09 | K18: 13849.47 | L18: 21380.75 | M18: 22 | N18: 9728.19 | O18: 1754.15 | P18: 15667.34 | Q18: 27149.68 | R18: COM | S18: 98947 | T18: 1 | U18: 42.33 | V18: 55.21 | W18: 0 | X18: 97.54 | Z18: 0 | AA18: 0 | AB18: 0 | AC18: 0 | AE18: 0 | AF18: 0 | AG18: 0 | AH18: 0 | AR18: COM | AS18: 98936 | AT18: =D18*1.6%+E18*6.3%+F18*28.9% -> 5191.8831 | AU18: =I18*1.6%+J18*6.3%+K18*28.9% -> 4314.9495 | AV18: =N18*1.6%+O18*6.3%+P18*28.9% -> 4794.0237 | BJ18: 98903 | BK18: RES | BL18: 18 | BM18: 98908 | BN18: RES | BO18: 44 | BP18: 98935 | BQ18: RES | BR18: 4 | BS18: 98936COM | BT18: 1445.29 | BU18: 98937RES | BV18: 4202.65 | BW18: 98944RES | BX18: 6514.1 | BY18: 99324RES | BZ18: 294.59 | CA18: 98953RES | CB18: 34.25 | CC18: 99362RES | CD18: 3871.47
A19: COM | B19: 98937 | C19: 25 | D19: 7287.07 | E19: 4856.71 | F19: 29434.02 | G19: 41577.8 | H19: 31 | I19: 22944.58 | J19: 4708.27 | K19: 31296.25 | L19: 58949.1 | M19: 28 | N19: 23480.04 | O19: 2860.44 | P19: 17955.52 | Q19: 44296 | R19: COM | S19: 98948 | T19: 9 | U19: 3976.71 | V19: 2494.41 | W19: 10820.2 | X19: 17291.32 | Y19: 8 | Z19: 0 | AA19: 3911.46 | AB19: 12242.74 | AC19: 16154.2 | AD19: 10 | AE19: 4452.82 | AF19: 4889.21 | AG19: 16154.2 | AH19: 25496.23 | AR19: COM | AS19: 98937 | AT19: =D19*1.6%+E19*6.3%+F19*28.9% -> 8928.9976 | AU19: =I19*1.6%+J19*6.3%+K19*28.9% -> 9708.3505 | AV19: =N19*1.6%+O19*6.3%+P19*28.9% -> 5745.0336 | BJ19: 98908 | BK19: RES | BL19: 46 | BM19: 98923 | BN19: RES | BO19: 2 | BP19: 98936 | BQ19: RES | BR19: 5 | BS19: 98936RES | BT19: 2145.05 | BU19: 98938RES | BV19: 18311.32 | BW19: 98947RES | BX19: 124.49 | BY19: 99328RES | BZ19: 357.05 | CA19: 99323RES | CB19: 79.64
A20: COM | B20: 98938 | C20: 19 | D20: 61067.37 | E20: 4221.54 | F20: 8501.43 | G20: 73790.34 | H20: 17 | I20: 39439.16 | J20: 30837.41 | K20: 11667.66 | L20: 81944.23 | M20: 19 | N20: 67634.04 | O20: 1486.44 | P20: 8229.13 | Q20: 77349.61 | R20: COM | S20: 98951 | T20: 2 | U20: 76.64 | V20: 51.41 | W20: 124.2 | X20: 252.25 | Y20: 3 | Z20: 178.19 | AA20: 76.64 | AB20: 175.61 | AC20: 430.44 | AD20: 3 | AE20: 141.28 | AF20: 83.71 | AG20: 190.7 | AH20: 415.69 | AR20: COM | AS20: 98938 | AT20: =D20*1.6%+E20*6.3%+F20*28.9% -> 3699.9482 | AU20: =I20*1.6%+J20*6.3%+K20*28.9% -> 5945.7371 | AV20: =N20*1.6%+O20*6.3%+P20*28.9% -> 3554.0089 | BJ20: 98921 | BK20: RES | BL20: 1 | BM20: 98930 | BN20: RES | BO20: 11 | BP20: 98937 | BQ20: RES | BR20: 3 | BS20: 98937COM | BT20: 17.42 | BU20: 98942COM | BV20: 18961.88 | BW20: 98948RES | BX20: 8551.77 | BY20: 99362COM | BZ20: 2352.5 | CA20: 99324RES | CB20: 316.18
A21: COM | B21: 98939 | C21: 2 | D21: 717.5 | E21: 176.72 | F21: 119.35 | G21: 1013.57 | H21: 2 | I21: 224.21 | J21: 216.94 | K21: 154.87 | L21: 596.02 | M21: 2 | N21: 268.62 | O21: 224.21 | P21: 371.81 | Q21: 864.64 | R21: COM | S21: 98952 | T21: 1 | U21: 89.54 | V21: 66.05 | W21: 0 | X21: 155.59 | Y21: 1 | Z21: 95.14 | AA21: 89.54 | AB21: 66.05 | AC21: 250.73 | AD21: 1 | AE21: 104.6 | AF21: 95.14 | AG21: 48.09 | AH21: 247.83 | AR21: COM | AS21: 98939 | AT21: =D21*1.6%+E21*6.3%+F21*28.9% -> 57.10551 | AU21: =I21*1.6%+J21*6.3%+K21*28.9% -> 62.01201 | AV21: =N21*1.6%+O21*6.3%+P21*28.9% -> 125.87624 | BJ21: 98923 | BK21: RES | BL21: 1 | BM21: 98932 | BN21: RES | BO21: 3 | BP21: 98942 | BQ21: RES | BR21: 17 | BS21: 98937RES | BT21: 1779.39 | BU21: 98942RES | BV21: 56427.81 | BW21: 98951COM | BX21: 430.9 | BY21: 99362RES | BZ21: 1693.87 | CA21: 99361RES | CB21: 84.98
A22: COM | B22: 98942 | C22: 59 | D22: 98891.39 | E22: 4903.02 | F22: 24819.88 | G22: 128614.29 | H22: 59 | I22: 70082.12 | J22: 4993.32 | K22: 20664.58 | L22: 95740.02 | M22: 70 | N22: 72079.13 | O22: 4833.23 | P22: 20619.88 | Q22: 97532.24 | R22: COM | S22: 98953 | T22: 4 | U22: 74.33 | V22: 130.2 | W22: 2609.18 | X22: 2813.71 | Y22: 3 | Z22: 88.64 | AA22: 74.16 | AB22: 2739.38 | AC22: 2902.18 | AD22: 3 | AE22: 74.18 | AF22: 88.64 | AG22: 2813.54 | AH22: 2976.36 | AR22: COM | AS22: 98942 | AT22: =D22*1.6%+E22*6.3%+F22*28.9% -> 9064.0978 | AU22: =I22*1.6%+J22*6.3%+K22*28.9% -> 7407.9567 | AV22: =N22*1.6%+O22*6.3%+P22*28.9% -> 7416.9049 | BJ22: 98930 | BK22: RES | BL22: 11 | BM22: 98933 | BN22: RES | BO22: 2 | BP22: 98944 | BQ22: RES | BR22: 18 | BS22: 98938RES | BT22: 21472.21 | BU22: 98944COM | BV22: 12921.82 | BW22: 98951RES | BX22: 20150.09 | CA22: 99362RES | CB22: 2300.95
