Workbook

Sheet 1. General 2024_Q1
A1: Count of aggreements by ZIP and CLASS.
A2: WA_TERM_COVID_COUNTS
A3: General 2024
A4: 45292 | D4: 45323 | G4: 45352 | K4: Retail Sales (kWh) | L4: July | M4: August | N4: September | O4: 45292 | P4: 45324 | Q4: 45354 | R4: July | S4: August | T4: September | U4: October | V4: November | W4: December | X4: Totals Q1
A5: Zip | B5: Class | C5: Count | D5: Zip | E5: Class | F5: Count | G5: Zip | H5: Class | I5: Count | K5: Residential | L5: 149454803 | M5: 144341255 | N5: 106642496 | O5: 210372218 | P5: 185759262 | Q5: 145770248 | X5: =SUM(O5:Q5) -> 541901728
A6: 98901 | B6: COM | C6: 2148 | D6: 98901 | E6: COM | F6: 2155 | G6: 98901 | H6: COM | I6: 2149 | K6: Commercial | L6: 140404042 | M6: 148198213 | N6: 131511808 | O6: 136370618 | P6: 125657389 | Q6: 120323998 | X6: =SUM(O6:Q6) -> 382352005
A7: 98902 | B7: COM | C7: 2583 | D7: 98902 | E7: COM | F7: 2579 | G7: 98902 | H7: COM | I7: 2586 | K7: Industrial | L7: 72533895 | M7: 71622459 | N7: 72818621 | O7: 97571126 | P7: 24268044 | Q7: 61864249 | X7: =SUM(O7:Q7) -> 183703419
A8: 98903 | B8: COM | C8: 1671 | D8: 98903 | E8: COM | F8: 1668 | G8: 98903 | H8: COM | I8: 1660 | K8: Irrigation | L8: 36860793 | M8: 39164393 | N8: 25760901 | O8: 503639 | P8: 634240 | Q8: 1931983 | X8: =SUM(O8:Q8) -> 3069862
A9: 98904 | B9: COM | C9: 2 | D9: 98904 | E9: COM | F9: 2 | G9: 98904 | H9: COM | I9: 2 | K9: Totals | L9: =SUM(L5:L8) -> 399253533 | M9: =SUM(M5:M8) -> 403326320 | N9: =SUM(N5:N8) -> 336733826 | O9: =SUM(O5:O8) -> 444817601 | P9: =SUM(P5:P8) -> 336318935 | Q9: =SUM(Q5:Q8) -> 329890478 | R9: =SUM(R5:R8) -> 0 | S9: =SUM(S5:S8) -> 0 | ... X9: =SUM(X5:X8) -> 1111027014
A10: 98907 | B10: COM | C10: 2 | D10: 98907 | E10: COM | F10: 2 | G10: 98907 | H10: COM | I10: 2
A11: 98908 | B11: COM | C11: 1607 | D11: 98908 | E11: COM | F11: 1601 | G11: 98908 | H11: COM | I11: 1615
A12: 98920 | B12: COM | C12: 4 | D12: 98920 | E12: COM | F12: 4 | G12: 98920 | H12: COM | I12: 4
A13: 98921 | B13: COM | C13: 27 | D13: 98921 | E13: COM | F13: 26 | G13: 98921 | H13: COM | I13: 26
A14: 98923 | B14: COM | C14: 105 | D14: 98923 | E14: COM | F14: 106 | G14: 98923 | H14: COM | I14: 106
A15: 98930 | B15: COM | C15: 663 | D15: 98930 | E15: COM | F15: 660 | G15: 98930 | H15: COM | I15: 664
A16: 98932 | B16: COM | C16: 233 | D16: 98932 | E16: COM | F16: 230 | G16: 98932 | H16: COM | I16: 230
A17: 98933 | B17: COM | C17: 71 | D17: 98933 | E17: COM | F17: 72 | G17: 98933 | H17: COM | I17: 72
A18: 98935 | B18: COM | C18: 139 | D18: 98935 | E18: COM | F18: 142 | G18: 98935 | H18: COM | I18: 140
A19: 98936 | B19: COM | C19: 344 | D19: 98936 | E19: COM | F19: 345 | G19: 98936 | H19: COM | I19: 345
A20: 98937 | B20: COM | C20: 400 | D20: 98937 | E20: COM | F20: 399 | G20: 98937 | H20: COM | I20: 403
A21: 98938 | B21: COM | C21: 158 | D21: 98938 | E21: COM | F21: 159 | G21: 98938 | H21: COM | I21: 158
... A41: 99363 | B41: COM | C41: 73 | D41: 99363 | E41: COM | F41: 73 | G41: 99363 | H41: COM | I41: 73
B42: COM | C42: 4 | E42: COM | F42: 4 | H42: COM | I42: 4
A43: 98901 | B43: IND | C43: 48 | D43: 98901 | E43: IND | F43: 48 | G43: 98901 | H43: IND | I43: 48
A44: 98902 | B44: IND | C44: 85 | D44: 98902 | E44: IND | F44: 85 | G44: 98902 | H44: IND | I44: 85
A45: 98903 | B45: IND | C45: 64 | D45: 98903 | E45: IND | F45: 64 | G45: 98903 | H45: IND | I45: 64
A46: 98908 | B46: IND | C46: 17 | D46: 98908 | E46: IND | F46: 17 | G46: 98908 | H46: IND | I46: 17
A47: 98921 | B47: IND | C47: 1 | D47: 98921 | E47: IND | F47: 1 | G47: 98921 | H47: IND | I47: 1
A48: 98923 | B48: IND | C48: 4 | D48: 98923 | E48: IND | F48: 4 | G48: 98923 | H48: IND | I48: 4
A49: 98930 | B49: IND | C49: 26 | D49: 98930 | E49: IND | F49: 26 | G49: 98930 | H49: IND | I49: 26
A50: 98932 | B50: IND | C50: 12 | D50: 98932 | E50: IND | F50: 12 | G50: 98932 | H50: IND | I50: 12
A51: 98933 | B51: IND | C51: 1 | D51: 98933 | E51: IND | F51: 1 | G51: 98933 | H51: IND | I51: 1
A52: 98935 | B52: IND | C52: 3 | D52: 98935 | E52: IND | F52: 3 | G52: 98935 | H52: IND | I52: 4
A53: 98936 | B53: IND | C53: 18 | D53: 98936 | E53: IND | F53: 18 | G53: 98936 | H53: IND | I53: 18
A54: 98937 | B54: IND | C54: 11 | D54: 98937 | E54: IND | F54: 11 | G54: 98937 | H54: IND | I54: 11
... A144: 99363 | B144: RES | C144: 72 | D144: 99363 | E144: RES | F144: 74 | G144: 99363 | H144: RES | I144: 72

Sheet 2. Disconnections 2024_Q1
A1: General 2024 | D1: Item a) Number of Disconnections by Customer Class per Month | N1: Item b) Avg. Duration of Disconnection by Customer Class (in Hours for recon 10 days or less) | X1: Item c) Number of Customers by Customer Class Receiving Disconnection Notices | AC1: Item d) Number of Customers by Customer Class Who Absent the Disconnection Moratorium Would Have Been Disconnected
D2: Zip Code | E2: Customer Class | F2: 45292 | G2: Zip Code | H2: Customer Class | I2: 45323 | J2: Zip Code | K2: Customer Class | L2: 45352 | N2: ZIP | O2: REV | P2: 45292 | Q2: ZIP | R2: REV | S2: 45323 | T2: ZIP | U2: REV | V2: 45352 | X2: Category | Y2: 45292 | Z2: 45323 | AA2: 45352 | AC2: Category | AD2: 45292 | AE2: 45323 | AF2: 45352
D3: 98901 | E3: RES | F3: 3 | G3: 98901 | H3: RES | I3: 1 | J3: 98901 | K3: RES | L3: 7 | N3: RES | O3: 98903 | P3: 1.3854167 | Q3: RES | R3: 98908 | S3: 0.24791667 | T3: RES | U3: 98901 | V3: 0.86493056 | X3: FFN | Y3: 7051 | Z3: 7345 | AA3: 7751
D4: 98902 | E4: RES | F4: 3 | G4: 98908 | H4: RES | I4: 2 | J4: 98902 | K4: RES | L4: 32 | N4: RES | O4: 99328 | P4: 2.1284722 | Q4: RES | R4: 99323 | S4: 0.51909722 | T4: RES | U4: 98902 | V4: 0.59502315 | X4: FNL | Y4: 11288 | Z4: 11763 | AA4: 11866
D5: 98903 | E5: COM | F5: 1 | G5: 98932 | H5: RES | I5: 2 | J5: 98903 | K5: RES | L5: 14 | N5: RES | O5: 99362 | P5: 0.73414352 | Q5: RES | R5: 99324 | S5: 1.4166667 | T5: RES | U5: 98903 | V5: 0.50677083 | X5: PDN | Y5: 13846 | Z5: 14638 | AA5: 14591
D6: 98903 | E6: RES | F6: 10 | G6: 98951 | H6: COM | I6: 1 | J6: 98908 | K6: COM | L6: 1 | Q6: RES | R6: 99328 | S6: 0.62222222 | T6: RES | U6: 98908 | V6: 2.0520833
D7: 98948 | E7: RES | F7: 2 | G7: 98951 | H7: IRG | I7: 1 | J7: 98908 | K7: RES | L7: 4 | Q7: RES | R7: 99360 | S7: 0.86388889 | T7: RES | U7: 98921 | V7: 0.099305556
D8: 99328 | E8: RES | F8: 2 | G8: 98951 | H8: RES | I8: 4 | J8: 98921 | K8: RES | L8: 2 | Q8: RES | R8: 99362 | S8: 1.0440972 | T8: RES | U8: 98944 | V8: 1.1159722
D9: 99362 | E9: RES | F9: 17 | G9: 99323 | H9: RES | I9: 3 | J9: 98930 | K9: RES | L9: 1 | T9: RES | U9: 98948 | V9: 0.35972222
G10: 99324 | H10: RES | I10: 2 | J10: 98942 | K10: RES | L10: 1 | T10: RES | U10: 98951 | V10: 0.13333333
G11: 99328 | H11: RES | I11: 4 | J11: 98944 | K11: RES | L11: 3 | T11: RES | U11: 99324 | V11: 1.1138889
G12: 99360 | H12: RES | I12: 2 | J12: 98948 | K12: RES | L12: 3 | T12: RES | U12: 99362 | V12: 0.74583333
G13: 99362 | H13: RES | I13: 5 | J13: 98951 | K13: RES | L13: 1
G14: 99363 | H14: RES | I14: 1 | J14: 99324 | K14: RES | L14: 5
J15: 99328 | K15: RES | L15: 3
J16: 99362 | K16: RES | L16: 4
D17: TOTAL | F17: =SUM(F3:F9) -> 38 | I17: =SUM(I3:I9) -> 14 | L17: =SUM(L3:L9) -> 61

Sheet 3. Fees 2024_Q1
A1: General 2024 | D1: Item a) Number of Customers by Customer Class Assessed Late Payment Fees | H1: Item a) Aggregate amount of Charged Late Payment Fees | L1: Item a) Number of Customers by Customer Class Assessed Disconnection Fees | P1: Item a) Aggregate amount of Charged Disconnection Fees | T1: Item a) Number of Customers by Customer Class Assessed Reconnection Fees | X1: Item a) Aggregate amount of Charged Reconnection Fees
A2: Zip Code | B2: Customer Class | D2: 45292 | E2: 45323 | F2: 45352 | H2: 45292 | I2: 45323 | J2: 45352 | L2: 45292 | M2: 45323 | N2: 45352 | P2: 45292 | Q2: 45323 | R2: 45352 | T2: 45292 | U2: 45323 | V2: 45352 | X2: 45292 | Y2: 45323 | Z2: 45352
A3: None
A4: Asked JH question

Sheet 4. Payment Arrangements 2024_Q1
A1: General 2024 | D1: Item a) Number of Customers by Customer Class Taking Service at the Beginning of Each Month with Existing Long Term Payment Agreements | H1: Item b) Number of Customers By Customer Class Completing Long-term Payment Agreements | L1: Item c) Number of Customers by Customer Class Enrolling in New Long-term Payment Agreements | P1: Item d) Number of Customers By Customer Class Renegotiating Long-term Payment Agreements
A2: Zip Code | B2: Customer Class | D2: 45292 | E2: 45323 | F2: 45352 | H2: 45292 | I2: 45323 | J2: 45352 | L2: 45292 | M2: 45323 | N2: 45352 | P2: 45292 | Q2: 45323 | R2: 45352
A3: NA | B3: COM | D3: 142 | E3: 170 | F3: 172 | H3: 19 | I3: 20 | J3: 33 | L3: 62 | M3: 54 | N3: 62 | P3: 0 | Q3: 0 | R3: 1
A4: NA | B4: RES | D4: 4276 | E4: 4296 | F4: 4442 | H4: 250 | I4: 209 | J4: 169 | L4: 991 | M4: 1144 | N4: 1187 | P4: 27 | Q4: 28 | R4: 33

Sheet 5. Medical Certificates 2024_Q1
A1: General 2023 | D1: Item a) Number of Customers Taking Service at the Beginning of Each Month Under Existing Medical Payment Arrangements | H1: Item b) Number of Customers Completing Medical Payment Arrangements Each Month | L1: Item c) Number of Customers Enrolling in New Medical Payment Arrangements Each Month | P1: Item d) Number of Customers Renegotiating Medical Payment Arrangements Each Month
A2: Zip Code | B2: Customer Class | D2: 45292 | E2: 45323 | F2: 45352 | H2: 45292 | I2: 45323 | J2: 45352 | L2: 45292 | M2: 45323 | N2: 45352 | P2: 44197 | Q2: 44228 | R2: 44256 | S2: 44287 | T2: 44317 | U2: 44348 | V2: 44378 | W2: 44409 | X2: 44440 | Y2: 45292 | Z2: 45323 | AA2: 45352
A3: NA | B3: RES | D3: 19 | E3: 16 | F3: 14 | H3: 0 | I3: 0 | J3: 0 | L3: 4 | M3: 5 | N3: 11 | P3: 0 | Q3: 0 | R3: 0 | S3: 0 | T3: 0 | U3: 0 | V3: 0 | W3: 0 | X3: 0 | Y3: 0 | Z3: 0 | AA3: 0

Sheet 6. Deposits 2024_Q1
A1: General 2024 | D1: Item a) Number of Customers by Customer Class with Required Deposits at the Beginning of Each Month | N1: Item b) Number of Customers by Customer Class Required to Submit New or Increased Deposits Each Month | AH1: Item c) Number of Customers by Customer Class Whose Deposits Were Reduced In Part or Foregone Each Month | AR1: Item d) Number of Customers by Customer Class whose Deposits were Returned in Full Each Month
D2: 45292 | G2: 45323 | J2: 45352 | N2: Zip Code | O2: Customer Class | P2: 44197 | Q2: 44228 | R2: 44256 | S2: Zip Code | T2: Customer Class | U2: 44287 | V2: 44317 | W2: 44348 | X2: 45292 | AA2: 45323 | AD2: 45352 | AH2: 44197 | AI2: 44228 | AJ2: 44256 | AK2: 44287 | AL2: 44317 | AM2: 44348 | AN2: 45292 | AO2: 45323 | AP2: 45352 | AR2: 45292 | AU2: 45323 | AX2: 45352
D3: ZIP | E3: CLASS | F3: Concat Agreement Number | G3: ZIP | H3: CLASS | I3: Concat Agreement Number | J3: ZIP | K3: CLASS | L3: Concat Agreement Number | N3: 98901 | O3: COM | P3: 4 | Q3: 1 | R3: 2 | S3: 98901 | T3: COM | U3: 1 | V3: 6 | X3: ZIP | Y3: CLASS | Z3: Concat Agreement Number | AA3: ZIP | AB3: CLASS | AC3: Concat Agreement Number | AD3: ZIP | AE3: CLASS | AF3: Concat Agreement Number | AR3: ZIP | AS3: CLASS | AT3: Concat Agreement Number | AU3: ZIP | AV3: CLASS | AW3: Concat Agreement Number | AX3: ZIP | AY3: CLASS | AZ3: Concat Agreement Number
D4: 98901 | E4: COM | F4: 64 | G4: 98901 | H4: COM | I4: 62 | J4: 98901 | K4: COM | L4: 61 | N4: 98901 | O4: RES | P4: 71 | Q4: 53 | R4: 58 | S4: 98901 | T4: RES | U4: 19 | V4: 17 | W4: 19 | X4: 98901 | Y4: COM | Z4: 7 | AA4: 98901 | AB4: COM | AC4: 2 | AD4: 98901 | AE4: COM | AF4: 9 | AR4: 98901 | AS4: COM | AT4: 8 | AU4: 98901 | AV4: COM | AW4: 3 | AX4: 98901 | AY4: COM | AZ4: 3
D5: 98901 | E5: RES | F5: 4 | G5: 98901 | H5: RES | I5: 4 | J5: 98901 | K5: RES | L5: 4 | N5: 98902 | O5: COM | Q5: 6 | R5: 3 | S5: 98902 | T5: COM | U5: 4 | V5: 12 | W5: 5 | X5: 98902 | Y5: COM | Z5: 14 | AA5: 98902 | AB5: COM | AC5: 11 | AD5: 98902 | AE5: COM | AF5: 10 | AR5: 98902 | AS5: COM | AT5: 4 | AU5: 98902 | AV5: COM | AW5: 2 | AX5: 98902 | AY5: COM | AZ5: 1
D6: 98902 | E6: COM | F6: 90 | G6: 98902 | H6: COM | I6: 101 | J6: 98902 | K6: COM | L6: 110 | N6: 98902 | O6: RES | P6: 103 | Q6: 75 | R6: 32 | S6: 98902 | T6: RES | U6: 48 | V6: 22 | W6: 19 | X6: 98903 | Y6: COM | Z6: 8 | AA6: 98903 | AB6: COM | AC6: 5 | AD6: 98903 | AE6: COM | AF6: 2 | AR6: 98902 | AS6: RES | AT6: 1 | AU6: 98903 | AV6: COM | AW6: 2 | AX6: 98903 | AY6: COM | AZ6: 3
D7: 98902 | E7: RES | F7: 1 | G7: 98903 | H7: COM | I7: 48 | J7: 98903 | K7: COM | L7: 50 | N7: 98903 | O7: COM | P7: 6 | R7: 1 | S7: 98903 | T7: COM | U7: 2 | V7: 3 | W7: 3 | X7: 98908 | Y7: COM | Z7: 6 | AA7: 98908 | AB7: COM | AC7: 5 | AD7: 98908 | AE7: COM | AF7: 6 | AR7: 98903 | AS7: COM | AT7: 4 | AU7: 98903 | AV7: RES | AW7: 1 | AX7: 98903 | AY7: RES | AZ7: 1
D8: 98903 | E8: COM | F8: 42 | G8: 98903 | H8: RES | I8: 4 | J8: 98903 | K8: RES | L8: 3 | N8: 98903 | O8: RES | P8: 17 | Q8: 16 | R8: 22 | S8: 98903 | T8: RES | U8: 5 | V8: 1 | W8: 6 | X8: 98930 | Y8: COM | Z8: 2 | AA8: 98923 | AB8: COM | AC8: 1 | AD8: 98921 | AE8: COM | AF8: 1 | AR8: 98908 | AS8: COM | AT8: 3 | AU8: 98908 | AV8: COM | AW8: 2 | AX8: 98908 | AY8: COM | AZ8: 3
D9: 98903 | E9: RES | F9: 4 | G9: 98908 | H9: COM | I9: 37 | J9: 98908 | K9: COM | L9: 40 | N9: 98908 | O9: COM | P9: 4 | Q9: 1 | R9: 2 | S9: 98908 | T9: COM | V9: 4 | W9: 2 | X9: 98932 | Y9: COM | Z9: 2 | AA9: 98930 | AB9: COM | AC9: 1 | AD9: 98923 | AE9: COM | AF9: 2 | AR9: 98908 | AS9: RES | AT9: 2 | AU9: 98930 | AV9: COM | AW9: 1 | AX9: 98933 | AY9: RES | AZ9: 1
D10: 98908 | E10: COM | F10: 34 | G10: 98908 | H10: RES | I10: 10 | J10: 98908 | K10: RES | L10: 10 | N10: 98908 | O10: RES | P10: 37 | Q10: 59 | R10: 47 | S10: 98908 | T10: RES | U10: 31 | V10: 18 | W10: 14 | X10: 98944 | Y10: COM | Z10: 3 | AA10: 98938 | AB10: COM | AC10: 1 | AD10: 98930 | AE10: COM | AF10: 2 | AR10: 98932 | AS10: COM | AT10: 1 | AU10: 98942 | AV10: COM | AW10: 1 | AX10: 98947 | AY10: COM | AZ10: 2
D11: 98908 | E11: RES | F11: 12 | G11: 98921 | H11: RES | I11: 1 | J11: 98921 | K11: RES | L11: 1 | N11: 98921 | O11: RES | P11: 2 | Q11: 1 | S11: 98921 | T11: RES | U11: 2 | X11: 98947 | Y11: COM | Z11: 1 | AA11: 98944 | AB11: COM | AC11: 8 | AD11: 98937 | AE11: COM | AF11: 1 | AR11: 98936 | AS11: COM | AT11: 4 | AU11: 98944 | AV11: COM | AW11: 2 | AX11: 98948 | AY11: COM | AZ11: 3
D12: 98921 | E12: RES | F12: 1 | G12: 98923 | H12: COM | I12: 1 | J12: 98923 | K12: COM | L12: 2 | N12: 98923 | O12: RES | P12: 3 | Q12: 1 | S12: 98923 | T12: RES | U12: 1 | X12: 98948 | Y12: COM | Z12: 4 | AA12: 98948 | AB12: COM | AC12: 2 | AD12: 98942 | AE12: COM | AF12: 2 | AR12: 98937 | AS12: COM | AT12: 2 | AU12: 98948 | AV12: COM | AW12: 2 | AX12: 98948 | AY12: RES | AZ12: 1
D13: 98923 | E13: COM | F13: 1 | G13: 98930 | H13: COM | I13: 16 | J13: 98930 | K13: COM | L13: 16 | N13: 98930 | O13: COM | P13: 2 | Q13: 2 | R13: 1 | S13: 98930 | T13: COM | V13: 2 | X13: 98951 | Y13: COM | Z13: 1 | AA13: 98951 | AB13: COM | AC13: 2 | AD13: 98944 | AE13: COM | AF13: 4 | AR13: 98942 | AS13: RES | AT13: 1 | AU13: 98951 | AV13: COM | AW13: 13 | AX13: 98951 | AY13: COM | AZ13: 2
D14: 98930 | E14: COM | F14: 14 | G14: 98930 | H14: RES | I14: 1 | J14: 98930 | K14: RES | L14: 1 | N14: 98930 | O14: RES | P14: 11 | Q14: 23 | R14: 21 | S14: 98930 | T14: RES | U14: 3 | V14: 2 | W14: 1 | X14: 98953 | Y14: COM | Z14: 4 | AA14: 98953 | AB14: COM | AC14: 1 | AD14: 98948 | AE14: COM | AF14: 4 | AR14: 98944 | AS14: COM | AT14: 1 | AU14: 98953 | AV14: COM | AW14: 1 | AX14: 98953 | AY14: COM | AZ14: 5
D15: 98930 | E15: RES | F15: 1 | G15: 98932 | H15: COM | I15: 4 | J15: 98932 | K15: COM | L15: 4 | N15: 98932 | O15: RES | P15: 5 | Q15: 4 | R15: 6 | S15: 98932 | T15: RES | V15: 3 | X15: 99324 | Y15: COM | Z15: 1 | AA15: 99328 | AB15: COM | AC15: 1 | AD15: 98951 | AE15: COM | AF15: 5 | AR15: 98948 | AS15: COM | AT15: 1 | AU15: 99347 | AV15: COM | AW15: 1 | AX15: 99360 | AY15: COM | AZ15: 1
D16: 98932 | E16: COM | F16: 2 | G16: 98933 | H16: COM | I16: 2 | J16: 98933 | K16: COM | L16: 2 | N16: 98933 | O16: RES | Q16: 1 | S16: 98933 | T16: RES | X16: 99328 | Y16: COM | Z16: 1 | AA16: 99329 | AB16: COM | AC16: 1 | AD16: 98953 | AE16: COM | AF16: 5 | AR16: 99347 | AS16: COM | AT16: 1 | AU16: 99360 | AV16: COM | AW16: 1 | AX16: 99362 | AY16: COM | AZ16: 9
D17: 98933 | E17: COM | F17: 2 | G17: 98933 | H17: RES | I17: 1 | J17: 98933 | K17: RES | L17: 1 | N17: 98935 | O17: COM | Q17: 4 | S17: 98935 | T17: COM | X17: 99362 | Y17: COM | Z17: 7 | AA17: 99360 | AB17: COM | AC17: 1 | AD17: 99347 | AE17: COM | AF17: 1 | AR17: 99362 | AS17: COM | AT17: 8 | AU17: 99362 | AV17: COM | AW17: 5
D18: 98933 | E18: RES | F18: 1 | G18: 98935 | H18: COM | I18: 10 | J18: 98935 | K18: COM | L18: 10 | N18: 98935 | O18: RES | P18: 6 | Q18: 9 | R18: 1 | S18: 98935 | T18: RES | U18: 2 | V18: 1 | AA18: 99362 | AB18: COM | AC18: 7 | AD18: 99360 | AE18: COM | AF18: 1
D19: 98935 | E19: COM | F19: 10 | G19: 98936 | H19: COM | I19: 8 | J19: 98936 | K19: COM | L19: 8 | N19: 98936 | O19: RES | P19: 2 | Q19: 6 | R19: 5 | S19: 98936 | T19: RES | AD19: 99361 | AE19: COM | AF19: 1
D20: 98936 | E20: COM | F20: 12 | G20: 98937 | H20: COM | I20: 9 | J20: 98937 | K20: COM | L20: 9 | N20: 98937 | O20: RES | P20: 5 | Q20: 2 | R20: 2 | S20: 98937 | T20: COM | U20: 1 | W20: 2 | AD20: 99362 | AE20: COM | AF20: 11
D21: 98937 | E21: COM | F21: 11 | G21: 98938 | H21: COM | I21: 1 | J21: 98938 | K21: COM | L21: 2 | N21: 98938 | O21: COM | P21: 1 | S21: 98937 | T21: RES | V21: 2
D22: 98938 | E22: COM | F22: 1 | G22: 98942 | H22: COM | I22: 14 | J22: 98942 | K22: COM | L22: 13 | N22: 98938 | O22: RES | P22: 7 | Q22: 2 | R22: 1 | S22: 98938 | T22: COM
D23: 98942 | E23: COM | F23: 14 | G23: 98944 | H23: COM | I23: 39 | J23: 98944 | K23: COM | L23: 45 | N23: 98939 | O23: RES | P23: 1 | S23: 98938 | T23: RES
D24: 98942 | E24: RES | F24: 1 | G24: 98944 | H24: RES | I24: 4 | J24: 98944 | K24: RES | L24: 4 | N24: 98942 | O24: COM | P24: 2 | Q24: 2 | S24: 98939 | T24: RES
D25: 98944 | E25: COM | F25: 37 | G25: 98947 | H25: COM | I25: 7 | J25: 98947 | K25: COM | L25: 7 | N25: 98942 | O25: RES | P25: 14 | Q25: 25 | R25: 25 | S25: 98942 | T25: COM | W25: 2
D26: 98944 | E26: RES | F26: 4 | G26: 98947 | H26: RES | I26: 1 | J26: 98947 | K26: RES | L26: 1 | N26: 98944 | O26: COM | P26: 4 | Q26: 1 | R26: 9 | S26: 98942 | T26: RES | U26: 7 | V26: 8 | W26: 6
D27: 98947 | E27: COM | F27: 6 | G27: 98948 | H27: COM | I27: 21 | J27: 98948 | K27: COM | L27: 21 | N27: 98944 | O27: RES | P27: 36 | Q27: 21 | R27: 7 | S27: 98944 | T27: COM | U27: 2 | V27: 3 | W27: 1
D28: 98947 | E28: RES | F28: 1 | G28: 98948 | H28: RES | I28: 3 | J28: 98948 | K28: RES | L28: 3 | N28: 98947 | O28: RES | P28: 3 | Q28: 5 | S28: 98944 | T28: RES | U28: 13 | V28: 7 | W28: 2
D29: 98948 | E29: COM | F29: 18 | G29: 98951 | H29: COM | I29: 43 | J29: 98951 | K29: COM | L29: 32 | N29: 98948 | O29: RES | P29: 20 | Q29: 16 | R29: 20 | S29: 98947 | T29: RES | U29: 4 | V29: 2
D30: 98948 | E30: RES | F30: 3 | G30: 98951 | H30: RES | I30: 2 | J30: 98951 | K30: RES | L30: 2 | N30: 98951 | O30: COM | R30: 1 | S30: 98948 | T30: COM | U30: 2 | V30: 5
D31: 98951 | E31: COM | F31: 42 | G31: 98952 | H31: COM | I31: 1 | J31: 98952 | K31: COM | L31: 1 | N31: 98951 | O31: RES | P31: 18 | Q31: 24 | R31: 13 | S31: 98948 | T31: RES | U31: 4 | V31: 3 | W31: 1
D32: 98951 | E32: RES | F32: 2 | G32: 98953 | H32: COM | I32: 18 | J32: 98953 | K32: COM | L32: 18 | N32: 98952 | O32: RES | Q32: 1 | R32: 2 | S32: 98951 | T32: COM | U32: 1 | V32: 8 | W32: 6
D33: 98952 | E33: COM | F33: 1 | G33: 98953 | H33: RES | I33: 2 | J33: 98953 | K33: RES | L33: 2 | N33: 98953 | O33: COM | R33: 1 | S33: 98951 | T33: RES | U33: 9 | V33: 2
D34: 98953 | E34: COM | F34: 14 | G34: 99323 | H34: COM | I34: 3 | J34: 99323 | K34: COM | L34: 3 | N34: 98953 | O34: RES | P34: 7 | Q34: 6 | R34: 9 | S34: 98952 | T34: RES | V34: 2
D35: 98953 | E35: RES | F35: 2 | G35: 99324 | H35: COM | I35: 3 | J35: 99324 | K35: COM | L35: 3 | N35: 99323 | O35: RES | Q35: 2 | R35: 3 | S35: 98953 | T35: COM | U35: 2
D36: 99323 | E36: COM | F36: 3 | G36: 99328 | H36: COM | I36: 9 | J36: 99328 | K36: COM | L36: 10 | N36: 99324 | O36: RES | P36: 14 | Q36: 8 | R36: 10 | S36: 98953 | T36: RES | U36: 5 | V36: 3
D37: 99324 | E37: COM | F37: 2 | G37: 99347 | H37: COM | I37: 2 | J37: 99329 | K37: COM | L37: 1 | N37: 99328 | O37: COM | R37: 1 | S37: 99323 | T37: COM | U37: 1
D38: 99328 | E38: COM | F38: 8 | G38: 99360 | H38: COM | I38: 8 | J38: 99347 | K38: COM | L38: 1 | N38: 99328 | O38: RES | P38: 7 | Q38: 9 | R38: 4 | S38: 99323 | T38: RES | U38: 2
D39: 99347 | E39: COM | F39: 3 | G39: 99361 | H39: COM | I39: 1 | J39: 99360 | K39: COM | L39: 8 | N39: 99347 | O39: RES | P39: 2 | Q39: 4 | R39: 4 | S39: 99324 | T39: RES | U39: 8 | W39: 7
D40: 99360 | E40: COM | F40: 8 | G40: 99362 | H40: COM | I40: 80 | J40: 99361 | K40: COM | L40: 1 | N40: 99360 | O40: COM | R40: 1 | S40: 99328 | T40: COM | U40: 1 | V40: 2
...

Sheet DEP_WKSHT
A1: Zip Code | B1: CLASS | C1: CountOfConcat Agreement Number | D1: MO | G1: Zip Code | H1: CLASS | I1: CountOfConcat Agreement Number | J1: YRMO | K1: Expr1 | Q1: Sum of CountOfConcat Agreement Number | S1: YRMO | X1: Zip Code | Y1: CLASS | Z1: CountOfConcat Agreement Number | AA1: SumOfAmount | AB1: YRMO | AD1: Sum of CountOfConcat Agreement Number | AF1: YRMO
A2: 98901 | B2: NDEP | C2: 78 | D2: 1 | E2: =VLOOKUP(A2,'6. Deposits 2024_Q1'!$A$3:$A$34,1,FALSE) -> #N/A | G2: 98901 | H2: NDEP | I2: 4 | J2: 202010 | K2: 0 | Q2: CLASS | R2: Zip Code | S2: 202010 | T2: 202011 | U2: 202012 | V2: 20209 | X2: 98901 | Y2: NDEP | Z2: 30 | AA2: 0 | AB2: 10 | AD2: CLASS | AE2: Zip Code | AF2: 10 | AG2: 11 | AH2: 12 | AI2: Grand Total
A3: 98902 | B3: NDEP | C3: 97 | D3: 1 | E3: =VLOOKUP(A3,'6. Deposits 2024_Q1'!$A$3:$A$34,1,FALSE) -> #N/A | G3: 98901 | H3: NDEP | I3: 9 | J3: 202011 | K3: 0 | Q3: NDEP | R3: 98901 | S3: 4 | T3: 9 | U3: 2 | V3: 6 | X3: 98901 | Y3: NDEP | Z3: 16 | AA3: 0 | AB3: 11 | AD3: NDEP | AE3: 98901 | AF3: 30 | AG3: 16 | AH3: 20 | AI3: 66
A4: 98903 | B4: NDEP | C4: 47 | D4: 1 | E4: =VLOOKUP(A4,'6. Deposits 2024_Q1'!$A$3:$A$34,1,FALSE) -> #N/A | G4: 98901 | H4: NDEP | I4: 2 | J4: 202012 | K4: 0 | Q4: NDEP | R4: 98902 | S4: 8 | T4: 2 | U4: 2 | V4: 5 | X4: 98901 | Y4: NDEP | Z4: 20 | AA4: 0 | AB4: 12 | AD4: NDEP | AE4: 98902 | AF4: 24 | AG4: 22 | AH4: 32 | AI4: 78
A5: 98908 | B5: NDEP | C5: 35 | D5: 1 | E5: =VLOOKUP(A5,'6. Deposits 2024_Q1'!$A$3:$A$34,1,FALSE) -> #N/A | G5: 98901 | H5: NDEP | I5: 6 | J5: 20209 | K5: 0 | Q5: NDEP | R5: 98903 | S5: 2 | T5: 2 | V5: 4 | X5: 98901 | Y5: RDEP | Z5: 344 | AA5: 0 | AB5: 10 | AD5: NDEP | AE5: 98903 | AF5: 12 | AG5: 6 | AH5: 8 | AI5: 26
A6: 98920 | B6: NDEP | C6: 2 | D6: 1 | E6: =VLOOKUP(A6,'6. Deposits 2024_Q1'!$A$3:$A$34,1,FALSE) -> #N/A | G6: 98901 | H6: RDEP | I6: 99 | J6: 202010 | K6: 0 | Q6: NDEP | R6: 98908 | T6: 5 | X6: 98901 | Y6: RDEP | Z6: 358 | AA6: 0 | AB6: 11 | AD6: NDEP | AE6: 98908 | AF6: 8 | AG6: 18 | AH6: 12 | AI6: 38
A7: 98921 | B7: NDEP | C7: 2 | D7: 1 | E7: =VLOOKUP(A7,'6. Deposits 2024_Q1'!$A$3:$A$34,1,FALSE) -> #N/A | G7: 98901 | H7: RDEP | I7: 70 | J7: 202011 | K7: 0 | Q7: NDEP | R7: 98930 | S7: 3 | X7: 98901 | Y7: RDEP | Z7: 398 | AA7: 0 | AB7: 12 | AD7: NDEP | AE7: 98920 | AH7: 2 | AI7: 2
A8: 98930 | B8: NDEP | C8: 24 | D8: 1 | E8: =VLOOKUP(A8,'6. Deposits 2024_Q1'!$A$3:$A$34,1,FALSE) -> #N/A | G8: 98901 | H8: RDEP | I8: 26 | J8: 202012 | K8: 0 | Q8: NDEP | R8: 98937 | T8: 3 | U8: 2 | X8: 98902 | Y8: NDEP | Z8: 24 | AA8: 0 | AB8: 10 | AD8: NDEP | AE8: 98930 | AF8: 8 | AG8: 8 | AH8: 4 | AI8: 20
A9: 98932 | B9: NDEP | C9: 7 | D9: 1 | E9: =VLOOKUP(A9,'6. Deposits 2024_Q1'!$A$3:$A$34,1,FALSE) -> #N/A | G9: 98901 | H9: RDEP | I9: 109 | J9: 20209 | K9: 0 | Q9: NDEP | R9: 98942 | S9: 2 | V9: 1 | X9: 98902 | Y9: NDEP | Z9: 22 | AA9: 0 | AB9: 11 | AD9: NDEP | AE9: 98932 | AF9: 2 | AI9: 2
A10: 98933 | B10: NDEP | C10: 3 | D10: 1 | E10: =VLOOKUP(A10,'6. Deposits 2024_Q1'!$A$3:$A$34,1,FALSE) -> #N/A | G10: 98902 | H10: NDEP | I10: 8 | J10: 202010 | K10: 0 | Q10: NDEP | R10: 98944 | S10: 17 | U10: 6 | V10: 2 | X10: 98902 | Y10: NDEP | Z10: 32 | AA10: 0 | AB10: 12 | AD10: NDEP | AE10: 98933 | AF10: 2 | AG10: 4 | AH10: 2 | AI10: 8
A11: 98935 | B11: NDEP | C11: 4 | D11: 1 | E11: =VLOOKUP(A11,'6. Deposits 2024_Q1'!$A$3:$A$34,1,FALSE) -> #N/A | G11: 98902 | H11: NDEP | I11: 2 | J11: 202011 | K11: 0 | Q11: NDEP | R11: 98948 | S11: 2 | X11: 98902 | Y11: RDEP | Z11: 502 | AA11: 0 | AB11: 10 | AD11: NDEP | AE11: 98935 | AF11: 4 | AI11: 4
A12: 98936 | B12: NDEP | C12: 21 | D12: 1 | E12: =VLOOKUP(A12,'6. Deposits 2024_Q1'!$A$3:$A$34,1,FALSE) -> #N/A | G12: 98902 | H12: NDEP | I12: 2 | J12: 202012 | K12: 0 | Q12: NDEP | R12: 98951 | S12: 2 | T12: 2 | U12: 2 | X12: 98902 | Y12: RDEP | Z12: 510 | AA12: 0 | AB12: 11 | AD12: NDEP | AE12: 98936 | AF12: 4 | AG12: 2 | AH12: 24 | AI12: 30
A13: 98937 | B13: NDEP | C13: 10 | D13: 1 | E13: =VLOOKUP(A13,'6. Deposits 2024_Q1'!$A$3:$A$34,1,FALSE) -> #N/A | G13: 98902 | H13: NDEP | I13: 5 | J13: 20209 | K13: 0 | Q13: NDEP | R13: 99324 | T13: 2 | X13: 98902 | Y13: RDEP | Z13: 784 | AA13: 0 | AB13: 12 | AD13: NDEP | AE13: 98937 | AG13: 6 | AH13: 2 | AI13: 8
A14: 98938 | B14: NDEP | C14: 1 | D14: 1 | E14: =VLOOKUP(A14,'6. Deposits 2024_Q1'!$A$3:$A$34,1,FALSE) -> #N/A | G14: 98902 | H14: RDEP | I14: 163 | J14: 202010 | K14: 0 | Q14: NDEP | R14: 99328 | V14: 1 | X14: 98903 | Y14: NDEP | Z14: 12 | AA14: 0 | AB14: 10 | AD14: NDEP | AE14: 98942 | AF14: 8 | AG14: 14 | AH14: 4 | AI14: 26
A15: 98942 | B15: NDEP | C15: 18 | D15: 1 | E15: =VLOOKUP(A15,'6. Deposits 2024_Q1'!$A$3:$A$34,1,FALSE) -> #N/A | G15: 98902 | H15: RDEP | I15: 98 | J15: 202011 | K15: 0 | Q15: NDEP | R15: 99347 | S15: 2 | T15: 2 | X15: 98903 | Y15: NDEP | Z15: 6 | AA15: 0 | AB15: 11 | AD15: NDEP | AE15: 98944 | AF15: 12 | AG15: 26 | AH15: 18 | AI15: 56
A16: 98944 | B16: NDEP | C16: 61 | D16: 1 | E16: =VLOOKUP(A16,'6. Deposits 2024_Q1'!$A$3:$A$34,1,FALSE) -> #N/A | G16: 98902 | H16: RDEP | I16: 53 | J16: 202012 | K16: 0 | Q16: NDEP | R16: 99360 | T16: 2 | X16: 98903 | Y16: NDEP | Z16: 8 | AA16: 0 | AB16: 12 | AD16: NDEP | AE16: 98948 | AF16: 6 | AG16: 2 | AH16: 10 | AI16: 18
A17: 98947 | B17: NDEP | C17: 1 | D17: 1 | E17: =VLOOKUP(A17,'6. Deposits 2024_Q1'!$A$3:$A$34,1,FALSE) -> #N/A | G17: 98902 | H17: RDEP | I17: 127 | J17: 20209 | K17: 0 | Q17: NDEP | R17: 99361 | S17: 2 | V17: 1 | X17: 98903 | Y17: RDEP | Z17: 130 | AA17: 0 | AB17: 10 | AD17: NDEP | AE17: 98951 | AF17: 2 | AG17: 4 | AH17: 16 | AI17: 22
A18: 98948 | B18: NDEP | C18: 29 | D18: 1 | E18: =VLOOKUP(A18,'6. Deposits 2024_Q1'!$A$3:$A$34,1,FALSE) -> #N/A | G18: 98903 | H18: NDEP | I18: 2 | J18: 202010 | K18: 0 | Q18: NDEP | R18: 99362 | S18: 4 | T18: 8 | U18: 3 | V18: 8 | X18: 98903 | Y18: RDEP | Z18: 84 | AA18: 0 | AB18: 11 | AD18: NDEP | AE18: 98952 | AH18: 4 | AI18: 4
A19: 98951 | B19: NDEP | C19: 36 | D19: 1 | E19: =VLOOKUP(A19,'6. Deposits 2024_Q1'!$A$3:$A$34,1,FALSE) -> #N/A | G19: 98903 | H19: NDEP | I19: 2 | J19: 202011 | K19: 0 | Q19: NDEP | R19: 99363 | S19: 1 | X19: 98903 | Y19: RDEP | Z19: 130 | AA19: 0 | AB19: 12 | AD19: NDEP | AE19: 98953 | AF19: 2 | AG19: 2 | AH19: 4 | AI19: 8
A20: 98952 | B20: NDEP | C20: 1 | D20: 1 | E20: =VLOOKUP(A20,'6. Deposits 2024_Q1'!$A$3:$A$34,1,FALSE) -> #N/A | G20: 98903 | H20: NDEP | I20: 4 | J20: 20209 | K20: 0 | Q20: RDEP | R20: 98901 | S20: 99 | T20: 70 | U20: 26 | V20: 109 | X20: 98908 | Y20: NDEP | Z20: 8 | AA20: 0 | AB20: 10 | AD20: NDEP | AE20: 99323 | AH20: 2 | AI20: 2
A21: 98953 | B21: NDEP | C21: 10 | D21: 1 | E21: =VLOOKUP(A21,'6. Deposits 2024_Q1'!$A$3:$A$34,1,FALSE) -> #N/A | G21: 98903 | H21: RDEP | I21: 27 | J21: 202010 | K21: 0 | Q21: RDEP | R21: 98902 | S21: 163 | T21: 98 | U21: 53 | V21: 127 | X21: 98908 | Y21: NDEP | Z21: 18 | AA21: 0 | AB21: 11 | AD21: NDEP | AE21: 99324 | AG21: 4 | AH21: 2 | AI21: 6
A22: 99323 | B22: NDEP | C22: 1 | D22: 1 | E22: =VLOOKUP(A22,'6. Deposits 2024_Q1'!$A$3:$A$34,1,FALSE) -> #N/A | G22: 98903 | H22: RDEP | I22: 5 | J22: 202011 | K22: 0 | Q22: RDEP | R22: 98903 | S22: 27 | T22: 5 | U22: 12 | V22: 26 | X22: 98908 | Y22: NDEP | Z22: 12 | AA22: 0 | AB22: 12 | AD22: NDEP | AE22: 99328 | AF22: 2 | AH22: 2 | AI22: 4
A23: 99324 | B23: NDEP | C23: 4 | D23: 1 | E23: =VLOOKUP(A23,'6. Deposits 2024_Q1'!$A$3:$A$34,1,FALSE) -> #N/A | G23: 98903 | H23: RDEP | I23: 12 | J23: 202012 | K23: 0 | Q23: RDEP | R23: 98908 | S23: 136 | T23: 107 | U23: 32 | V23: 123 | X23: 98908 | Y23: RDEP | Z23: 320 | AA23: 0 | AB23: 10 | AD23: NDEP | AE23: 99347 | AG23: 4 | AI23: 4
A24: 99328 | B24: NDEP | C24: 5 | D24: 1 | E24: =VLOOKUP(A24,'6. Deposits 2024_Q1'!$A$3:$A$34,1,FALSE) -> #N/A | G24: 98903 | H24: RDEP | I24: 26 | J24: 20209 | K24: 0 | Q24: RDEP | R24: 98921 | S24: 7 | T24: 4 | V24: 4 | X24: 98908 | Y24: RDEP | Z24: 450 | AA24: 0 | AB24: 11 | AD24: NDEP | AE24: 99360 | AG24: 4 | AH24: 2 | AI24: 6
A25: 99329 | B25: NDEP | C25: 1 | D25: 1 | E25: =VLOOKUP(A25,'6. Deposits 2024_Q1'!$A$3:$A$34,1,FALSE) -> #N/A | G25: 98908 | H25: NDEP | I25: 5 | J25: 202011 | K25: 0 | Q25: RDEP | R25: 98923 | S25: 3 | T25: 2 | U25: 1 | V25: 2 | X25: 98908 | Y25: RDEP | Z25: 350 | AA25: 0 | AB25: 12 | AD25: NDEP | AE25: 99361 | AH25: 6 | AI25: 6
A26: 99347 | B26: NDEP | C26: 3 | D26: 1 | E26: =VLOOKUP(A26,'6. Deposits 2024_Q1'!$A$3:$A$34,1,FALSE) -> #N/A | G26: 98908 | H26: RDEP | I26: 136 | J26: 202010 | K26: 0 | Q26: RDEP | R26: 98930 | S26: 29 | T26: 10 | U26: 18 | V26: 15 | X26: 98920 | Y26: NDEP | Z26: 2 | AA26: 0 | AB26: 12 | AD26: NDEP | AE26: 99362 | AF26: 18 | AG26: 20 | AH26: 16 | AI26: 54
A27: 99360 | B27: NDEP | C27: 3 | D27: 1 | E27: =VLOOKUP(A27,'6. Deposits 2024_Q1'!$A$3:$A$34,1,FALSE) -> #N/A | G27: 98908 | H27: RDEP | I27: 107 | J27: 202011 | K27: 0 | Q27: RDEP | R27: 98932 | S27: 7 | T27: 17 | U27: 8 | V27: 7 | X27: 98921 | Y27: RDEP | Z27: 6 | AA27: 0 | AB27: 10 | AD27: RDEP | AE27: 98901 | AF27: 344 | AG27: 358 | AH27: 398 | AI27: 1100
A28: 99361 | B28: NDEP | C28: 6 | D28: 1 | E28: =VLOOKUP(A28,'6. Deposits 2024_Q1'!$A$3:$A$34,1,FALSE) -> #N/A | G28: 98908 | H28: RDEP | I28: 32 | J28: 202012 | K28: 0 | Q28: RDEP | R28: 98933 | S28: 3 | T28: 3 | U28: 3 | V28: 1 | X28: 98921 | Y28: RDEP | Z28: 18 | AA28: 0 | AB28: 11 | AD28: RDEP | AE28: 98902 | AF28: 502 | AG28: 510 | AH28: 784 | AI28: 1796
A29: 99362 | B29: NDEP | C29: 62 | D29: 1 | E29: =VLOOKUP(A29,'6. Deposits 2024_Q1'!$A$3:$A$34,1,FALSE) -> #N/A | G29: 98908 | H29: RDEP | I29: 123 | J29: 20209 | K29: 0 | Q29: RDEP | R29: 98935 | S29: 5 | T29: 6 | U29: 2 | V29: 4 | X29: 98921 | Y29: RDEP | Z29: 14 | AA29: 0 | AB29: 12 | AD29: RDEP | AE29: 98903 | AF29: 130 | AG29: 84 | AH29: 130 | AI29: 344
A30: 99363 | B30: NDEP | C30: 1 | D30: 1 | E30: =VLOOKUP(A30,'6. Deposits 2024_Q1'!$A$3:$A$34,1,FALSE) -> #N/A | G30: 98921 | H30: RDEP | I30: 7 | J30: 202010 | K30: 0 | Q30: RDEP | R30: 98936 | S30: 6 | T30: 10 | U30: 6 | V30: 5 | X30: 98923 | Y30: RDEP | Z30: 4 | AA30: 0 | AB30: 10 | AD30: RDEP | AE30: 98908 | AF30: 320 | AG30: 450 | AH30: 350 | AI30: 1120
A31: 98901 | B31: RDEP | C31: 1427 | D31: 1 | E31: =VLOOKUP(A31,'6. Deposits 2024_Q1'!$A$35:$A$61,1,FALSE) -> #N/A | G31: 98921 | H31: RDEP | I31: 4 | J31: 202011 | K31: 0 | Q31: RDEP | R31: 98937 | S31: 9 | T31: 2 | U31: 3 | V31: 7 | X31: 98923 | Y31: RDEP | Z31: 4 | AA31: 0 | AB31: 11 | AD31: RDEP | AE31: 98921 | AF31: 6 | AG31: 18 | AH31: 14 | AI31: 38
A32: 98902 | B32: RDEP | C32: 1838 | D32: 1 | E32: =VLOOKUP(A32,'6. Deposits 2024_Q1'!$A$35:$A$61,1,FALSE) -> #N/A | G32: 98921 | H32: RDEP | I32: 4 | J32: 20209 | K32: 0 | Q32: RDEP | R32: 98938 | S32: 1 | U32: 4 | X32: 98923 | Y32: RDEP | Z32: 16 | AA32: 0 | AB32: 12 | AD32: RDEP | AE32: 98923 | AF32: 4 | AG32: 4 | AH32: 16 | AI32: 24
A33: 98903 | B33: RDEP | C33: 403 | D33: 1 | E33: =VLOOKUP(A33,'6. Deposits 2024_Q1'!$A$35:$A$61,1,FALSE) -> #N/A | G33: 98923 | H33: RDEP | I33: 3 | J33: 202010 | K33: 0 | Q33: RDEP | R33: 98939 | U33: 1 | X33: 98930 | Y33: NDEP | Z33: 8 | AA33: 0 | AB33: 10 | AD33: RDEP | AE33: 98930 | AF33: 90 | AG33: 74 | AH33: 120 | AI33: 284
A34: 98908 | B34: RDEP | C34: 1026 | D34: 1 | E34: =VLOOKUP(A34,'6. Deposits 2024_Q1'!$A$35:$A$61,1,FALSE) -> #N/A | G34: 98923 | H34: RDEP | I34: 2 | J34: 202011 | K34: 0 | Q34: RDEP | R34: 98942 | S34: 42 | T34: 27 | U34: 12 | V34: 36 | X34: 98930 | Y34: NDEP | Z34: 8 | AA34: 0 | AB34: 11 | AD34: RDEP | AE34: 98932 | AF34: 30 | AG34: 72 | AH34: 62 | AI34: 164
A35: 98921 | B35: RDEP | C35: 31 | D35: 1 | E35: =VLOOKUP(A35,'6. Deposits 2024_Q1'!$A$35:$A$61,1,FALSE) -> #N/A | G35: 98923 | H35: RDEP | I35: 1 | J35: 202012 | K35: 0 | Q35: RDEP | R35: 98944 | S35: 23 | T35: 30 | U35: 15 | V35: 31 | X35: 98930 | Y35: NDEP | Z35: 4 | AA35: 0 | AB35: 12 | AD35: RDEP | AE35: 98933 | AF35: 4 | AG35: 4 | AH35: 14 | AI35: 22
A36: 98923 | B36: RDEP | C36: 30 | D36: 1 | E36: =VLOOKUP(A36,'6. Deposits 2024_Q1'!$A$35:$A$61,1,FALSE) -> #N/A | G36: 98923 | H36: RDEP | I36: 2 | J36: 20209 | K36: 0 | Q36: RDEP | R36: 98947 | S36: 4 | T36: 2 | U36: 3 | V36: 1 | X36: 98930 | Y36: RDEP | Z36: 90 | AA36: 0 | AB36: 10 | AD36: RDEP | AE36: 98935 | AF36: 30 | AG36: 16 | AH36: 36 | AI36: 82
A37: 98930 | B37: RDEP | C37: 336 | D37: 1 | E37: =VLOOKUP(A37,'6. Deposits 2024_Q1'!$A$35:$A$61,1,FALSE) -> #N/A | G37: 98930 | H37: NDEP | I37: 3 | J37: 202010 | K37: 0 | Q37: RDEP | R37: 98948 | S37: 24 | T37: 4 | U37: 4 | V37: 10 | X37: 98930 | Y37: RDEP | Z37: 74 | AA37: 0 | AB37: 11 | AD37: RDEP | AE37: 98936 | AF37: 38 | AG37: 26 | AH37: 80 | AI37: 144
A38: 98932 | B38: RDEP | C38: 165 | D38: 1 | E38: =VLOOKUP(A38,'6. Deposits 2024_Q1'!$A$35:$A$61,1,FALSE) -> #N/A | G38: 98930 | H38: RDEP | I38: 29 | J38: 202010 | K38: 0 | Q38: RDEP | R38: 98951 | S38: 16 | T38: 12 | U38: 8 | V38: 10 | X38: 98930 | Y38: RDEP | Z38: 120 | AA38: 0 | AB38: 12 | AD38: RDEP | AE38: 98937 | AF38: 20 | AG38: 30 | AH38: 38 | AI38: 88
A39: 98933 | B39: RDEP | C39: 24 | D39: 1 | E39: =VLOOKUP(A39,'6. Deposits 2024_Q1'!$A$35:$A$61,1,FALSE) -> #N/A | G39: 98930 | H39: RDEP | I39: 10 | J39: 202011 | K39: 0 | Q39: RDEP | R39: 98952 | S39: 1 | U39: 1 | X39: 98932 | Y39: NDEP | Z39: 2 | AA39: 0 | AB39: 10 | AD39: RDEP | AE39: 98938 | AF39: 24 | AG39: 14 | AH39: 40 | AI39: 78
A40: 98935 | B40: RDEP | C40: 85 | D40: 1 | E40: =VLOOKUP(A40,'6. Deposits 2024_Q1'!$A$35:$A$61,1,FALSE) -> #N/A | G40: 98930 | H40: RDEP | I40: 18 | J40: 202012 | K40: 0 | Q40: RDEP | R40: 98953 | S40: 7 | T40: 9 | V40: 10 | X40: 98932 | Y40: RDEP | Z40: 30 | AA40: 0 | AB40: 10 | AD40: RDEP | AE40: 98939 | AF40: 4 | AG40: 4 | AH40: 2 | AI40: 10
...

Sheet 7. Bill Assistance 2024_Q1
A1: Item a) Number of Premises Receiving Bill Assistance or Enrolled in Any Other Assistance Program
A2: 44197 | B2: 44228 | C2: 44256 | D2: ZIP ** | E2: 44287 | F2: 44317 | G2: 44348 | H2: 44378 | I2: 44409 | J2: 44440 | K2: 44470 | L2: 44501 | M2: 44531 | N2: Zip Code | O2: 45292 | P2: Zip Code | Q2: 45323 | R2: Zip Code | S2: 45352
N3: 98901 | O3: 1263 | P3: 98901 | Q3: 1258 | R3: 98901 | S3: 1225
N4: 98902 | O4: 1762 | P4: 98902 | Q4: 1747 | R4: 98902 | S4: 1680
N5: 98903 | O5: 570 | P5: 98903 | Q5: 567 | R5: 98903 | S5: 547
N6: 98908 | O6: 607 | P6: 98908 | Q6: 604 | R6: 98908 | S6: 559
N7: 98921 | O7: 60 | P7: 98921 | Q7: 59 | R7: 98921 | S7: 59
N8: 98923 | O8: 35 | P8: 98923 | Q8: 35 | R8: 98923 | S8: 36
N9: 98930 | O9: 453 | P9: 98930 | Q9: 453 | R9: 98930 | S9: 463
N10: 98932 | O10: 228 | P10: 98932 | Q10: 226 | R10: 98932 | S10: 230
N11: 98933 | O11: 20 | P11: 98933 | Q11: 20 | R11: 98933 | S11: 22
N12: 98935 | O12: 135 | P12: 98935 | Q12: 133 | R12: 98935 | S12: 141
N13: 98936 | O13: 109 | P13: 98936 | Q13: 106 | R13: 98936 | S13: 96
N14: 98937 | O14: 46 | P14: 98937 | Q14: 46 | R14: 98937 | S14: 51
... N34: 99363 | O34: 3 | P34: 99363 | Q34: 4 | R34: 99363 | S34: 3
N35: TOTAL | O35: =SUM(O3:O34) -> 8701 | Q35: =SUM(Q3:Q34) -> 8655 | S35: =SUM(S3:S34) -> 8513

Sheet BA_WRKSHT
A1: FLAG | B1: SumOfJAN20 | C1: SumOfFEB20 | D1: SumOfMAR20 | E1: SumOfAPR20 | F1: SumOfMAY20 | G1: SumOfJUN20 | H1: SumOfJUL20 | I1: SumOfAUG20 | J1: SumOfSEP20 | K1: SumOfOCT20 | L1: SumOfNOV20 | M1: SumOfDEC20 | N1: SumOfJAN19 | O1: SumOfFEB19 | P1: SumOfMAR19 | Q1: SumOfAPR19 | R1: SumOfMAY19 | S1: SumOfJUN19 | T1: SumOfJUL19 | U1: SumOfAUG19 | V1: SumOfSEP19 | W1: SumOfOCT19 | X1: SumOfNOV19 | Y1: SumOfDEC19
A2: 98901RES | B2: 37 | C2: 35 | D2: 33 | E2: 31 | F2: 31 | G2: 31 | H2: 30 | I2: 27 | J2: 27 | K2: 27 | L2: 24 | M2: 24 | N2: 23 | O2: 28 | P2: 28 | Q2: 30 | R2: 32 | S2: 33 | T2: 33 | U2: 35 | V2: 36 | W2: 37 | X2: 38 | Y2: 39
A3: 98902RES | B3: 54 | C3: 51 | D3: 48 | E3: 46 | F3: 43 | G3: 41 | H3: 38 | I3: 34 | J3: 33 | K3: 29 | L3: 27 | M3: 24 | N3: 24 | O3: 31 | P3: 34 | Q3: 38 | R3: 39 | S3: 43 | T3: 45 | U3: 47 | V3: 48 | W3: 50 | X3: 51 | Y3: 53
A4: 98903RES | B4: 26 | C4: 26 | D4: 24 | E4: 24 | F4: 23 | G4: 21 | H4: 22 | I4: 23 | J4: 23 | K4: 22 | L4: 22 | M4: 21 | N4: 22 | O4: 23 | P4: 24 | Q4: 26 | R4: 26 | S4: 27 | T4: 26 | U4: 26 | V4: 25 | W4: 26 | X4: 26 | Y4: 26
A5: 98908RES | B5: 29 | C5: 29 | D5: 27 | E5: 27 | F5: 27 | G5: 26 | H5: 26 | I5: 25 | J5: 26 | K5: 26 | L5: 26 | M5: 23 | N5: 23 | O5: 26 | P5: 26 | Q5: 26 | R5: 25 | S5: 25 | T5: 25 | U5: 26 | V5: 27 | W5: 27 | X5: 26 | Y5: 28
A6: 98921RES | B6: 10 | C6: 10 | D6: 9 | E6: 9 | F6: 9 | G6: 10 | H6: 9 | I6: 9 | J6: 7 | K6: 7 | L6: 7 | M6: 7 | N6: 12 | O6: 13 | P6: 12 | Q6: 12 | R6: 12 | S6: 11 | T6: 11 | U6: 10 | V6: 10 | W6: 10 | X6: 10 | Y6: 10
A7: 98923RES | B7: 3 | C7: 4 | D7: 3 | E7: 4 | F7: 3 | G7: 3 | H7: 4 | I7: 3 | J7: 4 | K7: 3 | L7: 4 | M7: 4 | N7: 4 | O7: 4 | P7: 5 | Q7: 4 | R7: 4 | S7: 5 | T7: 4 | U7: 4 | V7: 5 | W7: 5 | X7: 4 | Y7: 4
A8: 98930RES | B8: 33 | C8: 32 | D8: 32 | E8: 32 | F8: 30 | G8: 29 | H8: 28 | I8: 28 | J8: 28 | K8: 24 | L8: 21 | M8: 20 | N8: 21 | O8: 22 | P8: 25 | Q8: 25 | R8: 26 | S8: 27 | T8: 28 | U8: 28 | V8: 32 | W8: 31 | X8: 32 | Y8: 32
A9: 98932RES | B9: 21 | C9: 20 | D9: 21 | E9: 22 | F9: 21 | G9: 18 | H9: 18 | I9: 18 | J9: 17 | K9: 16 | L9: 15 | M9: 14 | N9: 16 | O9: 17 | P9: 17 | Q9: 17 | R9: 17 | S9: 19 | T9: 19 | U9: 20 | V9: 19 | W9: 20 | X9: 21 | Y9: 21
A10: 98933RES | B10: 4 | C10: 4 | D10: 4 | E10: 4 | F10: 4 | G10: 4 | H10: 4 | I10: 3 | J10: 2 | K10: 2 | L10: 2 | M10: 3 | N10: 2 | O10: 3 | P10: 3 | Q10: 3 | R10: 2 | S10: 3 | T10: 1 | U10: 1 | V10: 1 | W10: 2 | X10: 3 | Y10: 3
A11: 98935RES | B11: 12 | C11: 12 | D11: 12 | E11: 12 | F11: 12 | G11: 11 | H11: 10 | I11: 10 | J11: 10 | K11: 10 | L11: 10 | M11: 8 | N11: 9 | O11: 10 | P11: 10 | Q11: 9 | R11: 10 | S11: 11 | T11: 11 | U11: 10 | V11: 10 | W11: 12 | X11: 12 | Y11: 12
A12: 98936RES | B12: 8 | C12: 8 | D12: 7 | E12: 8 | F12: 7 | G12: 8 | H12: 8 | I12: 8 | J12: 8 | K12: 10 | L12: 10 | M12: 9 | N12: 7 | O12: 7 | P12: 7 | Q12: 7 | R12: 6 | S12: 6 | T12: 6 | U12: 5 | V12: 5 | W12: 7 | X12: 6 | Y12: 8
A13: 98937RES | B13: 9 | C13: 10 | D13: 9 | E13: 9 | F13: 8 | G13: 10 | H13: 10 | I13: 9 | J13: 10 | K13: 9 | L13: 9 | M13: 9 | N13: 7 | O13: 7 | P13: 7 | Q13: 7 | R13: 8 | S13: 8 | T13: 7 | U13: 7 | V13: 7 | W13: 9 | X13: 8 | Y13: 9
... A33: 99363RES | B33: 3 | C33: 2 | D33: 2 | E33: 2 | F33: 2 | G33: 2 | H33: 2 | I33: 1 | J33: 2 | K33: 1 | L33: 1 | M33: 1 | N33: 2 | O33: 2 | P33: 2 | Q33: 3 | R33: 2 | S33: 2 | T33: 2 | U33: 2 | V33: 2 | W33: 2 | X33: 2 | Y33: 3

Sheet 8.ARREARS NEW 2024_Q1
A1: Item a) Number of Customers by Customer Class With Past-due balances (arrearages) | R1: Item c) Amount of Past-due Balances for Known Low-income Households and Number of Days Past-due | AR1: Section D. Bad Debt | AW1: Item e) The Amount of Past-due Balances Written-off and Classified as Bad Debt, if different than item d | BJ1: Item f) Number of Customer Accounts Referred to Collection Agencies | BS1: Item f) Total Amount of Bad Debt Referred for Collection | BY1: Item f) Total Revenue to the Company from the Collection Process
A3: 202401 | H3: 202402 | O3: 202403 | R3: 202401 | Y3: 202402 | AD3: 202403 | AR3: 202401 | AU3: 202402 | AV3: 202403 | AW3: Class | AX3: 202101 | AY3: 202102 | AZ3: 202103 | BA3: 202104 | BB3: 202105 | BC3: 202106 | BD3: 202107 | BE3: 202108 | BF3: 202109 | BG3: 202401 | BH3: 202402 | BI3: 202403 | BJ3: 202401 | BM3: 202402 | BP3: 202403 | BS3: 202401 | BU3: 202402 | BW3: 202403 | BY3: 202401 | CA3: 202402 | CC3: 202403
A4: CLASS | B4: ZIP | C4: COUNT | D4: DAYS 31 60 | E4: DAYS 61 90 | F4: DAYS 91+ | G4: ARREARS | H4: COUNT | I4: DAYS 31 60 | J4: DAYS 61 90 | K4: DAYS 91+ | L4: ARREARS | M4: COUNT | N4: DAYS 31 60 | O4: DAYS 61 90 | P4: DAYS 91+ | Q4: ARREARS | R4: CLASS | S4: ZIP | T4: COUNT | U4: DAYS 31 60 | V4: DAYS 61 90 | W4: DAYS 91+ | X4: ARREARS | Y4: COUNT | Z4: DAYS 31 60 | AA4: DAYS 61 90 | AB4: DAYS 91+ | AC4: ARREARS | AD4: COUNT | AE4: DAYS 31 60 | AF4: DAYS 61 90 | AG4: DAYS 91+ | AH4: ARREARS | AR4: CLASS | AS4: ZIP | AT4: BAD DEBT | AU4: BAD DEBT | AV4: BAD DEBT | AW4: RES | AX4: 78547.88 | AY4: 83507.78 | AZ4: 74673.15 | BA4: 63441.04 | BB4: 64476.9 | BC4: 57542.34 | BD4: 83815.89 | BE4: 81559.71 | BF4: 121882.53 | BG4: 332931.22 | BH4: 521109.71 | BI4: 529713.15 | BJ4: ZIP | BK4: CLASS | BL4: Count | BM4: ZIP | BN4: CLASS | BO4: Count | BP4: ZIP | BQ4: CLASS | BR4: Count | BS4: FLAG | BT4: SumOfSumOfAccount Collection Amount | BU4: FLAG | BV4: SumOfSumOfAccount Collection Amount | BW4: FLAG | BX4: SumOfSumOfAccount Collection Amount | BY4: FLAG | BZ4: SumOfPaid Amount | CA4: FLAG | CB4: SumOfPaid Amount | CC4: FLAG | CD4: SumOfPaid Amount
A5: COM | B5: 98901 | C5: 131 | D5: 69568.04 | E5: 16310.36 | F5: 119403.81 | G5: 205282.21 | H5: 123 | I5: 34900.54 | J5: 21242.23 | K5: 85977.31 | L5: 142120.08 | M5: 142 | N5: 81373.57 | O5: 19757.51 | P5: 77773.65 | Q5: 178904.73 | R5: COM | S5: 98901 | T5: 5 | U5: 406.89 | V5: 224.2 | W5: 775.07 | X5: 1406.16 | Y5: 4 | Z5: 413.36 | AA5: 383.61 | AB5: 924.2 | AC5: 1721.17 | AD5: 4 | AE5: 390.84 | AF5: 395.42 | AG5: 1270.05 | AH5: 2056.31 | AR5: =A5 -> COM | AS5: =B5 -> 98901 | AT5: =D5*1.6%+E5*6.3%+F5*28.9% -> 36648.342 | AU5: =I5*1.6%+J5*6.3%+K5*28.9% -> 26744.112 | AV5: =N5*1.6%+O5*6.3%+P5*28.9% -> 25023.285 | AW5: COM | AX5: 35411.49 | AY5: 19861.99 | AZ5: 1614.2 | BA5: 209.93 | BB5: 2347.21 | BC5: 3702.39 | BD5: 16587.84 | BE5: 21717.76 | BF5: 41593.57 | BG5: 42414.62 | BH5: 14589.08 | BI5: 20749.08 | BJ5: 98901 | BK5: COM | BL5: 8 | BM5: 98901 | BN5: COM | BO5: 1 | BP5: 98901 | BQ5: RES | BR5: 65 | BS5: 98901COM | BT5: 27265.99 | BU5: 98901COM | BV5: 2903.22 | BW5: 98901RES | BX5: 48324.46 | BY5: 98901COM | BZ5: 2181.68 | CA5: 98901RES | CB5: 737.56 | CC5: 98901RES | CD5: 491.89
A6: COM | B6: 98902 | C6: 188 | D6: 55317.06 | E6: 20010.3 | F6: 104595.96 | G6: 179923.32 | H6: 227 | I6: 113297.04 | J6: 27278.76 | K6: 107772.19 | L6: 248347.99 | M6: 203 | N6: 68594.01 | O6: 37551.17 | P6: 99427.64 | Q6: 205572.82 | R6: COM | S6: 98902 | T6: 4 | U6: 307.69 | V6: 113.12 | W6: 377.64 | X6: 798.45 | Y6: 4 | Z6: 386.22 | AA6: 299.69 | AB6: 132.14 | AC6: 818.05 | AD6: 5 | AE6: 283.7 | AF6: 350.79 | AG6: 210.93 | AH6: 845.42 | AR6: =A6 -> COM | AS6: =B6 -> 98902 | AT6: =D6*1.6%+E6*6.3%+F6*28.9% -> 32373.954 | AU6: =I6*1.6%+J6*6.3%+K6*28.9% -> 34677.477 | AV6: =N6*1.6%+O6*6.3%+P6*28.9% -> 32197.816 | BJ6: 98901 | BK6: RES | BL6: 85 | BM6: 98901 | BN6: RES | BO6: 64 | BP6: 98902 | BQ6: COM | BR6: 6 | BS6: 98901RES | BT6: 63382.49 | BU6: 98901RES | BV6: 94219.05 | BW6: 98902COM | BX6: 6680.46 | BY6: 98901RES | BZ6: 2158.21 | CA6: 98902COM | CB6: 250.08 | CC6: 98902COM | CD6: 117.45
A7: COM | B7: 98903 | C7: 101 | D7: 24198.88 | E7: 4458.14 | F7: 156033.01 | G7: 184690.03 | H7: 133 | I7: 58387.8 | J7: 8750.71 | K7: 55105.97 | L7: 122244.48 | M7: 121 | N7: 30300.13 | O7: 12520.28 | P7: 55606.16 | Q7: 98426.57 | R7: COM | S7: 98903 | T7: 2 | U7: 353.36 | V7: 242.74 | W7: 72.28 | X7: 668.38 | Y7: 2 | Z7: 401.97 | AA7: 338.8 | AB7: 329.58 | AC7: 1070.35 | AD7: 3 | AE7: 302.08 | AF7: 387.68 | AG7: 668.38 | AH7: 1358.14 | AR7: =A7 -> COM | AS7: =B7 -> 98903 | AT7: =D7*1.6%+E7*6.3%+F7*28.9% -> 45761.585 | AU7: =I7*1.6%+J7*6.3%+K7*28.9% -> 17411.125 | AV7: =N7*1.6%+O7*6.3%+P7*28.9% -> 17343.76 | BJ7: 98902 | BK7: COM | BL7: 6 | BM7: 98902 | BN7: COM | BO7: 7 | BP7: 98902 | BQ7: RES | BR7: 85 | BS7: 98902COM | BT7: 1825.24 | BU7: 98902COM | BV7: 10207.93 | BW7: 98902RES | BX7: 63250.47 | BY7: 98902COM | BZ7: 169.26 | CA7: 98902RES | CB7: 2986.94 | CC7: 98902RES | CD7: 2475.53
A8: COM | B8: 98904 | D8: 0 | E8: 0 | F8: 0 | G8: 0 | I8: 0 | J8: 0 | K8: 0 | L8: 0 | N8: 0 | O8: 0 | P8: 0 | Q8: 0 | R8: COM | S8: 98908 | T8: 4 | U8: 664.49 | V8: 507.45 | W8: 2804.53 | X8: 3976.47 | Y8: 5 | Z8: 1128.12 | AA8: 626.93 | AB8: 3311.98 | AC8: 5067.03 | AD8: 6 | AE8: 982.22 | AF8: 766.41 | AG8: 3938.91 | AH8: 5687.54 | AR8: =A8 -> COM | AS8: =B8 -> 98904 | AT8: =D8*1.6%+E8*6.3%+F8*28.9% -> 0 | AU8: =I8*1.6%+J8*6.3%+K8*28.9% -> 0 | AV8: =N8*1.6%+O8*6.3%+P8*28.9% -> 0 | BJ8: 98902 | BK8: RES | BL8: 110 | BM8: 98902 | BN8: RES | BO8: 74 | BP8: 98903 | BQ8: RES | BR8: 23 | BS8: 98902RES | BT8: 86277.4 | BU8: 98902RES | BV8: 46488.75 | BW8: 98903RES | BX8: 60814.18 | BY8: 98902RES | BZ8: 908.07 | CA8: 98903RES | CB8: 1759.29 | CC8: 98903RES | CD8: 339.94
A9: COM | B9: 98907 | D9: 0 | E9: 0 | F9: 0 | G9: 0 | I9: 0 | J9: 0 | K9: 0 | L9: 0 | N9: 0 | O9: 0 | P9: 0 | Q9: 0 | R9: COM | S9: 98930 | U9: 0 | V9: 0 | W9: 0 | X9: 0 | Y9: 1 | Z9: 21.22 | AA9: 0 | AB9: 0 | AC9: 21.22 | AR9: =A9 -> COM | AS9: =B9 -> 98907 | AT9: =D9*1.6%+E9*6.3%+F9*28.9% -> 0 | AU9: =I9*1.6%+J9*6.3%+K9*28.9% -> 0 | AV9: =N9*1.6%+O9*6.3%+P9*28.9% -> 0 | BJ9: 98903 | BK9: COM | BL9: 2 | BM9: 98903 | BN9: COM | BO9: 2 | BP9: 98908 | BQ9: RES | BR9: 44 | BS9: 98903COM | BT9: 1797.35 | BU9: 98903COM | BV9: 2127.82 | BW9: 98908RES | BX9: 25083.52 | BY9: 98903COM | BZ9: 1703.32 | CA9: 98908RES | CB9: 895.95 | CC9: 98908RES | CD9: 1187.01
A10: COM | B10: 98908 | C10: 128 | D10: 37174.41 | E10: 9264.09 | F10: 35610.03 | G10: 82048.53 | H10: 133 | I10: 49700.56 | J10: 11002.22 | K10: 38652.13 | L10: 99354.91 | M10: 131 | N10: 40502.57 | O10: 20698.55 | P10: 41216.81 | Q10: 102417.93 | R10: COM | S10: 98932 | T10: 1 | U10: 14.21 | V10: 0 | W10: 0 | X10: 14.21 | Y10: 1 | Z10: 14.46 | AA10: 0 | AB10: 0 | AC10: 14.46 | AD10: 1 | AE10: 14.85 | AF10: 0 | AG10: 0 | AH10: 14.85 | AR10: =A10 -> COM | AS10: =B10 -> 98908 | AT10: =D10*1.6%+E10*6.3%+F10*28.9% -> 11469.727 | AU10: =I10*1.6%+J10*6.3%+K10*28.9% -> 12658.814 | AV10: =N10*1.6%+O10*6.3%+P10*28.9% -> 13863.708 | BJ10: 98903 | BK10: RES | BL10: 26 | BM10: 98903 | BN10: RES | BO10: 23 | BP10: 98921 | BQ10: RES | BR10: 1 | BS10: 98903RES | BT10: 41341.98 | BU10: 98903RES | BV10: 28063.01 | BW10: 98921RES | BX10: 87.64 | BY10: 98903RES | BZ10: 321.66 | CA10: 98923RES | CB10: 111.55 | CC10: 98930RES | CD10: 10.01
A11: COM | B11: 98920 | D11: 0 | E11: 0 | F11: 0 | G11: 0 | I11: 0 | J11: 0 | K11: 0 | L11: 0 | N11: 0 | O11: 0 | P11: 0 | Q11: 0 | R11: COM | S11: 98933 | U11: 0 | V11: 0 | W11: 0 | X11: 0 | Z11: 0 | AA11: 0 | AB11: 0 | AC11: 0 | AE11: 0 | AF11: 0 | AG11: 0 | AH11: 0 | AR11: =A11 -> COM | AS11: =B11 -> 98920 | AT11: =D11*1.6%+E11*6.3%+F11*28.9% -> 0 | AU11: =I11*1.6%+J11*6.3%+K11*28.9% -> 0 | AV11: =N11*1.6%+O11*6.3%+P11*28.9% -> 0 | BJ11: 98908 | BK11: COM | BL11: 2 | BM11: 98908 | BN11: RES | BO11: 31 | BP11: 98930 | BQ11: RES | BR11: 10 | BS11: 98908COM | BT11: 305.37 | BU11: 98908RES | BV11: 25328.58 | BW11: 98930RES | BX11: 5497.77 | BY11: 98908COM | BZ11: 12.78 | CA11: 98930COM | CB11: 254.21 | CC11: 98932RES | CD11: 46.57
A12: COM | B12: 98921 | C12: 2 | D12: 163.44 | E12: 0 | F12: 0 | G12: 163.44 | I12: 0 | J12: 0 | K12: 0 | L12: 0 | M12: 1 | N12: 13.7 | O12: 0 | P12: 0 | Q12: 13.7 | R12: COM | S12: 98936 | T12: 1 | U12: 0 | V12: 35.22 | W12: 141.41 | X12: 176.63 | Y12: 1 | Z12: 38.08 | AA12: 38.93 | AB12: 176.63 | AC12: 253.64 | AD12: 1 | AE12: 35.22 | AF12: 77.01 | AG12: 166.82 | AH12: 279.05 | AR12: =A12 -> COM | AS12: =B12 -> 98921 | AT12: =D12*1.6%+E12*6.3%+F12*28.9% -> 2.61504 | AU12: =I12*1.6%+J12*6.3%+K12*28.9% -> 0 | AV12: =N12*1.6%+O12*6.3%+P12*28.9% -> 0.2192 | BJ12: 98908 | BK12: RES | BL12: 71 | BM12: 98921 | BN12: RES | BO12: 1 | BP12: 98932 | BQ12: RES | BR12: 6 | BS12: 98908RES | BT12: 40035.65 | BU12: 98921RES | BV12: 154.3 | BW12: 98932RES | BX12: 11140.44 | BY12: 98908RES | BZ12: 1340.08 | CA12: 98933COM | CB12: 191.91 | CC12: 98936RES | CD12: 141.43
A13: COM | B13: 98923 | C13: 5 | D13: 16940.32 | E13: 2535.15 | F13: 14050.68 | G13: 33526.15 | H13: 10 | I13: 3386.05 | J13: 2551.33 | K13: 10388.06 | L13: 16325.44 | M13: 7 | N13: 3222.68 | O13: 2634.86 | P13: 10181.55 | Q13: 16039.09 | R13: COM | S13: 98937 | T13: 1 | U13: 27.4 | V13: 24.16 | W13: 369.88 | X13: 421.44 | Y13: 1 | Z13: 47.29 | AA13: 27.4 | AB13: 236.23 | AC13: 310.92 | AD13: 1 | AE13: 20.65 | AF13: 47.29 | AG13: 263.63 | AH13: 331.57 | AR13: =A13 -> COM | AS13: =B13 -> 98923 | AT13: =D13*1.6%+E13*6.3%+F13*28.9% -> 4491.4061 | AU13: =I13*1.6%+J13*6.3%+K13*28.9% -> 3217.0599 | AV13: =N13*1.6%+O13*6.3%+P13*28.9% -> 3160.027 | BJ13: 98921 | BK13: RES | BL13: 3 | BM13: 98923 | BN13: COM | BO13: 1 | BP13: 98933 | BQ13: RES | BR13: 1 | BS13: 98921RES | BT13: 180.23 | BU13: 98923COM | BV13: 348.94 | BW13: 98933RES | BX13: 9828.91 | BY13: 98930RES | BZ13: 369.45 | CA13: 98935COM | CB13: 306.58 | CC13: 98951RES | CD13: 298.43
A14: COM | B14: 98930 | C14: 39 | D14: 11221.25 | E14: 1165.66 | F14: 29350.18 | G14: 41737.09 | H14: 39 | I14: 10592.47 | J14: 4565.52 | K14: 29031.34 | L14: 44189.33 | M14: 35 | N14: 8330.64 | O14: 5095.96 | P14: 30467.32 | Q14: 43893.92 | R14: COM | S14: 98938 | T14: 2 | U14: 443.13 | V14: 268.26 | W14: 1069.62 | X14: 1781.01 | Y14: 2 | Z14: 438.88 | AA14: 343.7 | AB14: 1337.88 | AC14: 2120.46 | AD14: 2 | AE14: 606.29 | AF14: 438.25 | AG14: 1681.58 | AH14: 2726.12 | AR14: =A14 -> COM | AS14: =B14 -> 98930 | AT14: =D14*1.6%+E14*6.3%+F14*28.9% -> 8735.1786 | AU14: =I14*1.6%+J14*6.3%+K14*28.9% -> 8847.1645 | AV14: =N14*1.6%+O14*6.3%+P14*28.9% -> 9259.3912 | BJ14: 98923 | BK14: RES | BL14: 8 | BM14: 98923 | BN14: RES | BO14: 1 | BP14: 98935 | BQ14: RES | BR14: 1 | BS14: 98923RES | BT14: 10431.85 | BU14: 98923RES | BV14: 111.55 | BW14: 98935RES | BX14: 75.62 | BY14: 98932RES | BZ14: 190.81 | CA14: 98936RES | CB14: 75.93 | CC14: 99328RES | CD14: 61.73
A15: COM | B15: 98932 | C15: 24 | D15: 12476 | E15: 1077.01 | F15: 17578.98 | G15: 31131.99 | H15: 24 | I15: 35023.44 | J15: 428.31 | K15: 5054.26 | L15: 40506.01 | M15: 19 | N15: 3818.37 | O15: 610.81 | P15: 4901.68 | Q15: 9330.86 | R15: COM | S15: 98939 | T15: 1 | U15: 426.38 | V15: 288.91 | W15: 224.28 | X15: 939.57 | Y15: 1 | Z15: 501.46 | AA15: 319.07 | AB15: 119.04 | AC15: 939.57 | AD15: 1 | AE15: 485.49 | AF15: 22.94 | AG15: 142.23 | AH15: 650.66 | AR15: =A15 -> COM | AS15: =B15 -> 98932 | AT15: =D15*1.6%+E15*6.3%+F15*28.9% -> 5347.7928 | AU15: =I15*1.6%+J15*6.3%+K15*28.9% -> 2048.0397 | AV15: =N15*1.6%+O15*6.3%+P15*28.9% -> 1516.1605 | BJ15: 98930 | BK15: RES | BL15: 25 | BM15: 98930 | BN15: COM | BO15: 2 | BP15: 98936 | BQ15: RES | BR15: 6 | BS15: 98930RES | BT15: 16314.13 | BU15: 98930COM | BV15: 422.71 | BW15: 98936RES | BX15: 2232.21 | BY15: 98935RES | BZ15: 59.78 | CA15: 98937RES | CB15: 57.15 | CC15: 99347RES | CD15: 113.3
A16: COM | B16: 98933 | C16: 10 | D16: 2093.94 | E16: 251.68 | F16: 186.3 | G16: 2531.92 | H16: 6 | I16: 830.84 | J16: 14 | K16: 14 | L16: 858.84 | M16: 8 | N16: 5840.85 | O16: 227.31 | P16: 0 | Q16: 6068.16 | R16: COM | S16: 98942 | U16: 0 | V16: 0 | W16: 0 | X16: 0 | Z16: 0 | AA16: 0 | AB16: 0 | AC16: 0 | AE16: 0 | AF16: 0 | AG16: 0 | AH16: 0 | AR16: =A16 -> COM | AS16: =B16 -> 98933 | AT16: =D16*1.6%+E16*6.3%+F16*28.9% -> 103.19958 | AU16: =I16*1.6%+J16*6.3%+K16*28.9% -> 18.22144 | AV16: =N16*1.6%+O16*6.3%+P16*28.9% -> 107.77413 | BJ16: 98932 | BK16: RES | BL16: 5 | BM16: 98930 | BN16: RES | BO16: 13 | BP16: 98937 | BQ16: RES | BR16: 4 | BS16: 98932RES | BT16: 4466.01 | BU16: 98930RES | BV16: 18389.11 | BW16: 98937RES | BX16: 546.98 | BY16: 98937COM | BZ16: 72.77 | CA16: 98942RES | CB16: 102.2 | CC16: 99362RES | CD16: 274.73
A17: COM | B17: 98935 | C17: 4 | D17: 1771.88 | E17: 0 | F17: 14.43 | G17: 1786.31 | H17: 3 | I17: 215.81 | J17: 0 | K17: 0 | L17: 215.81 | M17: 4 | N17: 599.25 | O17: 0 | P17: 0 | Q17: 599.25 | R17: COM | S17: 98944 | T17: 3 | U17: 954.98 | V17: 842.47 | W17: 23878.6 | X17: 25676.05 | Y17: 4 | Z17: 1288.61 | AA17: 954.98 | AB17: 24119.57 | AC17: 26363.16 | AD17: 4 | AE17: 1078.47 | AF17: 1288.61 | AG17: 25074.55 | AH17: 27441.63 | AR17: =A17 -> COM | AS17: =B17 -> 98935 | AT17: =D17*1.6%+E17*6.3%+F17*28.9% -> 32.52035 | AU17: =I17*1.6%+J17*6.3%+K17*28.9% -> 3.45296 | AV17: =N17*1.6%+O17*6.3%+P17*28.9% -> 9.588 | BJ17: 98933 | BK17: RES | BL17: 2 | BM17: 98932 | BN17: RES | BO17: 5 | BP17: 98938 | BQ17: RES | BR17: 2 | BS17: 98933RES | BT17: 16041.77 | BU17: 98932RES | BV17: 1895.13 | BW17: 98938RES | BX17: 7675.91 | BY17: 98939RES | BZ17: 14.55 | CA17: 98944RES | CB17: 392.99
A18: COM | B18: 98936 | C18: 21 | D18: 10345.76 | E18: 11502.12 | F18: 20556.05 | G18: 42403.93 | H18: 23 | I18: 70712.08 | J18: 1272.27 | K18: 11967.12 | L18: 83951.47 | M18: 23 | N18: 10495.06 | O18: 4387.49 | P18: 12853.96 | Q18: 27736.51 | R18: COM | S18: 98947 | U18: 0 | V18: 0 | W18: 0 | X18: 0 | Y18: 1 | Z18: 106.22 | AA18: 0 | AB18: 0 | AC18: 106.22 | AD18: 1 | AE18: 192.69 | AF18: 0 | AG18: 0 | AH18: 192.69 | AR18: =A18 -> COM | AS18: =B18 -> 98936 | AT18: =D18*1.6%+E18*6.3%+F18*28.9% -> 6830.8642 | AU18: =I18*1.6%+J18*6.3%+K18*28.9% -> 4670.044 | AV18: =N18*1.6%+O18*6.3%+P18*28.9% -> 4159.1273 | BJ18: 98935 | BK18: RES | BL18: 7 | BM18: 98933 | BN18: COM | BO18: 1 | BP18: 98942 | BQ18: RES | BR18: 15 | BS18: 98935RES | BT18: 3537.91 | BU18: 98933COM | BV18: 191.91 | BW18: 98942RES | BX18: 19480.52 | BY18: 98942RES | BZ18: 409.94 | CA18: 98947RES | CB18: 51.03
A19: COM | B19: 98937 | C19: 32 | D19: 17982.09 | E19: 2282.56 | F19: 13405.99 | G19: 33670.64 | H19: 31 | I19: 17962.2 | J19: 4560.46 | K19: 13749.17 | L19: 36271.83 | M19: 35 | N19: 15720.03 | O19: 2783.88 | P19: 11855.76 | Q19: 30359.67 | R19: COM | S19: 98948 | T19: 10 | U19: 5681.94 | V19: 2330.85 | W19: 17490.85 | X19: 25503.64 | Y19: 11 | Z19: 10728.07 | AA19: 1992.58 | AB19: 10765.52 | AC19: 23486.17 | AD19: 7 | AE19: 3065.2 | AF19: 4025.67 | AG19: 10138.46 | AH19: 17229.33 | AR19: =A19 -> COM | AS19: =B19 -> 98937 | AT19: =D19*1.6%+E19*6.3%+F19*28.9% -> 4305.8458 | AU19: =I19*1.6%+J19*6.3%+K19*28.9% -> 4548.2143 | AV19: =N19*1.6%+O19*6.3%+P19*28.9% -> 3853.2196 | BJ19: 98936 | BK19: RES | BL19: 7 | BM19: 98933 | BN19: RES | BO19: 2 | BP19: 98944 | BQ19: COM | BR19: 2 | BS19: 98936RES | BT19: 6875.3 | BU19: 98933RES | BV19: 6473.16 | BW19: 98944COM | BX19: 9292.87 | BY19: 98944COM | BZ19: 218.5 | CA19: 98948RES | CB19: 343
A20: COM | B20: 98938 | C20: 17 | D20: 32394.94 | E20: 903.05 | F20: 8737.46 | G20: 42035.45 | H20: 20 | I20: 35328.69 | J20: 30552.5 | K20: 8057.87 | L20: 73939.06 | M20: 16 | N20: 30621.42 | O20: 1795.27 | P20: 8996.35 | Q20: 41413.04 | R20: COM | S20: 98951 | T20: 4 | U20: 818.43 | V20: 121.76 | W20: 258.15 | X20: 1198.34 | Y20: 4 | Z20: 425.16 | AA20: 109.03 | AB20: 258.15 | AC20: 792.34 | AD20: 2 | AE20: 173.03 | AF20: 57.38 | AG20: 367.18 | AH20: 597.59 | AR20: =A20 -> COM | AS20: =B20 -> 98938 | AT20: =D20*1.6%+E20*6.3%+F20*28.9% -> 3100.3371 | AU20: =I20*1.6%+J20*6.3%+K20*28.9% -> 4818.791 | AV20: =N20*1.6%+O20*6.3%+P20*28.9% -> 3202.9899 | BJ20: 98937 | BK20: COM | BL20: 1 | BM20: 98935 | BN20: COM | BO20: 2 | BP20: 98944 | BQ20: RES | BR20: 38 | BS20: 98937COM | BT20: 72.77 | BU20: 98935COM | BV20: 310.56 | BW20: 98944RES | BX20: 17438.56 | BY20: 98944RES | BZ20: 495.95 | CA20: 98951RES | CB20: 557.73
A21: COM | B21: 98939 | C21: 2 | D21: 426.95 | E21: 288.91 | F21: 224.28 | G21: 940.14 | H21: 3 | I21: 672.33 | J21: 319.07 | K21: 119.04 | L21: 1110.44 | M21: 2 | N21: 509.3 | O21: 22.94 | P21: 142.23 | Q21: 674.47 | R21: COM | S21: 98952 | T21: 1 | U21: 142.92 | V21: 116.89 | W21: 245.31 | X21: 505.12 | Y21: 1 | Z21: 136.61 | AA21: 142.92 | AB21: 362.2 | AC21: 641.73 | AD21: 1 | AE21: 144.1 | AF21: 136.61 | AG21: 505.12 | AH21: 785.83 | AR21: =A21 -> COM | AS21: =B21 -> 98939 | AT21: =D21*1.6%+E21*6.3%+F21*28.9% -> 89.84945 | AU21: =I21*1.6%+J21*6.3%+K21*28.9% -> 65.26125 | AV21: =N21*1.6%+O21*6.3%+P21*28.9% -> 50.69849 | BJ21: 98937 | BK21: RES | BL21: 3 | BM21: 98935 | BN21: RES | BO21: 7 | BP21: 98947 | BQ21: RES | BR21: 2 | BS21: 98937RES | BT21: 488.48 | BU21: 98935RES | BV21: 3392.22 | BW21: 98947RES | BX21: 262.39 | BY21: 98947RES | BZ21: 103.91 | CA21: 99324RES | CB21: 254.97
A22: COM | B22: 98942 | C22: 56 | D22: 11099.93 | E22: 1960.7 | F22: 15454.52 | G22: 28515.15 | H22: 64 | I22: 177344.82 | J22: 3721.04 | K22: 14805.36 | L22: 195871.22 | M22: 63 | N22: 27922.76 | O22: 3816.14 | P22: 13035.01 | Q22: 44773.91 | R22: COM | S22: 98953 | T22: 4 | U22: 187.6 | V22: 483.68 | W22: 3350.72 | X22: 4022 | Y22: 4 | Z22: 193.8 | AA22: 187.6 | AB22: 3440.86 | AC22: 3822.26 | AD22: 5 | AE22: 296.43 | AF22: 193.8 | AG22: 3225.46 | AH22: 3715.69 | AR22: =A22 -> COM | AS22: =B22 -> 98942 | AT22: =D22*1.6%+E22*6.3%+F22*28.9% -> 4767.4793 | AU22: =I22*1.6%+J22*6.3%+K22*28.9% -> 7350.6917 | AV22: =N22*1.6%+O22*6.3%+P22*28.9% -> 4454.2989 | BJ22: 98938 | BK22: RES | BL22: 1 | BM22: 98936 | BN22: COM | BO22: 1 | BP22: 98948 | BQ22: COM | BR22: 1 | BS22: 98938RES | BT22: 323.75 | BU22: 98936COM | BV22: 1665.44 | BW22: 98948COM | BX22: 438.2 | BY22: 98951RES | BZ22: 142.72 | CA22: 99328RES | CB22: 491.91
A23: COM | B23: 98944 | C23: 99 | D23: 34942.88 | E23: 10216.64 | F23: 123485.32 | G23: 168644.84 | H23: 115 | I23: 45148.69 | J23: 18573.74 | K23: 127183.5 | L23: 190905.93 | M23: 116 | N23: 41395.79 | O23: 20822.17 | P23: 135741.57 | Q23: 197959.53 | R23: COM | S23: 99323 | T23: 1 | U23: 83.36 | V23: 103.27 | W23: 234.44 | X23: 421.07 | Y23: 1 | Z23: 52.88 | AA23: 83.36 | AB23: 337.71 | AC23: 473.95 | AE23: 0 | AF23: 0 | AG23: 0 | AH23: 0 | AR23: =A23 -> COM | AS23: =B23 -> 98944 | AT23: =D23*1.6%+E23*6.3%+F23*28.9% -> 36889.992 | AU23: =I23*1.6%+J23*6.3%+K23*28.9% -> 38648.556 | AV23: =N23*1.6%+O23*6.3%+P23*28.9% -> 41203.443 | BJ23: 98939 | BK23: RES | BL23: 4 | BM23: 98936 | BN23: RES | BO23: 7 | BP23: 98948 | BQ23: RES | BR23: 11 | BS23: 98939RES | BT23: 3036.33 | BU23: 98936RES | BV23: 15808.6 | BW23: 98948RES | BX23: 9395.19 | BY23: 98953RES | BZ23: 567.41 | CA23: 99347RES | CB23: 1899.16
A24: COM | B24: 98947 | C24: 12 | D24: 10344.96 | E24: 1058.9 | F24: 2565.77 | G24: 13969.63 | H24: 14 | I24: 5035.8 | J24: 235.96 | K24: 2397.72 | L24: 7669.48 | M24: 11 | N24: 3251.54 | O24: 1964.61 | P24: 2633.68 | Q24: 7849.83 | R24: COM | S24: 99324 | T24: 1 | U24: 12.22 | V24: 0 | W24: 0 | X24: 12.22 | Y24: 1 | Z24: 14.08 | AA24: 12.22 | AB24: 0 | AC24: 26.3 | AD24: 1 | AE24: 14.21 | AF24: 14.08 | AG24: 12.22 | AH24: 40.51 | AR24: =A24 -> COM | AS24: =B24 -> 98947 | AT24: =D24*1.6%+E24*6.3%+F24*28.9% -> 973.73759 | AU24: =I24*1.6%+J24*6.3%+K24*28.9% -> 788.37936 | AV24: =N24*1.6%+O24*6.3%+P24*28.9% -> 936.92859 | BJ24: 98942 | BK24: RES | BL24: 26 | BM24: 98937 | BN24: RES | BO24: 1 | BP24: 98951 | BQ24: RES | BR24: 15 | BS24: 98942RES | BT24: 17938.25 | BU24: 98937RES | BV24: 57.15 | BW24: 98951RES | BX24: 26543.17 | BY24: 99324RES | BZ24: 147.61 | CA24: 99362COM | CB24: 183.69
A25: COM | B25: 98948 | C25: 69 | D25: 18997.32 | E25: 18784.67 | F25: 194697.92 | G25: 232479.91 | H25: 110 | I25: 108221.94 | J25: 12330.23 | K25: 183058.95 | L25: 303611.12 | M25: 69 | N25: 47615.8 | O25: 28899.92 | P25: 169413.37 | Q25: 245929.09 | R25: COM | S25: 99328 | U25: 0 | V25: 0 | W25: 0 | X25: 0 | Z25: 0 | AA25: 0 | AB25: 0 | AC25: 0 | AE25: 0 | AF25: 0 | AG25: 0 | AH25: 0 | AR25: =A25 -> COM | AS25: =B25 -> 98948 | AT25: =D25*1.6%+E25*6.3%+F25*28.9% -> 57755.09 | AU25: =I25*1.6%+J25*6.3%+K25*28.9% -> 55412.392 | AV25: =N25*1.6%+O25*6.3%+P25*28.9% -> 51543.012 | BJ25: 98944 | BK25: COM | BL25: 1 | BM25: 98938 | BN25: RES | BO25: 2 | BP25: 98953 | BQ25: RES | BR25: 8 | BS25: 98944COM | BT25: 218.5 | BU25: 98938RES | BV25: 28200.44 | BW25: 98953RES | BX25: 13090.66 | BY25: 99328RES | BZ25: 61.73 | CA25: 99362RES | CB25: 1303.11
